Workbook

Sheet 2020.07
A1: 到课情况 | D1: 咨询回访 （写内容） | E1: 是否成功 | F1: 分组 | G1: 学号 | H1: 学生姓名 | J1: jiaofei | K1: 试读日期 | L1: 年龄 | M1: 家长联系方式 | N1: 校区 | O1: 市场 | P1: 区域国家 | Q1: 在读状态 | R1: 课程顾问 | S1: 学科 | T1: 课程情况 | U1: 在读课堂 | V1: 授课老师 | W1: 每周课时情况 | X1: 收费标准 | Z1: 优惠活动 | AB1: 课时情况 | AE1: 收费员 | AF1: 付费方式 | AG1: 习惯付款方式 | AH1: 最后缴费日期 | AI1: 计费日期 | AK1: 最后收费金额 | AL1: 请假情况 | AN1: 到期日期 | AO1: 备注
D2: 1 | E2: 1 | F2: 4 | G2: 20WA00236 | H2: 叶丹尼 | I2: 叶丹尼 | J2: =IFERROR(VLOOKUP(I2,Sheet1!A:C,3,FALSE),"zhoanudao") -> 是 | K2: 44013 | M2: angelicaye | P2: 西班牙 | S2: 中文 | U2: 四十三课堂 第九节 | X2: 660 | AH2: 44019 | AI2: 44018 | AJ2: 44048 | AK2: 660 | AN2: 44048
D3: 1 | E3: 1 | F3: 3 | G3: 20WC00351 | H3: 陈雅婷1（数） | I3: 陈雅婷1 | J3: =IFERROR(VLOOKUP(I3,Sheet1!A:C,3,FALSE),"zhoanudao") -> 是 | K3: 44013 | M3: simonechen170 | P3: 意大利 | S3: 数学 | U3: 十一课堂 第二节 | X3: 660 | AH3: 44014 | AI3: 44016 | AJ3: 44046 | AK3: 660 | AN3: 44046
D4: 1 | E4: 1 | F4: 兼职 | G4: 20WA00237 | H4: 潘佳慧（英） | I4: 潘佳慧 | J4: =IFERROR(VLOOKUP(I4,Sheet1!A:C,3,FALSE),"zhoanudao") -> zhoanudao | K4: 44013 | M4: xia618388632 | P4: 西班牙 | S4: 英文 | U4: 二十课堂 第三节 | X4: 660 | AH4: 44018 | AI4: 44018 | AJ4: 44079 | AK4: 1320 | AN4: 44079
D5: 语言听不懂 | E5: 0 | F5: 3 | G5: 20WC00352 | H5: kevinwang王柏皓（数） | I5: 王柏皓 | J5: =IFERROR(VLOOKUP(I5,Sheet1!A:C,3,FALSE),"zhoanudao") -> zhoanudao | K5: 44013 | M5: h1443638 | P5: 意大利 | S5: 数学 | U5: 一课堂 第二节
E6: 1 | F6: 3 | G6: 20WK0010 | H6: 姜希雅（数） | I6: 姜希雅 | J6: =IFERROR(VLOOKUP(I6,Sheet1!A:C,3,FALSE),"zhoanudao") -> zhoanudao | K6: 44013 | M6: huan8878216 | P6: 希腊 | S6: 数学 | U6: 十一课堂 第二节
D7: 1 | E7: 1 | F7: 1 | G7: 20WC00353 | H7: 虞可可 | I7: 虞可可 | J7: =IFERROR(VLOOKUP(I7,Sheet1!A:C,3,FALSE),"zhoanudao") -> 是 | K7: 44013 | M7: a3398259751 | P7: 意大利 | S7: 中文 | U7: 三十课堂 第四节 | X7: 660 | AH7: 44020 | AI7: 44018 | AJ7: 44048 | AK7: 660 | AN7: 44048
D8: 1 | E8: 1 | F8: 3 | G8: 20WC00354 | H8: 虞可可（英） | I8: 虞可可 | J8: =IFERROR(VLOOKUP(I8,Sheet1!A:C,3,FALSE),"zhoanudao") -> 是 | K8: 44013 | M8: a3398259752 | P8: 意大利 | S8: 英文 | U8: 五十八课堂 第五节 | X8: 660 | AH8: 44020 | AI8: 44016 | AJ8: 44046 | AK8: 660 | AN8: 44046
D9: 1 | E9: 1 | F9: 2 | G9: 20WA00238 | H9: 单梓嫣（英） | I9: 单梓嫣 | J9: =IFERROR(VLOOKUP(I9,Sheet1!A:C,3,FALSE),"zhoanudao") -> zhoanudao | K9: 44013 | M9: jing774435 | P9: 西班牙 | S9: 英文 | U9: 十四课堂 第三节 | X9: 660 | AH9: 44019 | AI9: 44018 | AJ9: 44109 | AK9: 1980 | AN9: 44109
D10: 1（7.8缴费） | E10: 1 | F10: 1 | G10: 20WA00239 | H10: 陈洋1 | I10: 陈洋1 | J10: =IFERROR(VLOOKUP(I10,Sheet1!A:C,3,FALSE),"zhoanudao") -> 是 | K10: 44013 | M10: linlanpin | P10: 西班牙 | S10: 中文 | U10: 二十二课堂 第八节 | X10: 660 | AH10: 44020 | AI10: 44018 | AJ10: 44048 | AK10: 660 | AN10: 44048
D11: 1 | E11: 1 | F11: 1 | G11: 20WA00240 | H11: 李林家俊 | I11: 李林家俊 | J11: =IFERROR(VLOOKUP(I11,Sheet1!A:C,3,FALSE),"zhoanudao") -> 是 | K11: 44013 | M11: linye821123 | P11: 西班牙 | S11: 中文 | U11: 三十六课堂 第四节 | X11: 660 | AH11: 44019 | AI11: 44018 | AJ11: 44048 | AK11: 660 | AN11: 44048
D12: 去代理那边报名，只上周末班或者兼职班 | E12: 1 | F12: 1 | G12: 20WA00241 | H12: 黄思睿 | I12: 黄思睿 | J12: =IFERROR(VLOOKUP(I12,Sheet1!A:C,3,FALSE),"zhoanudao") -> zhoanudao | K12: 44013 | M12: wxid_6rwnklpow3c511 | P12: 西班牙 | S12: 中文 | U12: 三十六课堂 第八节
E13: 1 | F13: 4 | G13: 20WD0066 | H13: 倪星哲 | I13: 倪星哲 | J13: =IFERROR(VLOOKUP(I13,Sheet1!A:C,3,FALSE),"zhoanudao") -> 是 | K13: 44013 | M13: xiulinfu | O13: 新 | P13: 巴西 | S13: 中文 | U13: 三课堂 6：30-7：00
F14: 1 | G14: 20WI0036 | H14: 陈冠燊 | I14: 陈冠燊 | J14: =IFERROR(VLOOKUP(I14,Sheet1!A:C,3,FALSE),"zhoanudao") -> zhoanudao | K14: 44013 | M14: winnie12345 | P14: 美国 | S14: 中文 | U14: 三十九课堂 第二节 | AO14: 运营部新生
D15: 1 | E15: 1 | F15: 3 | G15: 20WC00355 | H15: 陈亭妤 | I15: 陈亭妤 | J15: =IFERROR(VLOOKUP(I15,Sheet1!A:C,3,FALSE),"zhoanudao") -> zhoanudao | K15: 44014 | M15: zhang_xjin | P15: 意大利 | S15: 中文 | U15: 四十二课堂 第六节
D16: 1（妈妈很少看微信） | E16: 1 | F16: 1 | G16: 20WC00356 | H16: 张晓丹 | I16: 张晓丹 | J16: =IFERROR(VLOOKUP(I16,Sheet1!A:C,3,FALSE),"zhoanudao") -> 是 | K16: 44014 | M16: wxid_n9m9yp0ue2y422 | P16: 意大利 | S16: 中文 | U16: 三十九课堂 第二节 | X16: 660 | AH16: 44022 | AI16: 44025 | AJ16: 44117 | AK16: 1980 | AN16: 44117
D17: 暑假班冲突 | E17: 0 | F17: 2 | G17: 20WK031 | H17: 吴露娜 | I17: 吴露娜 | J17: =IFERROR(VLOOKUP(I17,Sheet1!A:C,3,FALSE),"zhoanudao") -> zhoanudao | K17: 44014 | M17: Qunyu_Vienna | P17: 奥地利 | S17: 中文 | U17: 五十五课堂 第五节
D18: 以前上学的地方开网课了 | E18: 0 | F18: 1 | H18: 章侨偌 | I18: 章侨偌 | J18: =IFERROR(VLOOKUP(I18,Sheet1!A:C,3,FALSE),"zhoanudao") -> zhoanudao | K18: 44014 | M18: zuiaidexiaozhi | P18: 意大利 | S18: 中文 | U18: 五十课堂 第三节
D19: 1（跟哥哥林泽锴1一起付） | F19: 3 | G19: 20WA00242 | H19: 林炜真（数） | I19: 林炜真 | J19: =IFERROR(VLOOKUP(I19,Sheet1!A:C,3,FALSE),"zhoanudao") -> zhoanudao | K19: 44014 | M19: ibai2012 | P19: 西班牙 | S19: 数学 | U19: 一课堂 第四节
D20: 家长觉得教的太慢了作业也少 | E20: 0 | F20: 3 | G20: 20WC00358 | H20: 王家轩（数） | I20: 王家轩 | J20: =IFERROR(VLOOKUP(I20,Sheet1!A:C,3,FALSE),"zhoanudao") -> zhoanudao | K20: 44014 | M20: xunzhao1023 | P20: 意大利 | S20: 数学 | U20: 四十四课堂 第六节
D21: 第二天转28课堂，后转回52课堂 | F21: 4 | G21: 20WA00243 | H21: 麻雅妮 | I21: 麻雅妮 | J21: =IFERROR(VLOOKUP(I21,Sheet1!A:C,3,FALSE),"zhoanudao") -> zhoanudao | K21: 44014 | M21: qingqing127214 | P21: 西班牙 | S21: 中文 | U21: 五十二课堂 第四节
D22: 第三天转52课堂 | F22: 4 | G22: 20WA00244 | H22: 麻安妮 | I22: 麻安妮 | J22: =IFERROR(VLOOKUP(I22,Sheet1!A:C,3,FALSE),"zhoanudao") -> zhoanudao | K22: 44014 | M22: qingqing127215 | P22: 西班牙 | S22: 中文 | U22: 三十一课堂 第五节
E23: 1 | F23: 2 | G23: 20WC00359 | H23: 任鹏铄 | I23: 任鹏铄 | J23: =IFERROR(VLOOKUP(I23,Sheet1!A:C,3,FALSE),"zhoanudao") -> 是 | K23: 44014 | M23: xie3272841959 | P23: 意大利 | S23: 中文 | U23: 二十六课堂 第四节 | X23: 660 | AH23: 44019 | AI23: 44018 | AJ23: 44048 | AK23: 660 | AN23: 44048
D24: 1 | F24: 2 | G24: 20WA00245 | H24: 杨雨宸 | I24: 杨雨宸 | J24: =IFERROR(VLOOKUP(I24,Sheet1!A:C,3,FALSE),"zhoanudao") -> zhoanudao | K24: 44014 | M24: xiaoqing8618 | P24: 西班牙 | S24: 中文 | U24: 五十五课堂 第五节
D25: 报了别的平台一对一 | E25: 0 | F25: 4 | G25: 20WI0037 | H25: 牛小凯 | I25: 牛小凯 | J25: =IFERROR(VLOOKUP(I25,Sheet1!A:C,3,FALSE),"zhoanudao") -> zhoanudao | K25: 44014 | M25: IvyNiu | P25: 美国 | S25: 中文 | U25: 四十三课堂 5:30-6:00
E26: 1 | F26: 4 | G26: 20WA00246 | H26: 潘昊泉 | I26: 潘昊泉 | J26: =IFERROR(VLOOKUP(I26,Sheet1!A:C,3,FALSE),"zhoanudao") -> 是 | K26: 44014 | M26: Z139017555 | P26: 西班牙 | S26: 中文 | U26: 五十三课堂 第十节 | AO26: 运营部新生
E27: 1 | F27: 3 | G27: 20WK032 | H27: 姜欢欣（数） | I27: 姜欢欣 | J27: =IFERROR(VLOOKUP(I27,Sheet1!A:C,3,FALSE),"zhoanudao") -> 是 | K27: 44015 | M27: huan8878216 | P27: 希腊 | S27: 数学 | U27: 一课堂 第九节 | AH27: 44015 | AI27: 44018 | AJ27: 44109 | AK27: 1854元 | AN27: 44109
D28: 1 | E28: 1 | F28: 2 | G28: 20WA00247 | H28: 叶豪 | I28: 叶豪 | J28: =IFERROR(VLOOKUP(I28,Sheet1!A:C,3,FALSE),"zhoanudao") -> 是 | K28: 44015 | M28: peifen8216 | P28: 西班牙 | S28: 中文 | U28: 五十五课堂 第五节 | X28: 620 | AH28: 44021 | AI28: 44019 | AJ28: 44112 | AK28: 1860 | AN28: 44112
D29: 1（7.8转四十九课堂） | E29: 1 | F29: 3 | G29: 20WA00248 | H29: 徐俏俏（数） | I29: 徐俏俏 | J29: =IFERROR(VLOOKUP(I29,Sheet1!A:C,3,FALSE),"zhoanudao") -> 是 | K29: 44015 | M29: q597037537 | P29: 西班牙 | S29: 数学 | U29: 三十二课堂 第二节 | X29: 660 | AH29: 44019 | AI29: 44021 | AJ29: 44051 | AK29: 660 | AN29: 44051
D30: 1 | E30: 1 | F30: 3 | G30: 20WA00249 | H30: 黄薏卉 | I30: 黄薏卉 | J30: =IFERROR(VLOOKUP(I30,Sheet1!A:C,3,FALSE),"zhoanudao") -> 是 | K30: 44015 | M30: HZY1314258 | P30: 西班牙 | S30: 中文 | U30: 四十二课堂 第二节 | X30: 660 | AH30: 44019 | AI30: 44021 | AJ30: 44051 | AK30: 660 | AN30: 44051
D31: 1 | E31: 1 | F31: 4 | G31: 20WA00250 | H31: 黄梓烨 | I31: 黄梓烨 | J31: =IFERROR(VLOOKUP(I31,Sheet1!A:C,3,FALSE),"zhoanudao") -> 是 | K31: 44015 | M31: HZY1314259 | P31: 西班牙 | S31: 中文 | U31: 五十三课堂 第十节 | X31: 660 | AH31: 44019 | AI31: 44021 | AJ31: 44051 | AK31: 660 | AN31: 44051
D32: 1 | E32: 1 | F32: 3 | G32: 20WA00251 | H32: 张智轩（数） | I32: 张智轩 | J32: =IFERROR(VLOOKUP(I32,Sheet1!A:C,3,FALSE),"zhoanudao") -> zhoanudao | K32: 44015 | M32: QT656866634 | P32: 西班牙 | S32: 数学 | U32: 六课堂 第六节
D33: 1 | E33: 1 | F33: 4 | G33: 20WA00252 | H33: 叶欣 | I33: 叶欣 | J33: =IFERROR(VLOOKUP(I33,Sheet1!A:C,3,FALSE),"zhoanudao") -> 是 | K33: 44015 | M33: peifen8216 | P33: 西班牙 | S33: 中文 | U33: 二十七课堂 第四节 | X33: 620 | AH33: 44021 | AI33: 44019 | AJ33: 44112 | AK33: 1860 | AN33: 44112
D34: 1 | F34: 金华 | G34: 20WC00360 | H34: 陈泉铕 | I34: 陈泉铕 | J34: =IFERROR(VLOOKUP(I34,Sheet1!A:C,3,FALSE),"zhoanudao") -> zhoanudao | K34: 44015 | M34: zhongyan027588 | P34: 意大利 | S34: 中文 | U34: 阳光第七课堂 第三节
E35: 1 | F35: 金华 | G35: 20WI0038 | H35: 王佳怡3 | I35: 王佳怡3 | J35: =IFERROR(VLOOKUP(I35,Sheet1!A:C,3,FALSE),"zhoanudao") -> 是 | K35: 44015 | M35: w9177168661 | P35: 美国 | S35: 中文 | U35: 阳光第七课堂 第三节 | X35: 660 | AH35: 44020 | AI35: 44021 | AJ35: 44051 | AK35: 660 | AN35: 44051
D36: 1 | E36: 1 | F36: 金华 | G36: 20WA00253 | H36: 叶婷2 | I36: 叶婷2 | J36: =IFERROR(VLOOKUP(I36,Sheet1!A:C,3,FALSE),"zhoanudao") -> 是 | K36: 44015 | M36: peifen8216 | P36: 西班牙 | S36: 中文 | U36: 阳光第七课堂 第三节 | X36: 620 | AH36: 44021 | AI36: 44019 | AJ36: 44112 | AK36: 1860 | AN36: 44112
D37: 1 | F37: 金华 | G37: 20WC00361 | H37: 林慧 | I37: 林慧 | J37: =IFERROR(VLOOKUP(I37,Sheet1!A:C,3,FALSE),"zhoanudao") -> zhoanudao | K37: 44015 | M37: wang605705793 | P37: 意大利 | S37: 中文 | U37: 阳光第七课堂 第三节
D38: 1 | E38: 1 | F38: 金华 | G38: 20WI0039 | H38: 王昕宇1 | I38: 王昕宇1 | J38: =IFERROR(VLOOKUP(I38,Sheet1!A:C,3,FALSE),"zhoanudao") -> zhoanudao | K38: 44015 | M38: wang112423 | P38: 美国 | S38: 中文 | U38: 阳光第七课堂 第三节
D39: 1 | F39: 3 | G39: 20WA00382 | H39: 单陈依 | I39: 单陈依 | J39: =IFERROR(VLOOKUP(I39,Sheet1!A:C,3,FALSE),"zhoanudao") -> zhoanudao | K39: 44018 | M39: Mm553173 | P39: 西班牙 | S39: 中文 | U39: 二十八课堂 第七节
D40: 1 | F40: 3 | G40: 20WC00362 | H40: 林子腾（数） | I40: 林子腾 | J40: =IFERROR(VLOOKUP(I40,Sheet1!A:C,3,FALSE),"zhoanudao") -> zhoanudao | K40: 44018 | M40: linjunleo | P40: 意大利 | S40: 数学 | U40: 六课堂 第七节
...

Sheet Sheet1
A1: 叶文浩1 | B1: 叶文浩1 | C1: 是
A2: 叶鋆睿 | B2: 叶鋆睿 | C2: 是
A3: 何子恒（数） | B3: 何子恒 | C3: 是
A4: 吉娜 | B4: 吉娜 | C4: 是
A5: 宋崇铭 | B5: 宋崇铭 | C5: 是
A6: 吴楚惟 | B6: 吴楚惟 | C6: 是
A7: 吕泽歆 | B7: 吕泽歆 | C7: 是
A8: 小恩 | B8: 小恩 | C8: 是
A9: 吴炳铨（数） | B9: 吴炳铨 | C9: 是
A10: 林泽锴1 | B10: 林泽锴1 | C10: 是
A11: 胡昊阳 | B11: 胡昊阳 | C11: 是
A12: 胡昊阳（数） | B12: 胡昊阳 | C12: 是
... A253: 郑安俊郑俊杰郑迪纪柯艳 | B253: 郑安俊 | C253: 是
B254: 柯艳 | C254: 是
B255: 郑迪纪 | C255: 是
B256: 郑俊杰 | C256: 是
A257: 金喜1（数） | B257: 金喜1 | C257: 是
A258: 金娜娜1 | B258: 金娜娜1 | C258: 是
A259: 陈帅 | B259: 陈帅 | C259: 是
A260: 陈诺1 | B260: 陈诺1 | C260: 是
A261: 袁乐琛（数） | B261: 袁乐琛 | C261: 是
A262: 王新迪 | B262: 王新迪 | C262: 是
A263: 倪瑞璇 | B263: 倪瑞璇 | C263: 是
A264: 周素丽 | B264: 周素丽 | C264: 是
A265: 周熠 | B265: 周熠 | C265: 是
A266: 李浩然1 | B266: 李浩然1 | C266: 是
A267: 陈奕嘉 | B267: 陈奕嘉 | C267: 是
A268: 龚炫瑞 | B268: 龚炫瑞 | C268: 是
... A363: Huana wang, haoda wang,xunda wang | B363: Huana wang | C363: 是
B364: xunda wang | C364: 是
B365: haoda wang | C365: 是
A366: 张欣悦 | B366: 张欣悦 | C366: 是
A367: 朱佳慧 | B367: 朱佳慧 | C367: 是
A368: 朱凯文 | B368: 朱凯文 | C368: 是
A369: 陈明雪 | B369: 陈明雪 | C369: 是
A370: 杨欣蕊 | B370: 杨欣蕊 | C370: 是
A371: 叶欣茹前几天付了一个月 84现在在付一个月84。 叶思雅付两个月168 | B371: 叶欣茹 | C371: 是
B372: 叶思雅 | C372: 是
A373: 胡思光 | B373: 胡思光 | C373: 是
A374: 张晓丹 | B374: 张晓丹 | C374: 是
...

Sheet 2020.06
A1: 到课情况 | D1: 咨询回访 （写内容） | E1: 是否成功 | F1: 分组 | G1: 学号 | H1: 学生姓名 | I1: 年龄 | J1: 家长联系方式 | K1: 校区 | L1: 市场 | M1: 区域国家 | N1: 在读状态 | O1: 课程顾问 | P1: 学科 | Q1: 课程情况 | R1: 在读课堂 | S1: 授课老师 | T1: 每周课时情况 | U1: 收费标准 | W1: 优惠活动 | Y1: 课时情况 | AB1: 收费员 | AC1: 付费方式 | AD1: 习惯付款方式 | AE1: 最后缴费时间 | AF1: 计费日期 | AH1: 最后收费金额 | AI1: 请假情况 | AK1: 到期时间 | AL1: 试读日期 | AM1: 备注
U2: 按月收费 | V2: 按节收费 | W2: 送课时 | X2: 优惠金额 | Y2: 总课时 | Z2: 当月消耗课时 | AA2: 剩余课时 | AF2: 起始日期 | AG2: 截止日期 | AH2: 人民币 | AI2: 开始请假日期 | AJ2: 截止请假日期
A3: 1 | B3: 1 | C3: 1 | D3: 1 | E3: 1 | F3: 2 | G3: 20WC00234 | H3: 叶毅晨 | J3: xunzhen158491543 | K3: 堂堂行 | L3: 老 | M3: 意大利 | P3: 中文 | Q3: 一对六 | R3: 五十五课堂 第四节 | T3: 一周五天 | U3: 660元/月 | AE3: 43983 | AF3: 43984 | AG3: 44014 | AH3: 660元 | AK3: 44014 | AL3: 6.01
A4: 1 | B4: 1 | C4: 1 | D4: 1 | E4: 1 | F4: 1 | G4: 20WC00233 | H4: 叶晨星 | J4: xunzhen158491544 | K4: 堂堂行 | L4: 老 | M4: 意大利 | P4: 中文 | Q4: 一对六 | R4: 三十课堂 第七节 | T4: 一周五天 | U4: 660元/月 | AE4: 43983 | AF4: 43984 | AG4: 44014 | AH4: 660元 | AK4: 44014 | AL4: 6.01
A5: 1 | B5: 1 | C5: 1 | D5: 1 | E5: 1 | F5: 4 | G5: 20WB0021 | H5: 陈毅轩 | J5: dong19791014 | K5: 堂堂行 | L5: 老 | M5: 葡萄牙 | O5: 陈雨2妈妈 | P5: 中文 | Q5: 一对六 | R5: 四十三课堂 第四节 | T5: 一周五天 | U5: 660元/月 | AE5: 43983 | AF5: 43984 | AG5: 44014 | AH5: 660元 | AK5: 44014 | AL5: 6.01
A6: 1 | B6: 1 | C6: 1 | D6: 1 | E6: 1 | F6: 4 | G6: 20WD0056 | H6: 胡智豪 | J6: huyou2009 | K6: 堂堂行 | L6: 老 | M6: 巴西 | P6: 中文 | Q6: 一对六 | R6: 五十六课堂 第十二节 | T6: 一周五天 | U6: 660元/月 | AE6: 43983 | AF6: 43984 | AG6: 44014 | AH6: 660元 | AK6: 44014 | AL6: 6.01
A7: 1 | B7: 1 | C7: 1 | D7: 1 | E7: 1 | F7: 2 | G7: 20WD0057 | H7: 胡子怡 | J7: huyou2009 | K7: 堂堂行 | L7: 老 | M7: 巴西 | P7: 中文 | Q7: 一对六 | R7: 三十八课堂 第六节 | T7: 一周五天 | U7: 660元/月 | AE7: 43983 | AF7: 43984 | AG7: 44014 | AH7: 660元 | AK7: 44014 | AL7: 6.01
A8: 1 | B8: 1 | C8: 1 | D8: 1 | E8: 1 | F8: 3 | G8: 20WC00235 | H8: 樊益洁（数） | J8: yjqsnyeq | K8: 堂堂行 | L8: 老 | M8: 意大利 | P8: 数学 | Q8: 一对六 | R8: 六课堂 第五节 | T8: 一周五天 | U8: 79元/节 | AE8: 43983 | AF8: 43994 | AG8: 44023 | AH8: 660元 | AK8: 44023 | AL8: 6.01 | AM8: 短期
A9: 1 | B9: 1 | C9: 1 | D9: 1 | E9: 1 | F9: 3 | G9: 20WC00236 | H9: 樊益欣（数） | J9: yjqsnyeq | K9: 堂堂行 | L9: 老 | M9: 意大利 | P9: 数学 | Q9: 一对六 | R9: 六课堂 第五节 | T9: 一周五天 | U9: 79元/节 | AE9: 43983 | AF9: 43994 | AG9: 44023 | AH9: 660元 | AK9: 44023 | AL9: 6.01 | AM9: 短期
A10: 1 | B10: 1 | C10: 1 | D10: 1 | E10: 1 | F10: 3 | G10: 20WA00175 | H10: 朱晞欧（数） | J10: Azul651420220 | K10: 堂堂行 | L10: 老 | M10: 西班牙 | P10: 数学 | Q10: 一对六 | R10: 四十四课堂 第八节 | T10: 一周五天 | U10: 660元/月 | AE10: 43983 | AF10: 43984 | AG10: 44014 | AH10: 660元 | AK10: 44014 | AL10: 6.01
A11: 1 | B11: 1 | C11: 1 | D11: 1 | E11: 1 | F11: 2 | G11: 20WC00237 | H11: 胡欢胜 | J11: michela001 | K11: 堂堂行 | L11: 老 | M11: 意大利 | P11: 中文 | Q11: 一对六 | R11: 四十八课堂 第二节 | T11: 一周五天 | U11: 660元/月 | AE11: 43983 | AF11: 43984 | AG11: 44014 | AH11: 660元 | AK11: 44014 | AL11: 6.01
A12: 1 | B12: 1 | C12: 1 | D12: 孩子不喜欢 | E12: 0 | F12: 3 | H12: 历暄妍（数） | J12: S123456789y2006 | K12: 堂堂行 | L12: 老 | M12: 意大利 | P12: 数学 | Q12: 一对六 | R12: 三十二课堂 第六节 | T12: 一周五天 | U12: 660元/月 | AL12: 6.01
A13: 1 | B13: 1 | C13: 1 | D13: 1 | E13: 1 | F13: 1 | G13: 20WA00176 | H13: 章鑫彦 | J13: ZYF301411 | K13: 堂堂行 | L13: 老 | M13: 西班牙 | P13: 中文 | Q13: 一对六 | R13: 三十七课堂 第九节 | T13: 一周五天 | U13: 660元/月 | AE13: 2020.6.19 | AF13: 43986 | AG13: 44104 | AH13: 2427元 | AK13: 44104 | AL13: 6.01
A14: 1 | B14: 1 | C14: 1 | D14: 1 | E14: 1 | F14: 2 | G14: 20WC00239 | H14: 虞咏凯 | J14: chen1534779756 | K14: 堂堂行 | L14: 老 | M14: 意大利 | O14: 徐熙桐妈妈 | P14: 中文 | Q14: 一对六 | R14: 三十三课堂 第八节 | T14: 一周五天 | U14: 660元/月 | AE14: 43983 | AF14: 43987 | AG14: 44016 | AH14: 660元 | AK14: 44016 | AL14: 6.01
A15: 1 | B15: 1 | C15: 1 | D15: 1 | E15: 1 | F15: 3 | G15: 20WC00240 | H15: 葛子涵 | J15: geyun221 | K15: 堂堂行 | L15: 老 | M15: 意大利 | P15: 中文 | Q15: 一对六 | R15: 五十七课堂 第十节 | T15: 一周五天 | U15: 660元/月 | AE15: 43984 | AF15: 43986 | AG15: 44015 | AH15: 660元 | AK15: 44015 | AL15: 6.01
A16: 1 | B16: 1 | C16: 1 | D16: 1 | E16: 1 | F16: 1 | G16: 20WC00241 | H16: 叶培熙 | J16: qq546245075 | K16: 堂堂行 | L16: 老 | M16: 意大利 | P16: 中文 | Q16: 一对六 | R16: 三十课堂 第七节 | T16: 一周五天 | U16: 660元/月 | AE16: 43988 | AF16: 43986 | AG16: 44015 | AH16: 660元 | AK16: 44015 | AL16: 6.01
A17: 1 | E17: 0 | F17: 3 | G17: 20WA00177 | H17: 张家盛(数） | J17: hongli1688 | K17: 堂堂行 | L17: 新 | M17: 西班牙 | P17: 数学 | Q17: 一对六 | R17: 十一课堂 第十二节 | T17: 一周五天 | U17: 660元/月 | AL17: 6.01 | AM17: 运营部老生重读
A18: 1 | B18: 1 | C18: 1 | D18: 1 | E18: 1 | F18: 2 | G18: 20WC00242 | H18: 周嘉欣 | J18: tina19861120 | K18: 堂堂行 | L18: 老 | M18: 意大利 | P18: 中文 | Q18: 一对六 | R18: 十三课堂 第二节 | T18: 一周五天 | U18: 660元/月 | AL18: 6.02
A19: 1 | B19: 1 | C19: 1 | D19: 1 | E19: 1 | F19: 3 | G19: 20WC00243 | H19: 朱浩钰（数） | J19: wxid_to3k0bbkljeh11 | K19: 堂堂行 | L19: 老 | M19: 意大利 | P19: 数学 | Q19: 一对六 | R19: 三十二课堂 第八节 | T19: 一周五天 | U19: 660元/月 | AE19: 43990 | AF19: 43990 | AG19: 44020 | AH19: 660元 | AK19: 44020 | AL19: 6.02
A20: 1 | B20: 1 | C20: 1 | D20: 学美术，没时间 | E20: 0 | F20: 1 | H20: 留诗雅 | J20: Sara__26 | K20: 堂堂行 | L20: 老 | M20: 意大利 | P20: 中文 | Q20: 一对六 | R20: 三十课堂 第七节 | T20: 一周五天 | U20: 660元/月 | AL20: 6.02
A21: 1 | B21: 1 | C21: 1 | D21: 1 | E21: 1 | F21: 2 | G21: 20WC00245 | H21: 庄嘉宁 | J21: lin697403 | K21: 堂堂行 | L21: 老 | M21: 意大利 | P21: 中文 | Q21: 一对六 | R21: 五十四课堂 第二节 | T21: 一周五天 | U21: 660元/月 | AE21: 43998 | AF21: 43988 | AG21: 44079 | AH21: 1980元 | AK21: 44079 | AL21: 6.02
A22: 1 | B22: 1 | C22: 1 | D22: 1 | E22: 1 | F22: 3 | G22: 20WC00246 | H22: 林轩玮（英） | J22: yaoyao369815226 | K22: 堂堂行 | L22: 老 | M22: 意大利 | P22: 英文 | Q22: 一对六 | R22: 四十五课堂 第八节 | T22: 一周五天 | U22: 660元/月 | AE22: 43990 | AF22: 43990 | AG22: 44019 | AH22: 660元 | AK22: 44019 | AL22: 6.02
A23: 1 | B23: 1 | C23: 1 | D23: 1 | E23: 1 | F23: 2 | G23: 20WC00247 | H23: 杜王洲 | J23: caihq1210 | K23: 堂堂行 | L23: 老 | M23: 意大利 | P23: 中文 | Q23: 一对六 | R23: 四十八课堂 第十节 | T23: 一周五天 | U23: 660元/月 | AE23: 43988 | AF23: 43988 | AG23: 44079 | AH23: 1980元 | AK23: 44079 | AL23: 6.02
A24: 1 | D24: 没有时间陪孩子 | E24: 0 | F24: 2 | H24: 张灵萱 | J24: Evaluky | K24: 堂堂行 | L24: 老 | M24: 意大利 | P24: 中文 | Q24: 一对六 | R24: 四十八课堂 第十节 | T24: 一周五天 | U24: 660元/月 | AL24: 6.02
A25: 1 | D25: 1 | E25: 1 | F25: 2 | G25: 20WC00249 | H25: 林晶茹 | J25: paola123 | K25: 堂堂行 | L25: 老 | M25: 意大利 | P25: 中文 | Q25: 一对六 | R25: 四十八课堂 第十节 | T25: 一周五天 | U25: 660元/月 | AE25: 2020.6.18 | AF25: 43987 | AG25: 44078 | AH25: 1980元 | AK25: 44078 | AL25: 6.02
A26: 1 | D26: 1 | E26: 1 | F26: 2 | G26: 20WB0023 | H26: 陈洛彬 | J26: Chloe130708 | K26: 堂堂行 | L26: 老 | M26: 葡萄牙 | P26: 中文 | Q26: 一对六 | R26: 四十八课堂 第十节 | T26: 一周五天 | U26: 660元/月 | AE26: 43990 | AF26: 43990 | AG26: 44020 | AH26: 660元 | AK26: 44020 | AL26: 6.02
A27: 1 | D27: 1 | E27: 1 | F27: 3 | G27: 20WB0024 | H27: 李世龙1（英） | J27: L571638321 | K27: 堂堂行 | L27: 老 | M27: 葡萄牙海岛 | P27: 英文 | Q27: 一对六 | R27: 四十五课堂 第十节 | T27: 一周五天 | U27: 660元/月 | AE27: 43990 | AF27: 43990 | AG27: 44020 | AH27: 660元 | AK27: 44020 | AL27: 6.02
A28: 1 | D28: 1 | E28: 1 | F28: 3 | G28: 20WA00178 | H28: 陈知奕（数） | J28: helena331835 | K28: 堂堂行 | L28: 老 | M28: 西班牙 | P28: 数学 | Q28: 一对六 | R28: 三十二课堂 第八节 | T28: 一周五天 | U28: 660元/月 | AE28: 43988 | AF28: 43988 | AG28: 44079 | AH28: 1980元 | AK28: 44079 | AL28: 6.02
A29: 1 | D29: 1 | E29: 1 | F29: 3 | G29: 20WA00179 | H29: 唐惠怡（数） | J29: twjw32 | K29: 堂堂行 | L29: 老 | M29: 西班牙 | P29: 数学 | Q29: 一对六 | R29: 三十二课堂 第八节 | T29: 一周五天 | U29: 660元/月 | AE29: 43999 | AF29: 43987 | AG29: 44016 | AH29: 660元 | AK29: 44016 | AL29: 6.02
A30: 1 | E30: 1 | F30: 4 | G30: 20WA00180 | H30: 王天缘 | J30: wangzhaonihao | K30: 堂堂行 | L30: 新 | M30: 西班牙 | P30: 中文 | Q30: 一对六 | R30: 四十三课堂 第五节 | T30: 一周五天 | U30: 660元/月 | AB30: 运营部新生 | AE30: 44008 | AF30: 43987 | AG30: 44078 | AH30: 1980元 | AK30: 44078 | AL30: 6.02 | AM30: 运营部新生
A31: 1 | D31: 1 | E31: 1 | F31: 3 | G31: 20WC00250 | H31: 包瑞莹（英） | J31: bao19831012 | K31: 堂堂行 | L31: 老 | M31: 意大利 | P31: 英文 | Q31: 一对六 | R31: 四十五课堂 第三节 | T31: 一周五天 | U31: 640元/月 | AE31: 43991 | AF31: 43991 | AG31: 44082 | AH31: 1920元 | AK31: 44082 | AL31: 6.03
A32: 1 | D32: 1 | E32: 1 | F32: 3 | G32: 20WA00181 | H32: 叶晨欣(英） | J32: liushuangmei1982 | K32: 堂堂行 | L32: 老 | M32: 西班牙 | P32: 英文 | Q32: 一对六 | R32: 四十五课堂 第三节 | T32: 一周五天 | U32: 660元/月 | Y32: 1 | AL32: 6.03
A33: 1 | D33: 1 | E33: 1 | F33: 3 | G33: 20WB0025 | H33: 李子涵1（英） | J33: L571638321 | K33: 堂堂行 | L33: 老 | M33: 葡萄牙海岛 | P33: 英文 | Q33: 一对六 | R33: 四十五课堂 第三节 | T33: 一周五天 | U33: 660元/月 | AE33: 43990 | AF33: 43990 | AG33: 44020 | AH33: 660元 | AK33: 44020 | AL33: 6.03
A34: 1 | D34: 1 | E34: 1 | F34: 3 | G34: 20WC00251 | H34: 叶昊铭（英） | J34: zjpdxyx | K34: 堂堂行 | L34: 老 | M34: 意大利 | P34: 英文 | Q34: 一对六 | R34: 四十五课堂 第三节 | T34: 一周五天 | U34: 660元/月 | AE34: 20/6/08 | AF34: 44019 | AG34: 44019 | AH34: 610元 | AK34: 44019 | AL34: 6.03
A35: 1 | D35: 1 | E35: 1 | F35: 2 | G35: 20WD0058 | H35: yuranran(余冉冉) | J35: one138138 | K35: 堂堂行 | L35: 老 | M35: 巴西 | P35: 中文 | Q35: 一对六 | R35: 四十八课堂 第十节 | T35: 一周五天 | U35: 660元/月 | AE35: 20.6.23 | AF35: 43990 | AG35: 44081 | AH35: 1860元 | AK35: 44081 | AL35: 6.03
A36: 1 | D36: 1 | E36: 1 | F36: 1 | G36: 20WC00252 | H36: 黄可馨 | J36: Jie2782286 | K36: 堂堂行 | L36: 老 | M36: 意大利 | P36: 中文 | Q36: 一对六 | R36: 十二课堂 第五节 | T36: 一周五天 | U36: 660元/月 | AE36: 43998 | AF36: 43991 | AG36: 44020 | AH36: 660元 | AK36: 44020 | AL36: 6.03
A37: 1 | D37: 1 | E37: 1 | F37: 3 | G37: 20WA00182 | H37: 庞梦洁 | J37: xiping_1111 | K37: 堂堂行 | L37: 老 | M37: 西班牙 | P37: 中文 | Q37: 一对六 | R37: 二十八课堂 第十节 | T37: 一周五天 | U37: 660元/月 | AE37: 44016 | AF37: 43991 | AG37: 44020 | AH37: 660元 | AK37: 44020 | AL37: 6.03
A38: 1 | D38: 1 | E38: 1 | F38: 2 | G38: 20WB0026 | H38: 叶君泽 | J38: Zeng963739528 | K38: 堂堂行 | L38: 老 | M38: 葡萄牙 | P38: 中文 | Q38: 一对六 | R38: 四十八课堂 第十节 | T38: 一周五天 | U38: 660元/月 | Y38: 1 | AE38: 44000 | AF38: 43990 | AG38: 44019 | AH38: 660元 | AK38: 44019 | AL38: 6.04
A39: 1 | D39: 1 | E39: 1 | F39: 3 | G39: 20WC00253 | H39: 胡梦蕾（英） | J39: chichichiting | K39: 堂堂行 | L39: 老 | M39: 意大利 | P39: 英文 | Q39: 一对六 | R39: 四十五课堂 第三节 | T39: 一周五天 | U39: 660元/月 | Y39: 1 | AE39: 20/6/11 | AF39: 43990 | AG39: 44081 | AH39: 1980元 | AK39: 44081 | AL39: 6.04
A40: 1 | D40: 追女孩学英文 | E40: 0 | F40: 3 | H40: 周炀（英） | J40: a719465208 | K40: 堂堂行 | L40: 老 | M40: 意大利 | P40: 英文 | Q40: 一对六 | R40: 十四课堂 第五节 | T40: 一周五天 | U40: 660元/月 | X40: 试读失败 | AL40: 6.04
...

Sheet 2020.05
A1: 国家 | B1: 科目 | C1: 学生 | D1: 课程安排 | E1: 试读日期 | G1: 新生到课情况 | J1: 是否回访 | L1: 是否缴费 | N1: 备注
A2: 葡萄牙 | B2: 中文 | C2: 陈锦汝 | D2: 八课堂 第七节 | E2: 5.04 | F2: 2 | G2: 1 | M2: 5.11
A3: 意大利 | B3: 中文 | C3: 陈梦琪 | D3: 八课堂 第七节 | E3: 5.04 | F3: 2 | G3: 1 | M3: 5.15
A4: 荷兰 | B4: 中文 | C4: 潘书雅 | D4: 八课堂 第七节 | E4: 5.04 | F4: 2 | G4: 1 | M4: 5.15
A5: 意大利 | B5: 中文 | C5: 焦梓 | D5: 八课堂 第七节 | E5: 5.04 | F5: 2 | G5: 1 | M5: 5.15
A6: 西班牙 | B6: 中文 | C6: 蒋俊豪 | D6: 八课堂 第七节 | E6: 5.04 | F6: 2 | G6: 1 | M6: 5.19
A7: 意大利 | B7: 中文 | C7: 温杰利 | D7: 四课堂 第八节 | E7: 5.04 | F7: 4 | M7: 5.07
A8: 西班牙 | B8: 中文 | C8: 叶竞骏 | D8: 五十三课堂 第二节 | E8: 5.05 | F8: 4 | M8: 5.18
A9: 意大利 | B9: 数学 | C9: 虞冠中（数） | D9: 十一课堂 第六节 | E9: 5.05 | F9: 4 | M9: 5.18
A10: 意大利 | B10: 中文 | C10: 郑语涵 | D10: 三十课堂 第八节 | E10: 5.05 | F10: 1 | G10: 1 | H10: 1 | M10: 5.06
A11: 西班牙 | B11: 中文 | C11: 潘若茜 | D11: 十课堂 第七节 | E11: 5.05 | F11: 2 | M11: 5.09
A12: 西班牙 | B12: 英文 | C12: 潘若茜 | D12: 五十八课堂 第十节 | E12: 5.05 | F12: 3 | J12: 试读失败
A13: 意大利 | B13: 中文 | C13: 叶新裕 | D13: 十课堂 第七节 | E13: 5.05 | F13: 2 | M13: 5.15
A14: 葡萄牙 | B14: 中文 | C14: 叶铭哲 | D14: 三十八课堂 第十节 | E14: 5.05 | F14: 2 | G14: 1 | H14: 1 | I14: 1 | J14: 试读失败
A15: 巴西 | B15: 数学 | C15: 朱家豪2 | D15: 四十九课堂 6:00-6:30 | E15: 5.05 | F15: 3 | M15: 5.18
A16: 意大利 | B16: 中文 | C16: 焦心蕾 | D16: 四课堂第五节 | E16: 5.06 | F16: 4 | M16: 5.15
A17: 巴西 | B17: 中文 | C17: 叶奕辰 | D17: 四十一课堂第二节 | E17: 5.06 | F17: 2 | K17: 1 | L17: 1 | M17: 6.09 | N17: 19岁
A18: 巴西 | B18: 中文 | C18: 叶欣佁 | D18: 四十一课堂第二节 | E18: 5.06 | F18: 2 | J18: 试读失败
A19: 西班牙 | B19: 数学 | C19: 潘若茜（数） | D19: 一课堂 第六节 | E19: 5.06 | F19: 3 | M19: 5.09
A20: 奥地利 | B20: 中文 | C20: 刘懿暄 | D20: 三十八课堂 第五节 | E20: 5.06 | F20: 2 | M20: 5.15
A21: 巴西 | B21: 中文 | C21: 陈墨轩 | D21: 十课堂 第五节 | E21: 5.06 | F21: 2 | M21: 5.15
A22: 西班牙 | B22: 中文 | C22: 郭可欣 | D22: 十课堂 第五节 | E22: 5.06 | F22: 2 | M22: 转白班在读
A23: 西班牙 | B23: 中文 | C23: 郭欣得 | D23: 八课堂 第七节 | E23: 5.06 | F23: 2 | M23: 转白班在读
A24: 西班牙 | B24: 中文 | C24: 邹雨欣 | D24: 五十二课堂 第十二节 | E24: 5.06 | F24: 2 | M24: 5.19
A25: 西班牙 | B25: 中文 | C25: 邹博宇 | D25: 二十二课堂 第六节 | E25: 5.06 | F25: 1 | G25: 1 | H25: 试读失败
A26: 西班牙 | B26: 中文 | C26: 张婕 | D26: 五十六课堂 第十二节 | E26: 5.06 | F26: 4 | M26: 5.22
A27: 意大利 | B27: 英文 | C27: 虞冠中（英） | D27: 十四课堂 第三节 | E27: 5.06 | F27: 2 | M27: 5.18
A28: 西班牙 | B28: 英文 | C28: 桑德拉（英） | D28: 十四课堂 第三节 | E28: 5.06 | F28: 2 | M28: 5.27
A29: 西班牙 | B29: 中文 | C29: 朱语欣 | D29: 五十六课堂 第三节 | E29: 5.06 | F29: 4 | J29: 试读失败
A30: 意大利 | B30: 中文 | C30: 张安娜 | D30: 二十六课堂 第七节 | E30: 5.06 | F30: 2 | M30: 5.28
A31: 西班牙 | B31: 中文 | C31: 张浩宇 | D31: 三十八课堂 第八节 | E31: 5.06 | F31: 2 | M31: 5.09
A32: 意大利 | B32: 中文 | C32: 曦曦 | D32: 十课堂 第五节 | E32: 5.06 | F32: 2 | J32: 试读失败
A33: 意大利 | B33: 中文 | C33: 黄衍凯 | D33: 十课堂 第九节 | E33: 5.06 | F33: 2 | L33: 1 | M33: 5.19
A34: 希腊 | B34: 数学 | C34: 黄浩然（数） | D34: 四十四课堂 第五节 | E34: 5.06 | F34: 3 | M34: 5.09
A35: 巴西 | B35: 数学 | C35: 李煜（数） | D35: 四十九课堂 第九节 | E35: 5.06 | F35: 3 | M35: 5.25
A36: 西班牙 | B36: 中文 | C36: 彭宇航 | D36: 五十六课堂第十一节 | E36: 5.06 | F36: 4 | M36: 5.15 | N36: 老生重读
A37: 美国 | B37: 双语中文 | C37: 发发1 | D37: 十八课堂 第一节 | E37: 5.06 | F37: 兼职 | J37: 试读失败
A38: 美国 | B38: 双语中文 | C38: 宝宝1 | D38: 十八课堂 第一节 | E38: 5.06 | F38: 兼职 | J38: 试读失败
A39: 西班牙 | B39: 中文 | C39: 陈亚楠 | D39: 五十三课堂 第七节 | E39: 5.07 | F39: 4 | M39: 5.15
A40: 西班牙 | B40: 中文 | C40: 程金雅萱 | D40: 十课堂 第五节 | E40: 5.07 | F40: 2 | K40: 1
...

Sheet 2020.04
A1: 国家 | B1: 科目 | C1: 学生 | D1: 课程安排 | E1: 试读日期 | G1: 新生到课情况 | J1: 是否回访 | L1: 是否缴费 | M1: 缴费日期 | N1: 备注
A2: 巴西 | B2: 中文 | C2: 郭畅 | D2: 五课堂6:30 | E2: 4.01 | F2: 1 | G2: 1 | H2: 1 | I2: 1 | M2: 4.03
A3: 巴西 | B3: 中文 | C3: 郭好 | D3: 十课堂5:20 | E3: 4.01 | F3: 2 | G3: 1 | M3: 4.03
A4: 巴西 | B4: 中文 | C4: 郭阳 | D4: 五课堂6:30 | E4: 4.01 | F4: 1 | G4: 1 | H4: 1 | I4: 1 | M4: 4.03
A5: 西班牙 | B5: 中文 | C5: 章宇婧 | D5: 三十八课堂第一节课 | E5: 4.02 | F5: 2 | G5: 1 | H5: 1 | I5: 1 | M5: 5.07
A6: 意大利 | B6: 中文 | C6: 叶昕阳 | D6: 五十二课堂第一节课 | E6: 4.02 | F6: 4 | G6: 1
A7: 希腊 | B7: 中文 | C7: 叶米娜 | D7: 三十八课堂第三节课 | E7: 4.02 | F7: 2 | G7: 1 | H7: 1 | M7: 从叶安娜2处分八个月
A8: 西班牙 | B8: 中文 | C8: 朱逸晨 | D8: 三十八课堂第三节课 | E8: 4.02 | F8: 2 | G8: 1 | H8: 1 | I8: 试读失败 | N8: 试读失败
A9: 西班牙海岛 | B9: 中文 | C9: 陈起锐 | D9: 二十七课堂第四节课 | E9: 4.02 | F9: 4 | G9: 1 | N9: 4.8试读失败
A10: 西班牙海岛 | B10: 中文 | C10: 王战鑫 | D10: 三十八课堂第三节课 | E10: 4.02 | F10: 2 | G10: 1 | H10: 1 | I10: 0
A11: 西班牙 | B11: 中文 | C11: 周凯文 | D11: 三十八课堂第三节课 | E11: 4.02 | F11: 2 | G11: 1 | H11: 1 | I11: 1
A12: 西班牙 | B12: 中文 | C12: 徐佳儿 | D12: 五十四课堂第二节课 | E12: 4.02 | F12: 3 | G12: 1 | H12: 1 | I12: 1 | M12: 5.13
A13: 西班牙 | B13: 中文 | C13: 徐嘉诚 | D13: 三十八课堂第三节课 | E13: 4.02 | F13: 2 | G13: 1 | H13: 1 | M13: 5.13
A14: 西班牙 | B14: 中文 | C14: 林文轩 | D14: 三十八课堂第二节课 | E14: 4.02 | F14: 2 | G14: 1 | H14: 1 | I14: 1 | M14: 5.20
A15: 西班牙海岛 | B15: 中文 | C15: 陈佳瑜 | D15: 三十八课堂第三节课 | E15: 4.02 | F15: 2 | G15: 1 | H15: 1 | I15: 试读失败 | N15: 试读失败
A16: 希腊 | B16: 中文 | C16: 胡雅晗 | D16: 十三课堂第十节课 | E16: 4.02 | F16: 3 | G16: 1 | H16: 1 | I16: 1 | J16: 1 | M16: 5.18
A17: 希腊 | B17: 中文 | C17: 胡浩元1 | D17: 十三课堂第十节课 | E17: 4.02 | F17: 3 | G17: 1 | H17: 1 | I17: 1 | J17: 1 | M17: 5.18
A18: 捷克 | B18: 数学 | C18: 胡立源 | D18: 十一课堂第七节课 | E18: 4.02 | F18: 4 | G18: 1 | M18: 4.03
A19: 意大利 | B19: 中文 | C19: 陈莉莎 | D19: 三十八课堂第四节课 | E19: 4.02 | F19: 2 | G19: 1 | H19: 1 | I19: 1 | M19: 5.09
A20: 意大利 | B20: 中文 | C20: 黄铭翔 | D20: 五十八课堂第四节课 | E20: 4.02 | F20: 4 | G20: 1 | M20: 4.25
A21: 巴西 | B21: 中文 | C21: 袁乐琛 | D21: 四十一课堂第三节课 | E21: 4.02 | F21: 2 | G21: 1 | H21: 1 | I21: 1
A22: 巴西 | B22: 数学 | C22: 袁乐琛 | D22: 十一课堂5:00 | E22: 4.02 | F22: 4 | G22: 1 | M22: 5.06
A23: 意大利 | B23: 中文 | C23: 柳程怡 | D23: 十三课堂第四节课 | E23: 4.02 | F23: 3 | G23: 1 | H23: 1 | I23: 1 | J23: 1 | M23: 4.05
A24: 葡萄牙海岛 | B24: 中文 | C24: 柳怡 | D24: 三十八课堂第四节课 | E24: 4.02 | F24: 2 | G24: 1 | H24: 1 | I24: 1 | M24: 4.26
A25: 葡萄牙海岛 | B25: 中文 | C25: 柳彦1 | D25: 三十八课堂第四节课 | E25: 4.02 | F25: 2 | G25: 1 | H25: 1 | I25: 1 | M25: 4.26
A26: 西班牙 | B26: 中文 | C26: 朱雨昕 | D26: 三十八课堂第四节课 | E26: 4.02 | F26: 2 | G26: 1 | H26: 1 | I26: 1 | M26: 5.11
A27: 美国 | B27: 中文 | C27: 赵艾米 | D27: 五十六课堂第十一节课 | E27: 4.02 | F27: 4 | G27: 1 | M27: 4.03
A28: 西班牙 | B28: 中文 | C28: 王理轩 | D28: 三十八课堂第二节课 | E28: 4.03 | F28: 2 | G28: 1 | H28: 1 | I28: 1 | N28: 运营部新生
A29: 西班牙 | B29: 中文 | C29: 翁佳慧 | D29: 十三课堂第一节课 | E29: 4.03 | F29: 3 | G29: 1 | H29: 试读失败 | N29: 运营部新生
A30: 巴西 | B30: 中文 | C30: 黄俊皓 | D30: 三十八课堂第四节课 | E30: 4.03 | F30: 2 | G30: 1 | H30: 1 | M30: 4.27
A31: 葡萄牙海岛 | B31: 数学 | C31: 柳彦1 | D31: 十一课堂第三节课 | E31: 4.03 | F31: 4 | G31: 1 | M31: 4.26
A32: 葡萄牙海岛 | B32: 数学 | C32: 柳怡 | D32: 四十九课堂第五节课 | E32: 4.03 | F32: 3 | G32: 1 | H32: 1 | I32: 1 | M32: 4.26
A33: 西班牙 | B33: 数学 | C33: 徐均盛 | D33: 十一课堂第七节课 | E33: 4.03 | F33: 4 | G33: 1 | M33: 5.14
A34: 巴西 | B34: 中文 | C34: 方浩轩 | D34: 三十九课堂第三节课 | E34: 4.03 | F34: 1 | G34: 1 | H34: 1 | M34: 4.09
A35: 巴西 | B35: 数学 | C35: 方浩轩 | D35: 十一课堂第五节课 | E35: 4.03 | F35: 4 | G35: 1 | M35: 4.09
A36: 西班牙海岛 | B36: 中文 | C36: 许泽凯 | D36: 十九课堂第六节课 | E36: 4.03 | F36: 2 | G36: 1
A37: 西班牙海岛 | B37: 中文 | C37: 许吴菲 | D37: 二十七课堂第七节课 | E37: 4.03 | F37: 4 | G37: 1
A38: 意大利 | B38: 中文 | C38: 纪柯艳 | D38: 三十八课堂第一节课 | E38: 4.03 | F38: 2 | G38: 1 | H38: 1 | M38: 4.7
A39: 西班牙 | B39: 中文 | C39: 徐宇浩 | D39: 十三课堂第三节课 | E39: 4.03 | F39: 3 | G39: 1 | H39: 1 | I39: 1 | J39: 1 | M39: 5.08
A40: 西班牙 | B40: 中文 | C40: 徐宇芯 | D40: 三十八课堂第四节课 | E40: 4.03 | F40: 2 | G40: 1 | M40: 5.08
...

Sheet 2020.03
A1: 国家 | B1: 科目 | C1: 学生 | D1: 课堂 | E1: 试读日期 | F1: 组别 | G1: 新生到课情况 | J1: 是否回访 | L1: 是否缴费 | M1: 缴费日期 | N1: 备注
A2: 意大利 | B2: 中文 | C2: 魏铭轩 | D2: 二十七课堂第七节 | E2: 3.2 | F2: 4 | G2: 1 | H2: 1 | I2: 1
A3: 意大利 | B3: 中文 | C3: 柯睿媛 | D3: 六课堂第八节 | E3: 3.2 | F3: 4 | G3: 1 | H3: 1 | I3: 1
A4: 意大利 | B4: 中文 | C4: 潘佳琦 | D4: 二十七课堂第八节 | E4: 3.2 | F4: 4 | G4: 1 | H4: 1 | I4: 1
A5: 意大利 | B5: 中文 | C5: 邱叶旋 | D5: 三十九课堂第四节 | E5: 3.2 | F5: 2
A6: 意大利 | B6: 中文 | C6: 邱琪深 | D6: 四十七课堂第八节 | E6: 3.2 | F6: 4
A7: 意大利 | B7: 中文 | C7: 邱烁颖 | D7: 四十七课堂第八节 | E7: 3.2 | F7: 4
A8: 西班牙 | B8: 数学 | C8: 杨昕蕊 | D8: 二十一课堂第三节 | E8: 3.2 | F8: 1 | G8: 1 | H8: 1 | I8: 1
A9: 西班牙 | B9: 英语 | C9: 杨昕蕊 | D9: 六课堂第六节 | E9: 3.2 | F9: 4 | G9: 1 | H9: 1 | I9: 1 | L9: 1 | M9: 3.2
A10: 意大利 | B10: 中文 | C10: 洪佳乐 | D10: 三十六课堂第五节 | E10: 3.2 | F10: 1 | G10: 1 | H10: 1 | I10: 1
A11: 意大利 | B11: 英语 | C11: 洪佳乐 | D11: 四十八课堂第六节 | E11: 3.2 | F11: 1 | G11: 1 | H11: 1 | I11: 1
A12: 意大利 | B12: 中文 | C12: 洪杉杉 | D12: 七课堂第二节 | E12: 3.2 | F12: 1 | G12: 1 | H12: 1 | I12: 1
A13: 意大利 | B13: 英语 | C13: 洪杉杉 | D13: 二课堂第三节 | E13: 3.2 | F13: 1 | G13: 1 | H13: 1 | I13: 1
A14: 意大利 | B14: 英语 | C14: 洪晨燚 | D14: 六课堂第九节 | E14: 3.3 | F14: 4 | G14: 1 | H14: 1 | I14: 1
A15: 意大利 | B15: 中文 | C15: 洪晨燚 | D15: 三十六课堂第三节 | E15: 3.3 | F15: 1 | G15: 1 | H15: 1 | I15: 1
A16: 葡萄牙 | B16: 中文 | C16: 彭雅琦 | D16: 三十一课堂第十一节 | E16: 3.3 | F16: 3 | G16: 1 | H16: 1 | I16: 1
A17: 葡萄牙 | B17: 中文 | C17: 彭雅琰 | D17: 五十六课堂第九节 | E17: 3.4 | F17: 4 | G17: 1 | H17: 1 | I17: 1
A18: 美国 | B18: 中文 | C18: 辰辰 | D18: 二十二课堂6:30 | E18: 3.4 | F18: 1 | G18: 1 | H18: 1 | I18: 1
A19: 西班牙 | B19: 中文 | C19: 何矜矜 | D19: 五十五课堂第十节 | E19: 3.5 | F19: 3 | G19: 1 | H19: 1 | I19: 1
A20: 意大利 | B20: 中文 | C20: 杨承智 | D20: 六课堂第八节 | F20: 4 | G20: 1 | H20: 1 | I20: 1
A21: 意大利 | B21: 中文 | C21: 杨承栋 | D21: 五十六课堂第八节 | E21: 3.4 | F21: 4 | G21: 1 | H21: 1 | I21: 1
A22: 意大利 | B22: 中文 | C22: 王宇智 | D22: 六课堂第八节 | F22: 4 | G22: 1 | H22: 1 | I22: 1
A23: 意大利 | B23: 中文 | C23: 叶琦娇 | D23: 五十四课堂第十节 | E23: 3.4 | F23: 3 | G23: 1 | H23: 1 | I23: 1
A24: 意大利 | B24: 中文 | C24: 丹尼 | D24: 二十八课堂 | F24: 3 | G24: 未到课堂
A25: 意大利 | B25: 中文 | C25: 陈洁妮 | D25: 二十八课堂 | E25: 3.7 | F25: 3 | G25: 1 | H25: 1 | I25: 1
A26: 西班牙 | B26: 中文 | C26: 傅双俊 | D26: 五十四课堂第九节 | F26: 3 | G26: 1 | H26: 1 | I26: 1
A27: 西班牙 | B27: 中文 | C27: 傅俊羽 | D27: 五十六课堂第八节 | F27: 4 | G27: 1 | H27: 1 | I27: 1
A28: 意大利 | B28: 数学 | C28: 蒋俊哲 | D28: 十一课堂 | E28: 3.3 | F28: 4 | G28: 1 | H28: 1 | I28: 1 | J28: 1
A29: 意大利 | B29: 数学 | C29: 林静怡 | D29: 十一课堂 | E29: 3.3 | F29: 4 | G29: 1 | H29: 1 | I29: 1
A30: 意大利 | B30: 中文 | C30: 梅子1 | D30: 四十课堂第七节 | E30: 3.4 | F30: 3 | G30: 1 | H30: 1 | I30: 1
A31: 西班牙 | B31: 中文 | C31: 爱琳 | D31: 三十四课堂第四节 | E31: 3.7 | F31: 3 | G31: 1 | H31: 1 | I31: 1
A32: 西班牙 | B32: 中文 | C32: 索菲 | D32: 四十三课堂第五节 | E32: 3.7 | F32: 3 | G32: 1 | H32: 1 | I32: 1
A33: 意大利 | B33: 数学 | C33: 金依涟 | D33: 二十一课堂第八节 | F33: 1 | G33: 1 | H33: 1
A34: 意大利 | B34: 英语 | C34: 张郡雪 | D34: 四十二课堂第十节 | E34: 3.5 | F34: 3 | G34: 1 | H34: 1 | I34: 1
A35: 意大利 | B35: 中文 | C35: 吴梦冉 | D35: 五十五课堂第四节 | E35: 3.5 | F35: 3 | G35: 1 | H35: 1 | I35: 1
A36: 意大利 | B36: 中文 | C36: 何金诺 | D36: 六课堂第四节 | E36: 3.5 | F36: 4 | G36: 1 | H36: 1 | I36: 1
A37: 意大利 | B37: 数学 | C37: 何金诺 | D37: 十一课堂第三节 | E37: 3.5 | F37: 4 | G37: 1 | H37: 1 | I37: 1
A38: 意大利 | B38: 中文 | C38: 朱俊豪1 | D38: 三十四课堂第二节 | E38: 3.5 | F38: 3 | G38: 1 | H38: 1 | I38: 1
A39: 巴西 | B39: 中文 | C39: 王卓颖 | D39: 二十二课堂6:30 | E39: 3.5 | F39: 1 | G39: 1 | H39: 需要专业老师 | L39: （老生重读）
A40: 意大利 | B40: 中文 | C40: 何睿毅 | D40: 三十六课堂第一节 | E40: 3.5 | F40: 1 | G40: 1
...

Sheet 2020.01
A1: 国家 | B1: 学生 | C1: 课堂 | D1: 试读日期 | F1: 新生到课情况 | I1: 是否回访 | K1: 是否缴费 | L1: 缴费日期 | M1: 备注
E2: 组别 | F2: 第1天 | G2: 第2天 | H2: 第3天 | I2: 老师回访 | J2: 咨询回访
A3: 西班牙 | B3: 吴旭霞 | C3: 三课堂二上第一节 | D3: 43831 | E3: 1 | F3: 1 | G3: 1 | H3: 1 | M3: 1.8开始第二节
A4: 西班牙 | B4: 吴崇硕 | C4: 一上第八节 | D4: 43831 | E4: 3 | F4: 1 | G4: 1 | H4: 1 | M4: 1.8开始第二节
A5: 西班牙 | B5: 詹欣怡 | C5: 一课堂第五节 | D5: 43832 | E5: 3 | F5: 1 | G5: 1 | H5: 1
A6: 西班牙 | B6: 詹可怡 | C6: 二十一课堂第三节 | D6: 43832 | E6: 1 | F6: 1 | G6: 1 | H6: 1
A7: 意大利 | B7: 陈凯 | C7: 二十二课堂第二节 | D7: 43831 | E7: 1 | F7: 1 | G7: 1 | H7: 1
A8: 德国 | B8: 陈洁2 | C8: 新生接待课堂 | D8: 43832 | F8: 1 | M8: 放假结束再来
A9: 德国 | B9: 陈佳1 | C9: 新生接待课堂 | D9: 43832 | F9: 1 | M9: 放假结束再来
A10: 意大利 | B10: 胡玲玮 | C10: 七课堂第五节 | D10: 43832 | E10: 1 | F10: 1 | G10: 1 | H10: 1
A11: 意大利 | B11: 胡玲玮 | C11: 六课堂第七节 | D11: 43832 | E11: 4 | F11: 意大利 | G11: 胡玲玮 | H11: 六课堂第七节
A12: 意大利 | B12: 项婷婷 | C12: 四十五课堂第十节 | D12: 43832 | E12: 4 | F12: 意大利 | G12: 项婷婷 | H12: 四十五课堂第十节
A13: 意大利 | B13: 项智豪 | C13: 四十五课堂第十节 | D13: 43832 | E13: 4 | F13: 意大利 | G13: 项智豪 | H13: 四十五课堂第十节
A14: 西班牙 | B14: 叶子阳 | C14: 四十课堂第五节 | D14: 43833 | E14: 3 | F14: 1 | G14: 1 | H14: 1 | I14: 1
A15: 奥地利 | B15: 吴雨森 | C15: 四十五课堂第二节 | D15: 43833 | E15: 4 | F15: 西班牙 | G15: 罗俊浩 | H15: 六课堂第三节
A16: 西班牙 | B16: 罗俊浩 | C16: 六课堂第三节 | D16: 43833 | E16: 4 | F16: 意大利 | G16: 程贤之 | H16: 二十七课堂第十节
A17: 意大利 | B17: 程贤之 | C17: 二十七课堂第十节 | D17: 43833 | E17: 4 | F17: 西班牙 | G17: 陈梓豪 | H17: 五十六课堂第九节
A18: 西班牙 | B18: 杨嘉怡 | C18: 四十四课堂第二节 | D18: 43833 | G18: 1 | H18: 1 | M18: 转周末班
A19: 西班牙 | B19: 杨嘉心 | C19: 四十四课堂第二节 | D19: 43833 | G19: 1 | H19: 1
A20: 意大利 | B20: 晟璐 | C20: 三十一课堂第七节 | D20: 43833 | E20: 3 | F20: 1 | G20: 1 | H20: 1 | I20: 是
A21: 意大利 | B21: 源涛 | C21: 三十一课堂第四节 | D21: 43833 | E21: 3 | F21: 1 | G21: 1 | H21: 1 | I21: 是
A22: 西班牙 | B22: 徐馨怡 | C22: 三十四课堂周末00:30 | D22: 43833 | E22: 1 | F22: 1 | G22: 1
A23: 西班牙 | B23: 徐奕豪 | C23: 三十四课堂周末00:30 | D23: 43833 | E23: 1 | F23: 1 | G23: 1
A24: 意大利 | B24: 徐逸飞 | C24: 五十五课堂第四节 | D24: 43833 | E24: 3 | F24: 1 | G24: 1 | H24: 1
A25: 意大利 | B25: 吴若煦 | C25: 数学课堂03周日17:00 | D25: 43835
A26: 西班牙 | B26: 陈嘉豪 | C26: 五十五第八节 | D26: 43836 | E26: 3 | F26: 1 | G26: 1 | H26: 1
A27: 西班牙 | B27: 陈梓豪 | C27: 五十六课堂第九节 | D27: 43836 | E27: 4 | F27: 西班牙 | G27: 叶逸欧 | H27: 六课堂第三节
A28: 葡萄牙 | B28: 翁烁 | C28: 三十课堂第六节 | D28: 43836 | E28: 3 | G28: 1 | H28: 1 | I28: 是
A29: 葡萄牙 | B29: 翁航 | C29: 五课堂A第七节 | D29: 43836 | E29: 1 | F29: 1 | G29: 1
A30: 意大利 | B30: 戴百嘉 | C30: 六课堂第七节 | D30: 43836 | E30: 4 | F30: 希腊 | G30: 陈泽屹 | H30: 四十五课堂第五节
A31: 西班牙 | B31: 金以瑞 | C31: 五十五课堂第四节 | D31: 43837 | E31: 3 | F31: 1 | G31: 1 | H31: 1
A32: 西班牙 | B32: 戴澄 | C32: 二十六课堂第一节 | D32: 43837 | E32: 1 | F32: 1 | G32: 1 | H32: 1
A33: 德国 | B33: 郑鑫 | C33: 五十五课堂第四节 | D33: 43837 | E33: 3 | F33: 1 | G33: 0 | H33: 0 | M33: 试读失败
A34: 法国 | B34: 陈宣羽 | C34: ChineseonlineN课堂8:00 | D34: 43781 | F34: 1 | M34: 补登记
A35: 意大利 | B35: 陈慧淋 | C35: 三十六课堂第五节 | D35: 43837 | E35: 1 | F35: 1 | G35: 1 | H35: 1
A36: 美国 | B36: 里恩 | C36: 新生接待课堂 | D36: 43837 | F36: 1
A37: 西班牙 | B37: 周祺恩 | C37: 新生接待课堂 | D37: 43838 | F37: 1
A38: 西班牙 | B38: 夏谨睿 | C38: 五十六课堂第十节 | D38: 43838 | E38: 4 | F38: 西班牙 | G38: 朱雅琦 | H38: 二十七课堂18:00
A39: 西班牙 | B39: 蒋雨琪 | C39: 二十七课堂第十节 | D39: 43838 | E39: 4 | F39: 西班牙海岛 | G39: 林思翰 | H39: 二十七课堂第十节
A40: 法国 | B40: 吴米娜 | C40: 四课堂第九节 | D40: 1.03 | E40: 1 | F40: 1 | G40: 1 | H40: 1
...

Sheet 2019.11
A1: 国家 | B1: 学生 | C1: 课堂 | D1: 试读日期 | E1: 新生到课情况 | L1: 是否回访 | N1: 是否缴费 | O1: 缴费日期 | P1: 备注
E2: 第1天 | F2: 第2天 | G2: 第3天 | H2: 第4天 | I2: 第5天 | J2: 第6天 | K2: 第7天 | L2: 老师回访 | M2: 咨询回访
A3: 意大利 | B3: 虞潇 | C3: 二十八课堂第五节 | D3: 11.01 | N3: 是
A4: 西班牙海岛 | B4: 陈彩洁 | C4: 四十五课堂第五节 | D4: 11.01 | E4: 1 | F4: 1 | G4: 1 | H4: 1 | I4: 0 | J4: 0 | M4: 是 | P4: 孩子不愿意学了，家长说不来上课了
A5: 意大利 | B5: 毛铼熠 | C5: 四十五课堂第十节 | D5: 11.01 | E5: 1 | F5: 1 | G5: 1 | H5: 1 | I5: 1 | J5: 0 | N5: 是 | P5: 目前家长想要从aoe开始学，没有合适的时间和课
A6: 意大利 | B6: 吴雨静 | C6: 四十五课堂第六节 | D6: 11.01 | E6: 1 | F6: 1 | G6: 1 | H6: 1 | I6: 1 | J6: 1 | K6: 1 | M6: 是 | N6: 是
A7: 葡萄牙 | B7: 留佳 | C7: 四十二课堂第六节 | D7: 11.01 | M7: 是 | N7: 是
A8: 西班牙 | B8: 虞珊 | C8: 十三课堂第十一节 | D8: 11.01 | E8: 1 | F8: 0 | G8: 0 | H8: 0 | I8: 0 | M8: 是
A9: 挪威 | B9: 周佳欣3 | C9: 三十一课堂第四节 | D9: 11.01 | E9: 1 | F9: 1 | G9: 1 | H9: 1 | I9: 1 | M9: 是 | P9: 学生刚到挪威，家长希望孩子先学好挪威当地的语言
A10: 西班牙 | B10: 朱芳仪 | C10: 九课堂上课20:30 | D10: 11.02 | M10: 是 | N10: 是
A11: 西班牙海岛 | B11: 蔡铭瑜 | C11: 到十三课堂A 24:00 | D11: 11.02
A12: 西班牙海岛 | B12: 陈铭杰 | C12: 十三课堂A 24:00 | D12: 11.02
A13: 西班牙 | B13: 姚心一 | C13: 美术课堂21:00 | D13: 11.02 | M13: 是 | N13: 是
A14: 西班牙 | B14: 朱俊豪 | C14: 数学课堂18:20 | D14: 11.02
A15: 西班牙 | B15: 朱俊毅 | C15: 数学课堂19:20 | D15: 11.02
A16: 西班牙 | B16: 陈捷琪 | C16: 十九课堂第十节 | D16: 11.04 | E16: 1 | F16: 1 | G16: 0 | P16: 孩子觉得班级枯燥，不读了，调整班级回绝了
A17: 西班牙 | B17: 朱捷妮 | C17: 三十八课堂第八节 | D17: 11.04 | E17: 1 | F17: 1 | G17: 1 | P17: 试读失败
A18: 西班牙 | B18: 陈航勇 | C18: 四课堂第十一节 | D18: 11.04 | E18: 1 | F18: 1 | G18: 1 | H18: 1 | I18: 1 | J18: 0 | L18: 是 | M18: 是
A19: 西班牙 | B19: 陈馨妍 | C19: 四十一课堂第三节 | D19: 11.04 | E19: 1 | F19: 1 | G19: 1 | H19: 1 | I19: 1 | J19: 0 | M19: 是
A20: 西班牙 | B20: 陈航峻 | C20: 三十六课堂第一节 | D20: 11.04 | E20: 1 | F20: 1 | G20: 1 | H20: 1 | I20: 1 | J20: 0 | L20: 是 | M20: 是
A21: 西班牙 | B21: 黄函艺 | C21: 十三课堂第八节 | D21: 11.04 | M21: 是 | N21: 是
A22: 西班牙 | B22: 李炫 | C22: 十一课堂第八节 | D22: 11.04 | E22: 1 | F22: 1 | M22: 否
A23: 意大利 | B23: 朱安娜3 | C23: 四十五课堂第七节 | D23: 11.04 | E23: 1 | F23: 1 | G23: 1 | H23: 1 | I23: 1 | J23: 1 | M23: 是
A24: 西班牙 | B24: 叶雨俊 | C24: 四十五课堂第六节 | D24: 11.04 | E24: 0 | F24: 0 | M24: 是
A25: 意大利 | B25: 陈芊妤 | C25: 七课堂第二节 | D25: 11.04 | E25: 1 | F25: 1 | G25: 0 | M25: 是
A26: 意大利 | B26: 黄泽宇 | C26: 四十五课堂第五节 | D26: 11.04 | E26: 1 | F26: 1 | G26: 1 | H26: 1 | I26: 1 | J26: 1 | K26: 1 | M26: 是 | N26: 是
A27: 葡萄牙 | B27: 王碧瑶 | C27: 十六课堂第六节 | D27: 11.04 | E27: 1 | F27: 1 | G27: 1 | H27: 1 | I27: 1 | J27: 1 | K27: 1 | M27: 是 | N27: 是
A28: 西班牙 | B28: 叶璋涵 | C28: 三十八课堂第八节 | D28: 11.04 | E28: 1 | F28: 1 | G28: 1 | H28: 1 | I28: 1 | J28: 1 | K28: 1 | M28: 是 | N28: 是
A29: 西班牙 | B29: 厉韵涵 | C29: 四课堂第八节 | D29: 11.04 | E29: 0 | F29: 1 | G29: 1 | H29: 1 | I29: 1 | J29: 1 | K29: 1 | L29: 是 | M29: 是 | N29: 是
A30: 西班牙 | B30: 厉徐涵 | C30: 二十八课堂第十节 | D30: 11.04 | M30: 是 | N30: 是
A31: 意大利 | B31: 吴佳佳 | C31: 四十五课堂第五节 | D31: 11.05 | E31: 1 | F31: 1 | G31: 1 | H31: 1 | I31: 1 | J31: 1 | M31: 否 | N31: 是
A32: 西班牙 | B32: 李诺琳1 | C32: 三十三课堂第八节 | D32: 11.05 | E32: 0 | F32: 0 | G32: 1 | H32: 1 | I32: 1 | J32: 1 | K32: 1 | M32: 是 | N32: 是
A33: 西班牙 | B33: 叶湘怡 | C33: 二十三课堂第六节 | D33: 11.05 | E33: 1 | F33: 1 | G33: 1 | H33: 1 | I33: 1 | J33: 1 | K33: 1 | M33: 是 | N33: 是
A34: 西班牙 | B34: 李炫 | C34: 十三课堂第十一节 | D34: 11.05 | E34: 1 | F34: 1 | M34: 否 | N34: 是
A35: 西班牙 | B35: 朱歆妤 | C35: 四十六课堂第十一节 | D35: 11.05 | N35: 是
A36: 意大利 | B36: 晨曦 | C36: 二十二课堂第十一节 | D36: 11.05 | E36: 1 | F36: 1 | G36: 1 | H36: 0
A37: 美国 | B37: 潘尚恩 | C37: 四十三课堂7:30 | D37: 11.06 | E37: 1 | F37: 1
A38: 德国 | B38: 李凯诺 | C38: 四十五课堂第七节 | D38: 11.06 | E38: 1 | F38: 1 | G38: 1 | H38: 1 | I38: 1 | O38: 11.08
A39: 西班牙 | B39: 朱玮弘 | C39: 第十三课堂第八节 | D39: 11.06 | E39: 1 | F39: 1 | G39: 1
A40: 西班牙 | B40: 朱玮杰 | C40: 第三十七课堂第九节 | D40: 11.06 | E40: 1 | F40: 1 | G40: 1
...

Sheet 2019.12
A1: 国家 | B1: 学生 | C1: 课堂 | D1: 试读日期 | E1: 新生到课情况 | H1: 是否回访 | J1: 是否缴费 | K1: 缴费日期 | L1: 备注
E2: 第1天 | F2: 第2天 | G2: 第3天 | H2: 老师回访 | I2: 咨询回访
A3: 巴西 | B3: 徐喆 | C3: 七课堂第十二节 | D3: 12.02 | E3: 1 | F3: 1 | G3: 1 | H3: 是 | J3: 是
A4: 巴西 | B4: 梁锡康 | C4: ChineseonlineQ课堂8:40 | D4: 12.02 | E4: 1 | J4: 是
A5: 巴西 | B5: 梁锡健 | C5: ChineseonlineQ课堂8:40 | D5: 12.02 | E5: 1 | J5: 是
A6: 西班牙 | B6: 程迪文 | C6: 新生接待课堂 | D6: 12.02 | E6: 1 | F6: 1 | G6: 1 | H6: 是 | J6: 是
A7: 西班牙 | B7: 西西 | C7: 新生接待课堂 | D7: 12.02 | E7: 1 | F7: 1 | G7: 1 | H7: 是 | J7: 是
A8: 西班牙 | B8: 陈诗晴 | C8: 新生接待课堂 | D8: 12.02 | E8: 1 | F8: 1 | G8: 1 | H8: 是 | J8: 是 | K8: 12.07
A9: 西班牙 | B9: 陈媛馨 | C9: 新生接待课堂 | D9: 12.02 | E9: 1 | F9: 1 | G9: 1 | H9: 是 | J9: 是
A10: 巴西 | B10: 叶瑜繁 | C10: 十一课堂第十二节 | D10: 12.03 | E10: 1 | J10: 是
A11: 意大利 | B11: 朱宏瑞 | C11: 十一课堂第八节 | D11: 12.03 | E11: 1 | J11: 是
A12: 西班牙 | B12: 倪晨菲 | C12: 新生接待课堂 | D12: 12.03 | E12: 1 | L12: 已试读一节课，1月搬完家入学
A13: 西班牙 | B13: 倪晨翔 | C13: 新生接待课堂 | D13: 12.03 | E13: 1 | L13: 已试读一节课，1月搬完家入学
A14: 西班牙 | B14: 倪晨睿 | C14: 新生接待课堂 | D14: 12.03 | E14: 1 | L14: 已试读一节课，1月搬完家入学
A15: 巴西 | B15: 叶妤希 | C15: 十六课堂6:20 | D15: 12.04 | E15: 1 | J15: 是
A16: 西班牙 | B16: 胡朱锦梁 | C16: 五十一课堂第五节 | D16: 12.04 | E16: 1 | F16: 1 | J16: 是
A17: 巴西 | B17: 杨心圣 | C17: 新生接待课堂 | D17: 12.04 | E17: 1 | F17: 1 | G17: 1 | J17: 是
A18: 巴西 | B18: 杨心龙 | C18: 新生接待课堂 | D18: 12.04 | E18: 1 | F18: 1 | G18: 1 | J18: 是
A19: 意大利 | B19: 朱洪涛 | C19: 五十三课堂第六节 | D19: 12.04 | E19: 1 | F19: 1 | J19: 是
A20: 意大利 | B20: 朱洪涛 | C20: 一课堂第十节 | D20: 12.05 | E20: 1 | J20: 是
A21: 西班牙 | B21: 单陈霄冉 | C21: 三十八课堂第八节 | D21: 12.05 | E21: 1 | F21: 1 | G21: 1 | J21: 是
A22: 巴西 | B22: 陈映霖 | C22: 新生接待课堂 | D22: 12.05 | E22: 1 | J22: 是
A23: 意大利 | B23: 程优璇 | C23: 新生接待课堂 | D23: 12.05 | E23: 1 | F23: 1 | G23: 1 | H23: 是 | J23: 是
A24: 意大利 | B24: 林小雨 | C24: 二十二课堂第一节 | D24: 12.05 | E24: 1 | F24: 1 | G24: 1 | H24: 是 | J24: 是
A25: 西班牙 | B25: 陈艺 | C25: 五十一课堂第五节 | D25: 12.06 | E25: 1 | F25: 1 | J25: 是
A26: 西班牙海岛 | B26: 安琳 | C26: 三十四课堂第六节 | D26: 12.06 | E26: 1 | F26: 1 | G26: 1 | H26: 是 | J26: 是
A27: 巴西 | B27: 徐喆 | C27: 黄老师的课堂18:30 | D27: 12.06 | E27: 1
A28: 西班牙 | B28: 金佳鑫 | C28: 四十二课堂第二节 | D28: 12.06 | E28: 1 | F28: 1 | G28: 1
A29: 意大利 | B29: 管似幸 | C29: 新生接待课堂 | D29: 12.09 | E29: 1（12.09） | F29: 1（12.12） | G29: 1 | J29: 是
A30: 捷克 | B30: 郭鑫睿 | C30: Chineseonline课堂13:30 滕老师 | D30: 12.08 | E30: 1 | F30: 1 | G30: 0 | L30: 试读失败，第二节课后没有联系上
A31: 捷克 | B31: 季施宇 | C31: 三十三课堂第七节 | D31: 12.1 | E31: 1 | F31: 1 | G31: 1 | J31: 是
A32: 意大利 | B32: 詹晨鑫 | C32: 四十三课堂第九节 | D32: 12.1 | E32: 1 | F32: 1 | J32: 是
A33: 西班牙 | B33: 林佳宁 | C33: 四课堂第九节 | D33: 12.1 | E33: 1 | F33: 1 | G33: 1 | H33: 是 | J33: 是
A34: 西班牙 | B34: 陈柯冉 | C34: 二课堂第七节 | D34: 12.1 | E34: 1 | F34: 1 | G34: 1 | J34: 是
A35: 葡萄牙 | B35: 程新洋 | D35: 12.11 | E35: 1 | F35: 1 | G35: 1 | J35: 是
A36: 西班牙 | B36: 梁天麟 | C36: 四课堂第九节 | D36: 12.11 | E36: 1 | F36: 1 | G36: 1 | H36: 是
A37: 西班牙 | B37: 梁天乐 | C37: 四十五课堂第二节 | D37: 12.11 | E37: 1 | F37: 1
A38: 西班牙 | B38: 张贝赟 | C38: 四课堂第九节 | D38: 12.13 | E38: 1 | F38: 1 | G38: 1 | H38: 是 | J38: 是
A39: 美国 | B39: 陈雨昕 | C39: 四十九课堂第十一节 | D39: 12.13 | E39: 1 | F39: 1 | G39: 0
A40: 美国 | B40: 陈起翔 | C40: 三十一课堂第十二节 | D40: 12.17 | E40: 1 | F40: 1 | G40: 1 | H40: 是
...

Sheet 2020.02
A1: 巴西 | B1: 中文 | C1: 李煜 | D1: 二十九课堂6:30 | E1: 2.10 | F1: 1 | G1: 1 | H1: 1 | I1: 1
A2: 西班牙海岛 | B2: 中文 | C2: 徐子芯 | D2: 三十六课堂第二节 | E2: 2.10 | F2: 1 | G2: 1 | H2: 1 | I2: 1 | N2: 老生重读
A3: 巴西 | B3: 中文 | C3: 陶康帅 | D3: 三十五课堂第五节 | E3: 2.10 | F3: 3 | G3: 1 | H3: 1 | I3: 1
A4: 巴西 | B4: 英语 | C4: 季莎莎 | D4: 六课堂第六节 | E4: 2.10 | F4: 4 | G4: 1 | H4: 1 | I4: 1
A5: 西班牙 | B5: 中文 | C5: 蒋硕 | D5: 五十六课堂第十节 | E5: 2.10 | F5: 4 | G5: 1 | H5: 1 | I5: 1
A6: 西班牙 | B6: 中文 | C6: 蒋智 | D6: 五十六课堂第十一节 | E6: 2.10 | F6: 4 | G6: 1 | H6: 1 | I6: 1
A7: 巴西 | B7: 中文 | C7: 季莎莎 | D7: 十九课堂6：30 | E7: 2.10 | F7: 2
A8: 巴西 | B8: 中文 | C8: 季靖浩 | D8: 十七课堂第十节 | E8: 2.10 | F8: 2 | H8: 1 | I8: 1
A9: 巴西 | B9: 英语 | C9: 季靖浩 | D9: 二十九课堂7:00 | E9: 2.10 | F9: 1 | G9: 1 | H9: 1 | I9: 1
A10: 意大利 | B10: 中文 | C10: 付雨宣 | D10: 四十二课堂第七节 | E10: 2.10 | F10: 3 | G10: 1 | H10: 1 | I10: 1
A11: 意大利 | B11: 中文 | C11: 林静怡 | D11: 十四课堂第九节 | E11: 2.11 | F11: 2 | H11: 1 | I11: 1 | J11: 是
A12: 西班牙新生 | B12: 中文 | C12: 叶雨婷 | D12: 三课堂第一节 | E12: 2.11 | F12: 1 | G12: 1 | H12: 1 | I12: 1
A13: 意大利 | B13: 中文 | C13: 吴芷伊 | D13: 三课堂课堂第二节 | E13: 2.11 | F13: 1 | G13: 1 | H13: 1 | I13: 1
A14: 西班牙 | B14: 英语 | C14: 黄慧敏 | D14: 四十二课堂第十节 | E14: 2.11 | F14: 3 | G14: 1 | H14: 1 | I14: 1
A15: 西班牙 | B15: 中文 | C15: 吴烁 | D15: 新生接待课堂第九节 | E15: 2.11 | F15: 3 | G15: 1 | H15: 1 | I15: 1
A16: 意大利 | B16: 中文 | C16: 夏凯文 | D16: 新生接待课堂第九节 | E16: 2.11 | G16: 1
A17: 意大利 | B17: 中文 | C17: 何黄彼得 | D17: 新生接待课堂第九节 | E17: 2.11 | G17: 1
A18: 意大利 | B18: 中文 | C18: 罗伊佳 | D18: 五十六课堂第三节 | E18: 2.11 | F18: 4 | G18: 1
A19: 波兰 | B19: 中文 | C19: 傅陈好 | D19: 六课堂第三节 | E19: 2.11 | F19: 4 | G19: 1 | H19: 1 | I19: 1
A20: 意大利 | B20: 中文 | C20: 吴俊泽 | D20: 新生接待课堂第十节 | E20: 2.11
A21: 意大利 | B21: 中文 | C21: 何家慧 | D21: 十二课堂第六节 | E21: 2.12 | F21: 1 | G21: 1 | H21: 1 | I21: 1 | N21: 老生重读
A22: 意大利 | B22: 英语 | C22: 罗伊佳 | D22: 六课堂第一节 | E22: 2.12 | F22: 4 | G22: 1 | H22: 0
A23: 希腊 | B23: 数学 | C23: 张子轩 | D23: 二十一课堂第八节 | E23: 2.12
A24: 波兰 | B24: 中文 | C24: 傅福煜 | D24: 二十八课堂第十一节 | E24: 2.13 | F24: 3 | G24: 1 | H24: 1 | I24: 1
A25: 巴西 | B25: 数学 | C25: 金喾 | D25: 一课堂第六节 | E25: 2.14 | F25: 3 | G25: 1 | H25: 0 | I25: 0 | J25: 缴费成功后，3.2号继续上课
A26: 德国 | B26: 中文 | C26: 冯子涵 | D26: 三十一课堂17:00 | E26: 2.16 | F26: 3 | G26: 1 | H26: 1 | I26: 1
A27: 德国 | B27: 中文 | C27: 冯子萱 | D27: 三十一课堂17:00 | E27: 2.16 | F27: 3 | G27: 1 | H27: 1 | I27: 1
A28: 巴西 | B28: 中文 | C28: 吴喜乐 | D28: 四十五课堂6:30 | E28: 2.13 | F28: 4 | G28: 1
A29: 巴西 | B29: 中文 | C29: 吴喜悦 | D29: 三课堂7:30 | E29: 2.13 | F29: 1 | G29: 1 | H29: 1 | I29: 1
A30: 西班牙海岛 | B30: 美术 | C30: 陈昊轩2 | D30: 美术课堂17:00张纯纯 | E30: 2.8 | G30: 1 | H30: 1
A31: 西班牙 | B31: 美术 | C31: 魏雨萱 | D31: 美术课堂17:00张纯纯 | E31: 2.9 | G31: 1
A32: 西班牙 | B32: 美术 | C32: 张家盛 | D32: 美术课堂23:00叶老师 | E32: 2.15 | G32: 1 | H32: 0
A33: 西班牙 | B33: 美术 | C33: 刘博轩 | D33: 美术课堂17:00张纯纯 | E33: 2.15
A34: 西班牙 | B34: 美术 | C34: 陈嘉乐2 | D34: 美术课堂17:00张乙格 | E34: 2.8 | G34: 1 | H34: 1
A35: 希腊 | B35: 美术 | C35: 蒋博宇 | D35: 美术课堂17:00张纯纯 | E35: 2.15
A36: 西班牙 | B36: 中文 | C36: Erika | D36: ChineseonlineT10 | E36: 2,15
A37: 德国 | B37: 中文 | C37: 孙浚轩 | D37: 三十八课堂第七节 | E37: 2.17
A38: 西班牙 | B38: 中文 | C38: 罗超颖 | D38: 五十四课堂第十节 | E38: 2.17 | F38: 3 | G38: 1 | H38: 1 | I38: 1
A39: 西班牙 | B39: 中文 | C39: 罗超贤1 | D39: 三十一课堂第五节 | E39: 2.17 | F39: 3 | G39: 1 | H39: 1 | I39: 1
A40: 西班牙 | B40: 数学 | C40: 孙颖1 | D40: 一课堂第十节 | E40: 2.17 | F40: 3 | G40: 1 | H40: 1 | I40: 1
...

Sheet 2019.10
A1: 国家 | B1: 学生 | C1: 课堂 | D1: 试读日期 | E1: 新生到课情况 | L1: 是否回访 | N1: 是否缴费 | O1: 缴费日期 | P1: 备注 | Q1: 批注：完成1，未完成0
E2: 第1天 | F2: 第2天 | G2: 第3天 | H2: 第4天 | I2: 第5天 | J2: 第6天 | K2: 第7天 | L2: 老师回访 | M2: 咨询回访
A3: 葡萄牙 | B3: 赵宇诺 | C3: 三十六课堂第六节 | D3: 10.8
A4: 巴西 | B4: 潘雨晴 | C4: 三十六课堂6:00 | D4: 10.8
A5: 西班牙 | B5: 林策 | C5: 三十课堂第二节 | D5: 10.8 | P5: 流失
A6: 西班牙 | B6: 林君 | C6: 三十课堂第二节 | D6: 10.8 | N6: 是
A7: 西班牙 | B7: 林家豪 | C7: 四十七课堂第二节 | D7: 10.8 | N7: 是
A8: 西班牙 | B8: 林家俊 | C8: 三十一课堂第七节 | D8: 10.8 | N8: 是
A9: 西班牙 | B9: 林家麒 | C9: 三十一课堂第七节 | D9: 10.8 | N9: 是
A10: 西班牙 | B10: 黄胜昔 | C10: 四十八课堂第八节 | D10: 10.8 | N10: 是
A11: 西班牙 | B11: 黄胜毅 | C11: 十三课堂第七节 | D11: 10.8 | N11: 是
A12: 西班牙 | B12: 林安娜1 | C12: 三十六课堂第十二节 | D12: 10.8 | N12: 是
A13: 西班牙 | B13: 潘凯涵 | C13: 四十六课堂第十节 | D13: 10.8 | N13: 是
A14: 西班牙 | B14: 潘凯祥 | C14: 四十八课堂第九节 | D14: 10.8 | N14: 是
A15: 西班牙 | B15: 阮卓正 | C15: 四十七课堂第八节 | D15: 10.8 | P15: 流失
A16: 西班牙 | B16: 阮卓莹 | C16: 四十七课堂第八节 | D16: 10.8 | P16: 流失
A17: 西班牙 | B17: 陈骏 | C17: 二十二课堂第十节 | D17: 10.8 | N17: 是
A18: 西班牙 | B18: 陈依诺 | C18: 十课堂第十节 | D18: 10.8 | N18: 是
A19: 巴西 | B19: 陈骏禹 | C19: 三十六课堂6:00 | D19: 10.8
A20: 西班牙 | B20: 朱文浩 | C20: 三十课堂第三节 | D20: 10.8 | N20: 是
A21: 西班牙 | B21: 刘恩泽 | C21: 三十一课堂第七节 | D21: 10.8 | N21: 是
A22: 西班牙 | B22: 刘翔泽 | C22: 三十一课堂第七节 | D22: 10.8 | P22: 流失
A23: 西班牙 | B23: 程新泽 | C23: 三十一课堂第八节 | D23: 10.8 | N23: 是
A24: 西班牙 | B24: 陈轩 | C24: 四十六课堂第十节 | D24: 10.9 | N24: 是
A25: 西班牙 | B25: 朱雨霜 | C25: 二十二课堂第六节 | D25: 10.9 | N25: 是
A26: 西班牙 | B26: 李淑晴 | C26: 二课堂第一节 | D26: 10.9 | E26: 1 | F26: 1 | G26: 1 | H26: 1 | I26: 1 | J26: 1 | K26: 1
A27: 西班牙 | B27: 朱锌锌 | C27: 二十三课堂第一节 | D27: 10.9 | E27: 1 | F27: 1 | G27: 1 | H27: 1 | I27: 1 | J27: 1 | K27: 1 | N27: 是
A28: 葡萄牙 | B28: 麻佳瑶 | C28: 四十六课堂第八节 | D28: 10.9 | N28: 是
A29: 西班牙 | B29: 诸心茹 | C29: 三十六课堂第十二节 | D29: 10.9
A30: 西班牙 | B30: 林馨1 | C30: 十七课堂第二节 | D30: 10.9 | E30: 1 | F30: 1 | G30: 1 | H30: 1 | I30: 1 | J30: 1 | K30: 1 | L30: 是 | N30: 是
A31: 捷克 | B31: 史昂 | C31: 四十七课堂第八节 | D31: 10.9 | P31: 流失
A32: 捷克 | B32: 史可 | C32: 二十二课堂第八节 | D32: 10.9 | P32: 流失
A33: 葡萄牙 | B33: 郦锦仪 | C33: 四十六课堂第十节 | D33: 10.1 | N33: 是
A34: 赛尔维亚 | B34: 曾宇菲 | C34: 十课堂第十节 | D34: 10.1
A35: 西班牙 | B35: 张琦嫣 | C35: 四十六课堂第五节 | D35: 10.1 | P35: 流失
A36: 葡萄牙 | B36: 叶诗恬 | C36: 九课堂第一节 | D36: 10.1 | N36: 是
A37: 西班牙 | B37: 孙欣欣 | C37: 三十五课堂第六节 | D37: 10.1 | E37: 1 | F37: 1 | G37: 1 | H37: 1 | I37: 1 | J37: 1 | K37: 1
A38: 法国海外 | B38: 黄涵涵 | C38: Chineseonline L第二节 | D38: 10.1 | N38: 是
A39: 法国海外 | B39: 黄胄雅 | C39: Chineseonline L第三节 | D39: 10.1 | N39: 是
A40: 西班牙 | B40: 季轩宇 | C40: 二十六课堂第十一节 | D40: 10.1 | N40: 是
...
