Workbook

Sheet 中文新生排课表
A1: 登记日期 | B1: 国家 | C1: 时差 | D1: 业务员 | E1: 组别 | F1: 学生姓名 | G1: 年龄 | H1: 家长自述程度及学习需求 | I1: 课程类型 | J1: 测试结果/预排年级 | K1: 业务员备注 | L1: 上课时间（中国时间） | M1: 排课安排（老师填写）
A2: 43963.292 | B2: 美国 | C2: 12 | D2: 丁阮琪 | E2: 2 | F2: 妮妮 | G2: 9 | H2: 不需要双语老师，想上专门针对作文的中文课 | J2: 想学专门针对作文的中文课，拼音学了，识字量还可以，家长自称已有四年级水平 | L2: 国内早上7:00 | M2: 预排兼职 已发 没有人接
A3: 5.18 | B3: 美国 | C3: 15 | D3: 程蕾 | E3: 3 | F3: Eva | G3: 9 | H3: 家长想要重点学习写作和阅读 | J3: 写作阅读课堂 | L3: 国内周二周四早上7:30后 | M3: 预排兼职 已发 没有人接
A4: 5.22 | B4: 澳大利亚 | C4: 2 | D4: 程蕾 | E4: 3 | F4: Alex | G4: 10 | H4: 认识简单的字，拼音有学过，妈妈自己教的，可以中文交流， 二次试读，希望安排专业一点的老师，一对三 | J4: 拼音an en un ang eng ung 开始 | L4: 正式上课周六周日下午12:00后 | M4: 家长在找可以一起周末搭班的学生
A5: 5.3 | B5: 澳大利亚 | C5: 2 | D5: 张文红 | E5: 3 | F5: 邱宇新 | G5: 12 | H5: 拼音有学过，复韵母不太会，可以中文交流 | J5: 拼音复韵母开始 | L5: 国内下午16:00后 | M5: 目前没有合适的班级
A6: 6.1 | B6: 美国 | C6: 15 | D6: 王可 | E6: 3 | F6: 李梓墨 | G6: 11 | I6: 周末班 | J6: 二下一单元，学生爱笑，性格很好 | M6: 一个学生目前无法开班
A7: 6.9 | B7: 意大利 | C7: 6 | D7: 俞酉兰 | E7: 0 | F7: 邓洁雅 | G7: 8 | I7: 一对四 | J7: 二下 | L7: 国内下午4:00左右 | M7: 一个学生目前无法开班
A8: 6.11 | B8: 澳大利亚 | C8: 2 | D8: 王可 | E8: 3 | F8: 黎嘉晗 | G8: 7 | J8: 建议拼音学起，孩子比较很害羞，老师要多加引导。认字课的字都认得。 | L8: 下午2:00 | M8: 预排I课堂 14:10 7.8 课程顾问说家长未回复
A9: 6.17 | B9: 美东 | C9: 12 | D9: 翁珊珊 | E9: 3 | F9: 郑芷妍 | G9: 7 | H9: 下周放假再安排班级 | I9: 一对四 | J9: 听说没问题，零基础，会写一两个字，没学过拼音 | L9: 国内时候晚上10:30 | M9: 课程顾问说暂时不排，学生还没有时间
A10: 6.2 | B10: 澳大利亚 | C10: 2 | D10: 王可 | E10: 3 | F10: 游智煊 | G10: 6 | I10: 一对四 | J10: 学生程度一般，朗读不够流畅，家长想上一对四的课程，建议从拼音bpmf开始学习拼读。 | L10: 中国下午6点钟 | M10: 一个学生目前无法开班
A11: 6.25 | B11: 美西 | C11: 15 | D11: 王晨 | F11: 吕蔓舒 | G11: 8 | H11: 有秩序的班级 | I11: 一对四 | J11: 建议二年级上册3单元 | K11: 排好就缴费，急急急急急！ | L11: 国内早上11点 | M11: 这个时间点目前没有班级可以插班
A12: 6.27 | B12: 美国 | C12: 15 | D12: 张霞 | E12: 3 | F12: 陈凯文 | G12: 9 | I12: 一对四 | J12: 二年级一单元 | L12: 国内早上6-8点半 | M12: 课程顾问说家长未回复
A13: 6.16 | B13: 意大利 | C13: 6 | D13: 俞酉兰 | E13: 0 | F13: 董振钦 | G13: 6 | I13: 一对六 | J13: 天地人 开始 | L13: 国内晚上9:00 | M13: 目前没有可以插的班级，一个不能开班
A14: 7.1 | B14: 澳大利亚 | C14: 2 | D14: 王可 | F14: 陈楚妍 | G14: 11 | I14: 一对三 | J14: 学生发音标准，朗读较流畅，识字量不错，建议从二上三四单元开始学起 | L14: 国内下午2点之后 | M14: 一对三，两个人开班
A15: 7.3 | B15: 美国中部 | C15: 15 | D15: 毛益丹 | F15: 陈凯琳 | G15: 10岁 | H15: 妈妈说是一二年级的水平 | I15: 一对四 | J15: 建议从二下开始学习，学生发音标准，朗读流畅，识字量大 | L15: 家长还没确定好时间 | M15: /
A16: 7.7 | B16: 美西 | C16: 15 | D16: 翁珊珊 | F16: 王姝曼 | G16: 8 | H16: 学过拼音很基础 | I16: 一对三 | J16: 一上七八单元，中文沟通流利，或者五六单元都行 | K16: 已缴费 急急急 | L16: 早上七点半 | M16: 一对三的课程，无法插班，一个人无法开班
A17: 7.9 | B17: 美东 | C17: 12 | D17: 平金军 | F17: 艺涵 | G17: 6 | H17: 之前也学过，识字量有200，活泼 | I17: 一对四 | J17: 拼音bpmf开始 | L17: 国内晚上10点

Sheet 试读跟进表2020.07
A1: 排课日期 | B1: 国家 | C1: 时差 | D1: 业务员 | E1: 组别 | F1: 学生姓名 | G1: 年龄 | H1: 预排年级 | I1: 课程类型 | J1: 上课时间（中国时间） | K1: 排课安排（老师填写） | M1: 试读日期 | N1: 课程 | O1: 学区 | P1: 是否到课（顾问填写） | Q1: 缴费
A2: 44012 | B2: 美西 | C2: 13 | D2: 程蕾 | F2: Tina | G2: 6 | H2: 拼音学过一点，识字量30 | I2: 一对四 | J2: bpmf，学习拼读 | K2: I课堂 8:20 7-1 | L2: Tina | M2: 44013 | N2: 中文 | O2: 白 | P2: 是 | Q2: =IFERROR(VLOOKUP(L2,Sheet1!A:C,3,FALSE),"zhaobudao") -> zhaobudao
A3: 44012 | B3: 美西 | C3: 15 | D3: 王晨 | F3: 欧阳书泰 | G3: 10 | H3: 有秩序的班级 | I3: 一对三/一对四 | J3: 建议二年级下册一单元 | K3: H课堂 9:40 7-1 | L3: 欧阳书泰 | M3: 44013 | N3: 中文 | O3: 白 | P3: 是 | Q3: =IFERROR(VLOOKUP(L3,Sheet1!A:C,3,FALSE),"zhaobudao") -> 是
A4: 44015 | B4: 美西 | C4: 15 | D4: 毛益丹 | E4: 3 | F4: 米明西 | G4: 6岁 | H4: 没有系统学习，不过在看其他学中文的app。拼音基本都会，但是还是有一些不熟练， 而且拼的比较慢，某些字也会拼错， 像“无”字， 他会直接打u，不是wu | I4: 一对四 | J4: 建议一年级上册五六单元，孩子话很多，会打断老师聊天，拼音发音二声容易读成四声 | K4: G课堂 7:00 7.1 | L4: 米明西 | M4: 44013 | N4: 中文 | O4: 白 | P4: 是 | Q4: =IFERROR(VLOOKUP(L4,Sheet1!A:C,3,FALSE),"zhaobudao") -> zhaobudao
A5: 44015 | B5: 美西 | C5: 15 | D5: 俞酉兰 | F5: 大明 | G5: 15 | H5: 是 | I5: 一对四 | J5: 二上一单元 | K5: J课堂 8:20 6-30 | L5: 大明 | M5: 44014 | N5: 中文 | O5: 白 | P5: 是 | Q5: =IFERROR(VLOOKUP(L5,Sheet1!A:C,3,FALSE),"zhaobudao") -> zhaobudao
A6: 44013 | B6: 加拿大 | C6: 15 | D6: 俞酉兰 | F6: 潘昱淳 | G6: 10岁 | I6: 一对四 | J6: 一下二单元 | K6: A课堂 7:40 7-2 | L6: 潘昱淳 | M6: 44014 | N6: 中文 | O6: 白 | P6: 是 | Q6: =IFERROR(VLOOKUP(L6,Sheet1!A:C,3,FALSE),"zhaobudao") -> zhaobudao
A7: 44015 | B7: 美东 | C7: 12 | D7: 高翱翔 | F7: 高鹏 | G7: 11 | H7: 会拼音，可以基础交流，希望可以老师带一点点英文讲解 | I7: 一对四 | J7: 一年上册七单元课文开始。{最好是项链这篇课文} | K7: Z 课堂 7:00 7-4 | L7: 高鹏 | M7: 44016 | N7: 中文 | O7: 白 | P7: 是 | Q7: =IFERROR(VLOOKUP(L7,Sheet1!A:C,3,FALSE),"zhaobudao") -> zhaobudao
A8: 44015 | B8: 美西 | C8: 15 | D8: 毛益丹3 | F8: 小恩 | G8: 7岁 | H8: 学过一册双双教材，认识一些字，不太擅长说句子，家里说中文，孩子听得懂。笔画也学了，想学拼音 | I8: 一对四，半小时；一周五天 | J8: 从拼音课开始，理解表达一般。 | K8: z课堂 10:20 7-3 | L8: 小恩 | M8: 44015 | N8: 中文 | O8: 白 | P8: 是 | Q8: =IFERROR(VLOOKUP(L8,Sheet1!A:C,3,FALSE),"zhaobudao") -> zhaobudao
A9: 44012 | B9: 美东 | C9: 12 | D9: 展旺 | F9: 曹天乐 | G9: 12 | H9: 国内早上七八点，九点之前结束就可以 | I9: 一对四 | J9: 可以放在程度比较好的班级里，建议一年级下册开始学 | K9: H课堂 8:20 7-1 | L9: 曹天乐 | M9: 44013 | N9: 中文 | O9: 白 | P9: 是 | Q9: =IFERROR(VLOOKUP(L9,Sheet1!A:C,3,FALSE),"zhaobudao") -> zhaobudao
A10: 44015 | B10: 美国纽约 | C10: -12 | D10: 王晨 | F10: 陈煾则 | G10: 9 | I10: 小班课 | J10: 中文沟通流畅，零基础，建议从拼音开始学。 | K10: J课堂 9:00 7-4 | L10: 陈煾则 | M10: 44016 | N10: 中文 | O10: 白 | P10: 是 | Q10: =IFERROR(VLOOKUP(L10,Sheet1!A:C,3,FALSE),"zhaobudao") -> zhaobudao
A11: 44015 | B11: 美国西部 | C11: 15 | D11: 王晨 | E11: 0 | F11: 赵宏康 | G11: 10 | H11: 课堂环境好 小班课 建议从拼音aieiui开始，理解表达都可以，有一点点害羞。 | I11: 一对四 | K11: Z课堂 9:00 7-4 | L11: 赵宏康 | M11: 44016 | N11: 中文 | O11: 白 | P11: 是 | Q11: =IFERROR(VLOOKUP(L11,Sheet1!A:C,3,FALSE),"zhaobudao") -> zhaobudao
A12: 44012 | B12: 美东纽约 | C12: 12 | D12: 毛益丹3 | F12: Avera Lu | G12: 7岁 | H12: 需要老师讲英文，要找一个好的老师，和梁凯琪，甄子帅排在一起 | I12: 一对一，半小时 | J12: 零基础，从拼音aieiui开始，需要双语老师 | K12: 阮洪慧；言智19；8:20开始；7.1 | L12: Avera Lu | M12: 44013 | N12: 中文 | O12: 兼 | P12: 是 | Q12: =IFERROR(VLOOKUP(L12,Sheet1!A:C,3,FALSE),"zhaobudao") -> zhaobudao
A13: 44013 | B13: 美东 | C13: 12 | D13: 高翱翔 | F13: 林卡卡 | G13: 8 | H13: 零基础开始，之前测试过，现在排正式课，在家中文交流 | I13: 一对四 | J13: 拼音开始学习 | K13: 宋老师课堂 7.2 8：10 | L13: 林卡卡 | M13: 44014 | N13: 中文 | O13: 兼 | P13: 是 | Q13: =IFERROR(VLOOKUP(L13,Sheet1!A:C,3,FALSE),"zhaobudao") -> 是
A14: 44013 | B14: 美东 | C14: 12 | D14: 杨斌 | F14: 琪伟 | G14: 8 | I14: 一对四 | J14: 建议从拼音课开始学起，可以交流，识字量少，很活泼 | K14: 宋老师课堂 7.2 8：10 | L14: 琪伟 | M14: 44014 | N14: 中文 | O14: 兼 | P14: 是 | Q14: =IFERROR(VLOOKUP(L14,Sheet1!A:C,3,FALSE),"zhaobudao") -> zhaobudao
A15: 44013 | B15: 美国 | D15: 展旺 | F15: 陈宇翔 | I15: 一对四 | J15: aoe开始学 | K15: 宋老师课堂 7.2 8：10 | L15: 陈宇翔 | M15: 44014 | N15: 中文 | O15: 兼 | P15: 是 | Q15: =IFERROR(VLOOKUP(L15,Sheet1!A:C,3,FALSE),"zhaobudao") -> zhaobudao
A16: 44013 | B16: 美东 | C16: 12 | D16: 毛益丹 | F16: 蓝天 | G16: 6岁 | H16: 有学了一点中文，刚学拼音，会基本的中文交流，没上幼儿园前一直说中文，上了幼儿园后和同学们习惯说英文 | I16: 一对四 | J16: 孩子表现非常好，记忆力也很好，之前也学过中文，建议从拼音一年级上册第二单元《a o e》开始学，妈妈意向高，孩子也愿意学。 | K16: 言智38 9：00 7.2 言智 36 9:00 7.6 | L16: 蓝天 | M16: 44014 | N16: 中文 | O16: 兼 | P16: 是 | Q16: =IFERROR(VLOOKUP(L16,Sheet1!A:C,3,FALSE),"zhaobudao") -> 是
A17: 44013 | B17: 美东 | C17: 12 | D17: 王可 | F17: 张明娜 | G17: 7 | H17: 零基础开始 | I17: 一对四 | K17: 言智38 9：00 7.2 | L17: 张明娜 | M17: 44014 | N17: 中文 | O17: 兼 | P17: 是 | Q17: =IFERROR(VLOOKUP(L17,Sheet1!A:C,3,FALSE),"zhaobudao") -> zhaobudao
A18: 44013 | B18: 美东 | C18: 12 | D18: 展旺 | F18: 苗牛牛 | G18: 10 | H18: 和蓝天， | I18: 一对四 | J18: 建议从拼音课开始，中文理解和表达很好，认字量一般，学生有时爱跑题需要老师去抓住学生的注意力。 | K18: 言智38 9：00 7.2 | L18: 苗牛牛 | M18: 44014 | N18: 中文 | O18: 兼 | P18: 是 | Q18: =IFERROR(VLOOKUP(L18,Sheet1!A:C,3,FALSE),"zhaobudao") -> 是
A19: 44013 | B19: 美东 | C19: 12 | D19: 翁珊珊 | F19: 陈冠燊 | G19: 10 | H19: 一上五单元《画》开始上 需要排在学生程度好的班级 | I19: 一对四 | J19: 一上五单元《画》 | K19: 三十九课堂 21:40 7-1 | L19: 陈冠燊 | M19: 44014 | N19: 中文 | O19: 夜1 | P19: 是 | Q19: =IFERROR(VLOOKUP(L19,Sheet1!A:C,3,FALSE),"zhaobudao") -> zhaobudao
A20: 44014 | B20: 美国东部 | C20: 12 | D20: 展望 | F20: Larry | G20: 7 | H20: 学过一年中文，中间断了半年，拼音没学过，听得懂中文，但是不太会说 | I20: 一对一 | J20: bpmf开始 | K20: 宋老师课堂 8:30 7-3 | L20: Larry | M20: 44015 | N20: 中文 | O20: 兼 | P20: 是 | Q20: =IFERROR(VLOOKUP(L20,Sheet1!A:C,3,FALSE),"zhaobudao") -> zhaobudao
A21: 44014 | B21: 美国西部 | C21: 15 | D21: 任宏印 | F21: 谢恩耀 | G21: 7 | H21: 学生比较害羞，简单的生字认识，建议从拼音开始上课。 | I21: 一对四 | J21: 从拼音开始上课。 美国时间晚上7：30中国时间7月1号开始上课早上10:30 | K21: Z课堂 10:20 7-2 | L21: 谢恩耀 | M21: 44014 | N21: 中文 | O21: 白 | P21: 是 | Q21: =IFERROR(VLOOKUP(L21,Sheet1!A:C,3,FALSE),"zhaobudao") -> zhaobudao
A22: 44014 | B22: 美东 | C22: 12 | D22: 刘巧芹 | F22: 李乐芯 | G22: 5.5 | H22: 拼音aoe开始学 | I22: 一对四，国内周二到周六 | K22: J课堂 9:00 7-3 | L22: 李乐芯 | M22: 44015 | N22: 中文 | O22: 白 | P22: 是 | Q22: =IFERROR(VLOOKUP(L22,Sheet1!A:C,3,FALSE),"zhaobudao") -> 是
A23: 44014 | B23: 美东 | C23: 12 | D23: 刘巧芹 | F23: 陈睿萱 | G23: 6 | H23: 拼音aoe开始学 | I23: 一对四，国内周二到周六 | K23: J课堂 9:00 7-3 | L23: 陈睿萱 | M23: 44015 | N23: 中文 | O23: 白 | P23: 是 | Q23: =IFERROR(VLOOKUP(L23,Sheet1!A:C,3,FALSE),"zhaobudao") -> 是
A24: 44014 | B24: 美东 | C24: 12 | D24: 刘巧芹 | F24: 朱紫晴 | G24: 快七岁 | H24: 拼音aoe开始学 | I24: 一对四，国内周二到周六 | K24: J课堂 9:00 7-3 | L24: 朱紫晴 | M24: 44015 | N24: 中文 | O24: 白 | P24: 是 | Q24: =IFERROR(VLOOKUP(L24,Sheet1!A:C,3,FALSE),"zhaobudao") -> 是
A25: 44014 | B25: 美国 | C25: 12 | D25: 张霞 | F25: 童童 | G25: 10 | H25: 零基础 | I25: 一对四 | J25: 直接从拼音开始 | K25: 言智38 7.2 22：00—22：30 | L25: 童童 | M25: 44014 | N25: 中文 | O25: 兼 | P25: 是 | Q25: =IFERROR(VLOOKUP(L25,Sheet1!A:C,3,FALSE),"zhaobudao") -> 是
A26: 44014 | B26: 美国 | C26: 12 | D26: 张霞 | F26: 朴智美 | G26: 11 | H26: 零基础 | I26: 一对四 | J26: 直接从拼音开始 | K26: 言智38 7.2 22：00—22：30 | L26: 朴智美 | M26: 44014 | N26: 中文 | O26: 兼 | P26: 是 | Q26: =IFERROR(VLOOKUP(L26,Sheet1!A:C,3,FALSE),"zhaobudao") -> 是
A27: 44014 | B27: 美国 | C27: 12 | D27: 张霞 | F27: 郑琳 | G27: 7 | H27: 希望老师带动力强，上课内容丰富一点 | I27: 一对四 | J27: 建议从拼音开始，能听懂一点点 | K27: 言智39 21:30~22:00 7.2 | L27: 郑琳 | M27: 44014 | N27: 中文 | O27: 兼 | P27: 是 | Q27: =IFERROR(VLOOKUP(L27,Sheet1!A:C,3,FALSE),"zhaobudao") -> zhaobudao
A28: 44015 | B28: 美西 | C28: 15 | D28: 毛益丹3 | E28: 3 | F28: 曾博 | G28: 7岁 | H28: 一年级，和哥哥曾晰一起上过一年的周末中文学校，学的是二年级中文，没有基础，没学过拼音，不会笔画笔顺，想利用暑假从头开始学。会基本中文交流 | I28: 一对四，半小时；一周五天 | J28: 建议aoe开始学习，拼音认识几个，喜欢说话，配合老师，发音非常不标准 | K28: 言智41 7:00-7:30 7.4 | L28: 曾博 | M28: 44016 | N28: 中文 | O28: 兼 | P28: 否 | Q28: =IFERROR(VLOOKUP(L28,Sheet1!A:C,3,FALSE),"zhaobudao") -> zhaobudao
A29: 44015 | B29: 美西 | C29: 15 | D29: 毛益丹3 | F29: 王子嘉 | G29: 6.5岁 | H29: 学过拼音，但是没学好，不介意孩子再学拼音，可以基本的中文交流 | I29: 一对四，半小时；一周五天 | J29: 学生其实拼音单独的可以完全读下来，但是拼读不太会。认字程度在一上七单元。妈妈想要拼音从头学起。 | K29: 言智41 7:00-7:30 7.4 | L29: 王子嘉 | M29: 44016 | N29: 中文 | O29: 兼 | P29: 否 | Q29: =IFERROR(VLOOKUP(L29,Sheet1!A:C,3,FALSE),"zhaobudao") -> 是
A30: 44015 | B30: 美国 | C30: 15 | D30: 王可 | E30: 3 | F30: 冯浩齐 | G30: 7 | J30: 一上第八单元开始学起，读没问题，句子不理解，不会组词和造句，孩子比较顽皮坐不住。双语 | K30: 范老师课堂 6:20 7.3 | L30: 冯浩齐 | M30: 44015 | N30: 中文 | O30: 兼 | P30: 是 | Q30: =IFERROR(VLOOKUP(L30,Sheet1!A:C,3,FALSE),"zhaobudao") -> 是
A31: 44015 | B31: 美国 | D31: 展旺 | F31: irina chen | I31: 一对四 | J31: 建议从一上第四单元开始，可以理解中文但是不怎么会说，家长想要学生多说话。拼音中的ang ong eng发音不太好，有点害羞。 | K31: 范老师课堂 6:20 7.3 | L31: irina chen | M31: 44015 | N31: 中文 | O31: 兼 | P31: 是 | Q31: =IFERROR(VLOOKUP(L31,Sheet1!A:C,3,FALSE),"zhaobudao") -> zhaobudao
A32: 44015 | B32: 加拿大 | C32: 15 | D32: 李波 | E32: 1 | F32: 戴妮 | G32: 10 | H32: 数学 初中 | K32: 数学课堂 7月4日 8:00-8:30 | L32: 戴妮 | M32: 44016 | N32: 数学 | O32: 兼 | Q32: =IFERROR(VLOOKUP(L32,Sheet1!A:C,3,FALSE),"zhaobudao") -> zhaobudao
A33: 44015 | B33: 美国 | C33: 12 | D33: 刘箫 | E33: 1 | F33: 洪安恬 | G33: 11 | H33: 数学 | I33: 1对1 | J33: 早上8点到9点 | K33: 黄老师上课课堂21:00 7-4 | L33: 洪安恬 | M33: 44016 | N33: 数学 | O33: 兼 | Q33: =IFERROR(VLOOKUP(L33,Sheet1!A:C,3,FALSE),"zhaobudao") -> zhaobudao
A34: 44015 | B34: 美中 | C34: 13 | D34: 杨斌 | F34: 陈嘉译 | G34: 9岁 | H34: 之前没学过听得懂简单的中文 | I34: 一对四 | J34: 建议从拼音开始学起，可以听懂但是中文表达一般。 | K34: 言智38，李斐斐老师； 8:20开始；7.3缴费 | L34: 陈嘉译 | M34: 44015 | N34: 中文 | O34: 兼 | P34: 是 | Q34: =IFERROR(VLOOKUP(L34,Sheet1!A:C,3,FALSE),"zhaobudao") -> zhaobudao
A35: 44015 | B35: 宋崇铭 | C35: 12 | D35: 杨斌 | F35: 宋崇铭 | G35: 8岁 | H35: 孩子注意力容易不集中希望老师引导 | J35: 建议从拼音开始学起，可以听懂但是中文表达一般。 | K35: 言智38，李斐斐老师； 8:20开始；7.3缴费 | L35: 宋崇铭 | M35: 44015 | N35: 中文 | O35: 兼 | P35: 是 | Q35: =IFERROR(VLOOKUP(L35,Sheet1!A:C,3,FALSE),"zhaobudao") -> 是
A36: 44015 | B36: 美国东部 | C36: 12 | D36: 毛益丹 | F36: 梁斯颖 | G36: 8岁半 | H36: 学了一年的中文，正在学拼音了，会一点点拼音，会基本的中文交流 | J36: 建议aoe开始，零基础，跟老师读发音标准，弟弟在旁边喜欢学 | K36: 言智38，李斐斐老师； 8:20开始；7.3缴费 | L36: 梁斯颖 | M36: 44015 | N36: 中文 | O36: 兼 | P36: 是 | Q36: =IFERROR(VLOOKUP(L36,Sheet1!A:C,3,FALSE),"zhaobudao") -> zhaobudao
A37: 44015 | B37: 美东 | C37: 12 | D37: 翁珊珊 | F37: 黄梓瑄 | G37: 10 | I37: 一对二 | J37: 两姐妹程度一般，会拼音，中文能听懂一些，词汇量识字量很少 ，建议从一上四单元开始上课 | K37: 程老师课堂8:30 7.3 | L37: 黄梓瑄 | M37: 44015 | N37: 中文 | O37: 兼 | P37: 是 | Q37: =IFERROR(VLOOKUP(L37,Sheet1!A:C,3,FALSE),"zhaobudao") -> 是
A38: 44015 | B38: 美东 | C38: 12 | D38: 翁珊珊 | F38: 黄奕瑄 | G38: 12 | I38: 一对二 | J38: 两姐妹程度一般，会拼音，中文能听懂一些，词汇量识字量很少 ，建议从一上四单元开始上课 | K38: 程老师课堂8:30 7.3 | L38: 黄奕瑄 | M38: 44015 | N38: 中文 | O38: 兼 | P38: 是 | Q38: =IFERROR(VLOOKUP(L38,Sheet1!A:C,3,FALSE),"zhaobudao") -> 是
A39: 44015 | B39: 美西 | C39: 15 | D39: 程蕾 | F39: Selena | G39: 8 | H39: 小孩子爱问问题 | I39: 一对四 | J39: 二年级上册6单元开始 | K39: G课堂 10:20 7.4 | L39: Selena | M39: 44016 | N39: 中文 | O39: 白 | P39: 是 | Q39: =IFERROR(VLOOKUP(L39,Sheet1!A:C,3,FALSE),"zhaobudao") -> zhaobudao
A40: 44015 | B40: 美国 | C40: 12 | D40: 李华 | E40: 1 | F40: 陈懿 | G40: 6 | H40: 数学，一上 | I40: 1对1 | J40: 早上10点 | K40: 数学十一C 22：00 7月3日 | L40: 陈懿 | M40: 44015 | N40: 数学 | O40: 兼 | Q40: =IFERROR(VLOOKUP(L40,Sheet1!A:C,3,FALSE),"zhaobudao") -> zhaobudao
...

Sheet 启蒙试读表2020.7
A1: 序号 | B1: 测试时间 | C1: 国家 | D1: 城市 | E1: 时差 | F1: 家长微信名 | G1: 家长微信 | H1: 电话号码 | I1: 学生姓名 | K1: jiaofei | L1: 年龄 | M1: 性别 | N1: 有没有学过拼音 | O1: 是否需要双语老师 | P1: 家长自述程度及学习需求 | Q1: 学习课程 | R1: 测试结果 | S1: 排课安排 | T1: 来源 | U1: 组别 | V1: 业务员 | W1: 试读日期 | X1: 试课安排 | Y1: 排课校区 | Z1: 是否在读 | AA1: 是否缴费 | AB1: 失败原因 | AC1: 课程单价 | AD1: 折扣 | AE1: 实收 | AF1: 首次收费时间
B2: 44013 | C2: 澳大利亚 | E2: 2 | F2: joanneys | G2: joanneys | I2: 黄若毅 | J2: 黄若毅 | K2: =IFERROR(VLOOKUP(J2,Sheet1!A:C,3,FALSE),"zhaobudao") -> 是 | L2: 5 | M2: 男 | N2: 否 | O2: 是 | P2: 可以听得懂 但是不愿意开口说中文 | Q2: 启蒙中文 | S2: 张倩 18:30 7.1 | T2: 家长介绍 | U2: 3 | V2: 翁珊珊 美丽妈妈介绍 | Z2: 是 | AA2: 是 | AC2: 116/课 | AD2: 一对一46+2 | AE2: 755.31 | AF2: 7.2日缴费
B3: 44014 | C3: 美国 | D3: 东部 | E3: 12 | H3: 001-7188082035 | I3: 梁彧博 | J3: 梁彧博 | K3: =IFERROR(VLOOKUP(J3,Sheet1!A:C,3,FALSE),"zhaobudao") -> zhaobudao | L3: 8 | M3: 男 | N3: 否 | O3: 否 | P3: 希望哥哥和妹妹一起学，因为都学过五四快读，识字量差不多 | Q3: 启蒙中文 | S3: 林玲玲 6:00 7.2 | T3: 介绍 | U3: 3 | V3: 张文红 | Z3: 是 | AA3: 是 | AC3: 116/课 | AD3: 一对一65+3 | AE3: 7540 | AF3: 7.6日缴费
B4: 44014 | C4: 美国 | D4: 东部 | E4: 12 | H4: 001-7188082035 | I4: 梁书婧 | J4: 梁书婧 | K4: =IFERROR(VLOOKUP(J4,Sheet1!A:C,3,FALSE),"zhaobudao") -> zhaobudao | L4: 5 | M4: 女 | N4: 否 | O4: 否 | P4: 希望哥哥和妹妹一起学，因为都学过五四快读，识字量差不多 | Q4: 启蒙中文 | S4: 林玲玲 7:00 7.2 | T4: 介绍 | U4: 3 | V4: 张文红
B5: 44014 | C5: 美国 | D5: 东部 | E5: 12 | F5: felicia | G5: chippiopio | H5: +1 9176671031 | I5: 齊藤鎮彥 | J5: 齊藤鎮彥 | K5: =IFERROR(VLOOKUP(J5,Sheet1!A:C,3,FALSE),"zhaobudao") -> zhaobudao | L5: 5.5 | O5: 是 | Q5: 启蒙数学 | S5: 卢爽 21:00 7.2 | T5: 微信 | U5: 3 | V5: 王可
B6: 44015 | C6: 美国 | D6: 中部 | E6: 13 | G6: Lily | H6: xc420695634 | I6: lexi | J6: lexi | K6: =IFERROR(VLOOKUP(J6,Sheet1!A:C,3,FALSE),"zhaobudao") -> zhaobudao | L6: 4.5 | M6: 男 | N6: 否 | O6: 否 | P6: 会中文交流，认识一两百字 | Q6: 启蒙中文 | S6: 童美英 8:00 7.3 | T6: 微信 | U6: 3 | V6: 王可
B7: 44015 | C7: 澳洲 | E7: 2 | H7: +61 433603061 | I7: 车伊然 | J7: 车伊然 | K7: =IFERROR(VLOOKUP(J7,Sheet1!A:C,3,FALSE),"zhaobudao") -> zhaobudao | L7: 3.5 | N7: 否 | O7: 否 | P7: 可以交流 | Q7: 启蒙中文 | S7: 吴岚 15:00 7.3 | T7: 微信 | U7: 3 | V7: 王可
B8: 44015 | C8: 加拿大 | H8: 无账号 | I8: 陈熙 | J8: 陈熙 | K8: =IFERROR(VLOOKUP(J8,Sheet1!A:C,3,FALSE),"zhaobudao") -> zhaobudao | L8: 3 | M8: 男 | N8: 否 | O8: 否 | P8: 零基础，交流可以，孩子很不愿意主动讲话 | Q8: 启蒙中文 | S8: 许杰8:30 7.3 | T8: 微信 | U8: 1 | V8: 何家昌1
B9: 44015 | C9: 美国 | H9: 16504070006 | I9: 吴舒瑶 | J9: 吴舒瑶 | K9: =IFERROR(VLOOKUP(J9,Sheet1!A:C,3,FALSE),"zhaobudao") -> 是 | M9: 女 | N9: 否 | O9: 否 | P9: 可以交流 | Q9: 启蒙中文 | S9: 蒋铄 7:20 7.3 | T9: 微信 | U9: 3 | V9: 王可
B10: 44015 | C10: 加拿大 | H10: 17782889773 | I10: Nina | J10: Nina | K10: =IFERROR(VLOOKUP(J10,Sheet1!A:C,3,FALSE),"zhaobudao") -> zhaobudao | L10: 4岁 | M10: 女 | N10: 否 | O10: 否 | P10: 会中文交流 零基础 | Q10: 启蒙中文 | S10: 张倩 8:00 7.3 | T10: 家长介绍 | U10: 白 | V10: 俞酉兰
B11: 44015 | C11: 马来西亚 | H11: 60122236813 | I11: 颜豪庆 | J11: 颜豪庆 | K11: =IFERROR(VLOOKUP(J11,Sheet1!A:C,3,FALSE),"zhaobudao") -> zhaobudao | L11: 3.5 | M11: 男 | N11: 否 | O11: 否 | P11: 会交流，零基础 | Q11: 启蒙中文 | S11: 林玲玲 19:00 7.3 | T11: 家长介绍 | U11: 白
B12: 44015 | C12: 美西 | E12: 15 | F12: wechunku | G12: klaviergirl91 | I12: Dana Lin | J12: Dana Lin | K12: =IFERROR(VLOOKUP(J12,Sheet1!A:C,3,FALSE),"zhaobudao") -> zhaobudao | L12: 6 | M12: 女 | P12: 三位数加法，基本九九乘法 | Q12: 启蒙数学 | S12: 解一聪 8:40 7.3 | T12: 微信 | U12: 3 | V12: 程蕾
B13: 44015 | C13: 美国 | F13: Serena | G13: serena138 | H13: 1 5086157686 | I13: 豆豆 | J13: 豆豆 | K13: =IFERROR(VLOOKUP(J13,Sheet1!A:C,3,FALSE),"zhaobudao") -> zhaobudao | L13: 5岁 | M13: 女 | N13: 没有 | O13: 否 | P13: 中文一般，认识20个汉字 | Q13: 启蒙中文 | S13: 许杰 7:30 7.3 | T13: 微信 | U13: 3 | V13: 毛益丹
B14: 44015 | C14: 美国 | F14: Serena | G14: serena138 | H14: 1 3303895044 | I14: 点点 | J14: 点点 | K14: =IFERROR(VLOOKUP(J14,Sheet1!A:C,3,FALSE),"zhaobudao") -> zhaobudao | L14: 快5岁 | M14: 女 | N14: 没有 | O14: 否 | P14: 有自己教她认字，进度是四五快读完成了第一册和第二册，平常在家里都说中文，希望后续学拼音 | Q14: 启蒙中文 | S14: 许杰 7:30 7.3 | T14: 微信 | U14: 3 | V14: 毛益丹
B15: 44016 | C15: 澳大利亚 | D15: 悉尼 | E15: 2 | H15: 416640906 | I15: camille | J15: camille | K15: =IFERROR(VLOOKUP(J15,Sheet1!A:C,3,FALSE),"zhaobudao") -> zhaobudao | L15: 2.5岁 3岁 | M15: 女 | N15: 没有 | O15: 需要 | P15: 小的两岁出头，大宝因为语言发育迟缓，跟小的差不多，中文会基本的沟通，也不是很懂。家长说试试看孩子能不能坐的住 | Q15: 启蒙中文 | S15: 蒋铄17:30 7.4 | T15: 微信 | U15: 0 | V15: 张仁波
B16: 44016 | C16: 澳大利亚 | D16: 悉尼 | E16: 2 | H16: 416640906 | I16: damier | J16: damier | K16: =IFERROR(VLOOKUP(J16,Sheet1!A:C,3,FALSE),"zhaobudao") -> zhaobudao | L16: 2.5岁 3岁 | M16: 女 | N16: 没有 | O16: 需要 | P16: 小的两岁出头，大宝因为语言发育迟缓，跟小的差不多，中文会基本的沟通，也不是很懂。家长说试试看孩子能不能坐的住 | Q16: 启蒙中文 | S16: 蒋铄17:30 7.4 | T16: 微信 | U16: 0 | V16: 张仁波
B17: 44016 | C17: 加拿大 | D17: 多伦多 | E17: 12 | H17: 5147466789 | I17: 王泰博 | J17: 王泰博 | K17: =IFERROR(VLOOKUP(J17,Sheet1!A:C,3,FALSE),"zhaobudao") -> zhaobudao | L17: 6岁 | M17: 男 | N17: 没有 | O17: 否 | P17: 认识几个字 喜欢攀岩 听说OK 家里尽力提供中文环境 | Q17: 启蒙中文 | S17: 许杰21:00 7.4 | T17: 微信 | U17: 2 | V17: 赵国花
B18: 44016 | C18: 加拿大 | D18: 温哥华 | E18: 15 | H18: 7789286579 | I18: 晨晨 | J18: 晨晨 | K18: =IFERROR(VLOOKUP(J18,Sheet1!A:C,3,FALSE),"zhaobudao") -> zhaobudao | L18: 5.5岁 | M18: 男 | N18: 没有 | O18: 否 数学 | P18: 学习数学哦，孩子零基础，没有学习过数学哦。喜欢卡通 | Q18: 启蒙数学 | S18: 解一聪11:00 7.4 | T18: 微信 | U18: 2 | V18: 高翱翔
B19: 44016 | C19: 加拿大 | D19: 温哥华 | E19: 15 | H19: 7789286579 | I19: 晨晨 | J19: 晨晨 | K19: =IFERROR(VLOOKUP(J19,Sheet1!A:C,3,FALSE),"zhaobudao") -> zhaobudao | L19: 5.5岁 | M19: 男 | N19: 没有 | O19: 否 | P19: 学习中文，孩子平时在家中文交流没有问题，没有学习过拼音什么的喜欢卡通 | Q19: 启蒙中文 | S19: 蒋铄9:00 7.4 | T19: 微信 | U19: 2 | V19: 高翱翔
B20: 44016 | C20: 美国 | D20: 西海岸 | E20: 15 | H20: 323 283 7396 | I20: 武雨桐 | J20: 武雨桐 | K20: =IFERROR(VLOOKUP(J20,Sheet1!A:C,3,FALSE),"zhaobudao") -> zhaobudao | L20: 四岁 | M20: 女 | N20: 否 | O20: 是 | P20: 零基础，一般的对话可以，害羞喜欢画画粉色 大裙子 | Q20: 启蒙中文 | S20: 张倩 8:30 7.4 | T20: 微信 | U20: 3 | V20: 刘巧芹 | Z20: 是 | AA20: 是 | AC20: 96/课 | AD20: 一对一收一对二44 | AE20: 4224 | AF20: 7.6日缴费
B21: 44016 | C21: 美国 | D21: 西部 | E21: 15 | H21: 1 6692566661 | I21: 小宝 | J21: 小宝 | K21: =IFERROR(VLOOKUP(J21,Sheet1!A:C,3,FALSE),"zhaobudao") -> zhaobudao | L21: 快5岁 | N21: 没有 | O21: 否 | P21: 不会写字，会认100个字左右，交流的话中文很好，会很多成语，暂时不学拼音 | Q21: 启蒙中文 | S21: 吴岚7:00 7.4 | T21: 微信 | U21: 3 | V21: 毛益丹
B22: 44016 | C22: 加拿大 | D22: 温哥华 | E22: 15 | F22: Liberty | G22: Liberty_feng | H22: +1 6043387728 | I22: 徐志镐 | J22: 徐志镐 | K22: =IFERROR(VLOOKUP(J22,Sheet1!A:C,3,FALSE),"zhaobudao") -> zhaobudao | L22: 月底满3岁 | M22: 男 | N22: 否 | O22: 是 | P22: 会说粤语，和一点中文 不会说英文 | Q22: 启蒙中文 | S22: 张媛媛9:00 7.4 | T22: 扫一扫 | U22: 白 | V22: 俞酉兰
A23: 二次试读 | B23: 44017 | C23: 美国 | D23: 西海岸 | E23: 15 | H23: 1 9192822200 | I23: 米明西 | J23: 米明西 | K23: =IFERROR(VLOOKUP(J23,Sheet1!A:C,3,FALSE),"zhaobudao") -> zhaobudao | L23: 6岁 | M23: 男 | N23: 学过 | O23: 否 | P23: 没有系统学习，不过在看其他学中文的app。拼音基本都会，但是还是有一些不熟练， 而且拼的比较慢，某些字也会拼错， 像“无”字， 他会直接打u，不是wu；建议一年级上册五六单元，孩子话很多，会打断老师聊天，拼音发音二声容易读成四声。因为孩子觉得小学语文枯燥转过来的，孩子喜欢有趣的课程，老师尽量提升宝贝的兴趣 | Q23: 启蒙中文 | S23: 张倩7:00 7.5 | T23: 微信 | U23: 3 | V23: 毛益丹
A24: 二次试读 | B24: 44017 | C24: 美国 | D24: 东部 | E24: 12 | H24: 9176052667 | I24: Darren Ma | J24: Darren Ma | K24: =IFERROR(VLOOKUP(J24,Sheet1!A:C,3,FALSE),"zhaobudao") -> zhaobudao | L24: 6 | M24: 男 | N24: 否 | O24: 是 | P24: 孩子零基础，会说一点中文 | Q24: 启蒙中文 | S24: 卢爽7:00 7.5 | T24: 微信 | U24: 3 | V24: 翁珊珊
B25: 44017 | C25: 加拿大 | H25: 17788296089 | I25: Nicole | J25: Nicole | K25: =IFERROR(VLOOKUP(J25,Sheet1!A:C,3,FALSE),"zhaobudao") -> zhaobudao | L25: 6.5 | M25: 女 | N25: 否 | O25: 是 | P25: 会说中文 不会写 有的时候听不懂 | Q25: 启蒙中文 | S25: 卢爽7:30 7.5 | T25: 微信 | U25: 白 | V25: 俞酉兰
B26: 44018 | C26: 美国 | D26: 中部 | E26: 13 | F26: rina | G26: rina4557715 | H26: 9173850398 | I26: Elina | J26: Elina | K26: =IFERROR(VLOOKUP(J26,Sheet1!A:C,3,FALSE),"zhaobudao") -> zhaobudao | L26: 6 | M26: 女 | N26: 没有 | O26: 是 | P26: 有时会用中文交流 | Q26: 启蒙中文 | S26: 卢爽22:30 7.6 | T26: 微信 | U26: 3 | V26: 翁珊珊
B27: 44018 | C27: 美国 | D27: 西部 | E27: 15 | H27: 13807489455 | I27: 秦可伊 | J27: 秦可伊 | K27: =IFERROR(VLOOKUP(J27,Sheet1!A:C,3,FALSE),"zhaobudao") -> zhaobudao | L27: 4岁半 | M27: 女 | N27: 否 | O27: 否 | P27: 妈妈在家教了一些字 | Q27: 启蒙中文 | S27: 卢爽8:00 7.6 | T27: 微信 | U27: 3 | V27: 张霞
B28: 44019 | C28: 美国 | D28: 加利福尼亚 | E28: 15 | H28: 17788583038 | I28: Felicia | J28: Felicia | K28: =IFERROR(VLOOKUP(J28,Sheet1!A:C,3,FALSE),"zhaobudao") -> zhaobudao | L28: 5.5 | M28: 女 | N28: 否 | O28: 是 | P28: 没学过 一家的 一块上 | Q28: 启蒙中文 | S28: 卢爽 7:00 7.7 | T28: 家长介绍 | U28: 白 | V28: 俞酉兰
B29: 44019 | C29: 美国 | D29: 加利福尼亚 | E29: 15 | H29: 17788583038 | I29: Natasha | J29: Natasha | K29: =IFERROR(VLOOKUP(J29,Sheet1!A:C,3,FALSE),"zhaobudao") -> zhaobudao | L29: 4 | M29: 女 | N29: 否 | O29: 是 | P29: 没学过 一家的 一块上 | Q29: 启蒙中文 | S29: 卢爽 7:00 7.7 | T29: 家长介绍 | U29: 白 | V29: 俞酉兰
B30: 44019 | C30: 加拿大 | D30: 温哥华 | E30: 15 | H30: 7786808698 | I30: 陆子涵 | J30: 陆子涵 | K30: =IFERROR(VLOOKUP(J30,Sheet1!A:C,3,FALSE),"zhaobudao") -> 是 | L30: 6 | M30: 女 | N30: 学过 | O30: 否 | P30: 从启蒙开始，20以内的加减法，扳着手指头算 | Q30: 启蒙数学 | S30: 卢爽8:15 7.7 | T30: 家长介绍 | V30: 任宏印
B31: 44019 | C31: 美国 | D31: 西部 | E31: 15 | H31: 13811239849 | I31: 卡卡 | J31: 卡卡 | K31: =IFERROR(VLOOKUP(J31,Sheet1!A:C,3,FALSE),"zhaobudao") -> zhaobudao | L31: 5 | M31: 男 | N31: 否 | O31: 否 | P31: 有在网络中文课，还没学拼音，有意向学拼音课 | Q31: 启蒙中文 | S31: 卢爽 7:00 7.7 | T31: 微信 | U31: 3 | V31: 毛益丹

Sheet Sheet1
A1: 原始 | B1: 整理后 | C1: 列1
A2: 叶文浩1 | B2: 叶文浩1 | C2: 是
A3: 叶鋆睿 | B3: 叶鋆睿 | C3: 是
A4: 何子恒（数） | B4: 何子恒 | C4: 是
A5: 吉娜 | B5: 吉娜 | C5: 是
A6: 宋崇铭 | B6: 宋崇铭 | C6: 是
A7: 吴楚惟 | B7: 吴楚惟 | C7: 是
A8: 吕泽歆 | B8: 吕泽歆 | C8: 是
A9: 小恩 | B9: 小恩 | C9: 是
A10: 吴炳铨（数） | B10: 吴炳铨 | C10: 是
A11: 林泽锴1 | B11: 林泽锴1 | C11: 是
A12: 胡昊阳 | B12: 胡昊阳 | C12: 是
... A244: 郑安俊郑俊杰郑迪纪柯艳 | B244: 郑安俊 | C244: 是
B245: 柯艳 | C245: 是
B246: 郑迪纪 | C246: 是
B247: 郑俊杰 | C247: 是
A248: 金喜1（数） | B248: 金喜1 | C248: 是
A249: 金娜娜1 | B249: 金娜娜1 | C249: 是
A250: 陈帅 | B250: 陈帅 | C250: 是
A251: 陈诺1 | B251: 陈诺1 | C251: 是
A252: 袁乐琛（数） | B252: 袁乐琛 | C252: 是
A253: 王新迪 | B253: 王新迪 | C253: 是
A254: 倪瑞璇 | B254: 倪瑞璇 | C254: 是
A255: 周素丽 | B255: 周素丽 | C255: 是
A256: 周熠 | B256: 周熠 | C256: 是
A257: 李浩然1 | B257: 李浩然1 | C257: 是
A258: 陈奕嘉 | B258: 陈奕嘉 | C258: 是
A259: 龚炫瑞 | B259: 龚炫瑞 | C259: 是
... A289: 廖铭晔 | B289: 廖铭晔 | C289: 是

Sheet 试读跟进表2020.06
A1: 日期 | B1: 国家 | C1: 时差 | D1: 业务员 | E1: 组别 | F1: 学生姓名 | G1: 年龄 | H1: 预排年级 | I1: 家长叙述/特殊要求 | J1: 上课时间（中国时间） | K1: 排课安排（老师填写） | L1: 试读日期 | M1: 课程 | N1: 学区 | O1: 是否到课（顾问填写）
A2: 6.1 | B2: 美国 | C2: 12 | D2: 王晨 | E2: 0 | F2: 轩辕瀚 | G2: 9 | H2: 2年级或3年级，识字量500 | I2: 想直接试黄莺老师的课 | J2: 国内134晚上22:05 | K2: 黄老师课堂 22:05 6.1 | L2: 43983 | M2: 中文 | N2: 兼 | O2: 是
A3: 6.1/22:05 | B3: 美国 | C3: 12 | D3: 王晨 | E3: 0 | F3: 杨乐乐 | G3: 8 | H3: 2年级或3年级，识字量100+没有准确统计过 | I3: 想直接试黄莺老师的课 | J3: 国内134晚上22:05 | K3: 黄老师课堂 22:05 6.1 | L3: 43983 | M3: 中文 | N3: 兼 | O3: 是
A4: 5.3 | B4: 西班牙 | C4: 6 | D4: 王可 | E4: 3 | F4: 王天缘 | G4: 14 | H4: 一上八单元 | I4: 表达能力较弱，识字量大，性格活泼爱笑，老师讲课要慢一些 | J4: 晚上11点半 | K4: 四十三课堂 23:40 6.1 | L4: 43983 | M4: 中文 | N4: 夜 | O4: 是
A5: 5.31 | B5: 美国 | C5: 15 | D5: 张文红 | E5: 3 | F5: Krystal | G5: 16 | H5: 建议拼音zh;ch;sh;r开始学起，很有耐心学习，认字量在10个左右，慢一点说可以听懂。 | J5: 国内早上八点 | K5: 言智16 7：00 6.2 | L5: 43984 | M5: 中文 | N5: 兼 | O5: 是
B6: 澳大利亚 | C6: 2 | D6: 张文红 | E6: 3 | F6: 陈远熙 | G6: 8 | H6: 建议天地人学起，零基础，学生比较好动，注意力不是太集中。双语 | I6: 需要双语，零基础 | J6: 国内时间18:30 | K6: 言智02 18:30 6.1 | L6: 43983 | M6: 中文 | N6: 兼 | O6: 是
B7: 美国 | C7: 15 | D7: 丁阮琪 | E7: 2 | F7: 李俊熙 | G7: 10 | H7: 已缴费，要魏霞老师教，一上六七单元开始上 | I7: 要魏霞老师教，一对一，已缴费 | J7: 国内早上11点 | K7: 魏老师课堂 11:00 6.2 | L7: 43984 | M7: 中文 | N7: 兼 | O7: 是
A8: 5.31 | B8: 美国 | C8: 15 | D8: 张文红 | E8: 3 | F8: Howard | G8: 8 | H8: 建议YCT的课学起，零基础，不太爱说话，有一点抵触发音比较慢。老师多引导 | J8: 国内早上八点 | K8: play east01 7:50 6.2 | L8: 43984 | M8: yct | N8: 兼 | O8: 是
A9: 6.1 | B9: 西班牙 | C9: 6 | D9: 欧阳江勇 | E9: 5 | F9: 张家盛 | G9: 10 | H9: 数学课，老师建议从四年级下册开始 | I9: 时间最好安排在国内凌晨四点左右 | J9: 国内凌晨04：00～05：00 | K9: 十一课堂 4：20 6.2 | L9: 43984 | M9: 中文 | N9: 夜
B10: 美国 | C10: -12 | D10: 翁珊珊 | E10: 3 | F10: 林雅熙 | G10: 10 | H10: 建议d;t;n;l开始学起，声调也不太会要复习。妈妈也希望拼音学起。认字量大一上第七单元的生字都认识，比较文静。 | I10: 家长想试一对二或者一对一的班级 | J10: 国内时间周5的早上七点到九点 | K10: 言智19 7：40 6.5 | L10: 43987 | M10: 中文 | N10: 兼 | O10: 是
A11: 5.31 | B11: 美西 | C11: 15 | D11: 王可 | E11: 3 | F11: 高一凡 | G11: 10 | H11: 三上第一单元 | J11: 中国上午11点 | K11: s课堂11:40 6.3 | L11: 43985 | M11: 中文 | N11: 白 | O11: 是
A12: 6.2 | B12: 美西圣何塞 | C12: 15 | D12: 毛益丹 | E12: 3 | F12: 陆时安 | G12: 快7岁 | H12: 建议一下二、三单元开始，认字较多，词汇不理解。说话比较慢，会回应老师，不热情。 | I12: 不需要老师 | J12: 中国早上7:00 | K12: O课堂 7：00 6.3 | L12: 43985 | M12: 中文 | N12: 白 | O12: 是
A13: 6.2 | B13: 美西旧金山 | C13: 15 | D13: 毛益丹 | E13: 3 | F13: 苑舒欣 | G13: 快7岁了 | H13: 建议拼音aoe开始学，沟通没问题，简单的字认识，拼音声调不认识 | I13: 学过一些中文，不太多 | J13: 国内早上7:00-9:00或10:00-11:00都可以 | K13: I课堂 11:00 6.2 | L13: 43984 | M13: 中文 | N13: 白 | O13: 是 | P13: 失败
A14: 6.2 | B14: 美东 | C14: 12 | D14: 展旺 | E14: 3 | F14: 林进轩 | G14: 11岁 | H14: 拼音忘记了，平翘舌不分，识字量丰富。建议三上中间，后面部分学习。 | I14: 一对一的，满意就缴费。我要求：1，安中国三年开始教，2，帮忙纠正拼音，有的忘了，可以穿插课堂教点，3，写字笔画也需要纠正。 | J14: 国内早上7:30到8：00 | K14: Chineseonline T10 7:30 6.3 | L14: 43985 | M14: 中文 | N14: 兼 | O14: 是
A15: 6.2 | B15: 英国 | C15: 7 | D15: 何家昌 | E15: 1 | F15: 常艺霏 | G15: 8 | H15: 孩子程度不错 ，拼音不是非常好，建议从一年级上册中后段开始 | I15: 已缴费，一对四。 | J15: 周一到周四16:00到16:30或者周一到周五19:30到20:00 | K15: A课堂 16：00 6.3 | L15: 43985 | M15: 中文 | N15: 白 | O15: 是
A16: 6.3 | B16: 加拿大 | C16: 15 | D16: 俞酉兰 | F16: 嘉轩 | G16: 8 | H16: 零基础 YCT 6月4号10点的课程 | I16: 6月4号上午10点 | J16: 6月4号上午10点 | K16: play east01 10:00 6.4 | L16: 43986 | M16: yct | N16: 兼 | O16: 是
A17: 6.2 | B17: 美西 | C17: 15 | D17: 王可 | E17: 3 | F17: 高泊宇 | G17: 11 | H17: 一下三单元 声调会搞混 | I17: 想要稍微难一点的，太简单担心孩子会觉得无聊 | J17: 国内上午11:40 | K17: H课堂 11:40 6.4 | L17: 43986 | M17: 中文 | N17: 白 | O17: 是
A18: 6.2 | B18: 美西 | C18: 15 | D18: 王可 | E18: 3 | F18: 高泊翔 | G18: 9 | H18: 一上六七单元 不太会造句 | J18: 国内上午11:40 | K18: J 课堂 11:40 6.4 | L18: 43986 | M18: 中文 | N18: 白 | O18: 是
A19: 6.3 | B19: 美西 | C19: 15 | D19: 杨斌 | E19: 3 | F19: 唐源 | G19: 10 | H19: 建议五上开始，所有生字都认识，文章表层含义理解，深层道理不理解，不会总结 | J19: 国内早上七点以后 | K19: L 课堂 9：00 6.4 | L19: 43986 | M19: 中文 | N19: 白 | O19: 是
A20: 6.2 | B20: 美国 | C20: 15 | D20: 王可 | E20: 3 | F20: Abby | G20: 8 | H20: 一下二三单元，学生程度很好，过度害羞，不开摄像头 | J20: 中国早上8-10点 | K20: E课堂 9：40 6.4 | L20: 43986 | M20: 中文 | N20: 白 | O20: 否
A21: 6.5 | B21: 美国 | C21: 12 | D21: 胡东东 | E21: 5 | F21: 柳宇翔 | G21: 10 | H21: 一上末尾开始 | I21: 老师上课生动一点，能让孩子学习到知识 妈妈想上一对1或1对2 | J21: 国内周五早上9点 | K21: Chineseonline T10 9:00 6.5 | L21: 43987 | M21: 中文 | N21: 兼 | O21: 是
B22: 美国 | C22: 15 | D22: 程蕾 | E22: 3 | F22: 小龙 | G22: 7 | H22: 一年级上册 | I22: 拼音学完了，能中文交流 | J22: 国内早上9：00-12;00 | K22: O课堂 7:40 6.4 | L22: 43986 | M22: 中文 | N22: 白 | O22: 否
A23: 6.4 | B23: 美国 | C23: 12 | D23: 高翱翔 | E23: 2 | F23: 孙浩轩 | G23: 9 | H23: 零基础，可以从拼音开始学起，家长不测试，直接安排小班试课 | I23: 小班测课满意就缴费， | J23: 国内7点到8点之间 | K23: N 课堂 7:40 6.5 | L23: 43987 | M23: 中文 | N23: 白 | O23: 是
A24: 6.3 | B24: 美国 | C24: 12 | D24: 刘箫 | E24: 5 | F24: jayden | G24: 8 | H24: 0基础，家长要求从拼音开始学起【已缴费】 | I24: 上课时间在7点到8点之间 | J24: 国内7点到8点之间 | K24: N 课堂 7:40 6.5 | L24: 43987 | M24: 中文 | N24: 白 | O24: 是
A25: 6.3 | B25: 美国 | C25: 12 | D25: 展望 | E25: 3 | F25: 王锦文 | G25: 6 | H25: 建议拼音学起，配合度高很听话。说的能力好很爱表现，认字量50个内。 | I25: 国内上午7：30——9：00.已缴费 | J25: 国内时间7：30——9：00 | K25: N 课堂 7:40 6.5 | L25: 43987 | M25: 中文 | N25: 白 | O25: 是
A26: 6.4 | B26: 美东 | C26: 12 | D26: 翁珊珊 | E26: 3 | F26: Evangela | G26: 7 | H26: 建议从一上四五单元开始学 | J26: 国内时间9：00 | K26: O课堂 7:40 | L26: 43988 | M26: 中文 | N26: 白 | O26: 否
A27: 5.31 | B27: 美西 | C27: 15 | D27: 王可 | E27: 3 | F27: Aine | G27: 5 | H27: 天地人开始 | I27: 需要双语老师 | J27: 中国早上七八点 | K27: 言智31 8:30 6.5 | L27: 43987 | M27: 中文 | N27: 兼 | O27: 是
D28: 王可 | E28: 3 | F28: Logan | G28: 8 | H28: 天地人开始 | I28: 需要双语老师 | J28: 中国早上七八点 | K28: 言智31 8:30 6.5 | L28: 43987 | M28: 中文 | N28: 兼 | O28: 是
A29: 6.3 | B29: 美国 | C29: 12 | D29: 平金军 | E29: 2 | F29: 林宇 | G29: 12 | H29: 建议拼音开始学起， | I29: 反映有点慢说中文的能力不太好，要双语老师， | J29: 国内早上7:30 | K29: 言智07 7:30 6.7 | L29: 43989 | M29: 中文 | N29: 兼 | O29: 是
A30: 6.4 | B30: 加拿大 | C30: 15 | D30: 俞酉兰 | F30: 彤彤 | G30: 7 | H30: 零基础 直接试课 | J30: 国内早上7点40 | K30: N课堂7:40 6.5 | L30: 43987 | M30: 中文 | N30: 白 | O30: 是
A31: 6.4 | B31: 美国 | C31: 12 | D31: 胡东东 | E31: 5 | F31: 黄博腾 | G31: 11 | H31: 你我他开始 | I31: 已缴费，一对二 。希望细心一点的老师，活泼一点的老师，一周三天一三五 | J31: 国内早上7点半 | K31: 言智16 7:50 6.6 | L31: 43988 | M31: 中文 | N31: 兼 | O31: 是
A32: 6.4 | B32: 加拿大 | C32: 15 | D32: 俞酉兰 | F32: 方宝 | G32: 14 | H32: 四上 | J32: 国内9多到10点 | K32: F课堂 11:40 6.5 | L32: 43987 | M32: 中文 | N32: 白 | O32: 否
A33: 6.5 | B33: 美国旧金山 | C33: -15 | D33: 赵国花 | E33: 2 | F33: 张心桥 | G33: 8.5 | H33: 零基础，建议YCT的课程，学生很认真乖巧。双语 | I33: 跟家长谈好一对一的课程了 明天付钱 要求明天就上课 请周老师一定拍好课 家长希望杨老师上课 而且不能中途换老师 | J33: 国内时间早上7:30-8:30 | K33: 已发yct play east02 8:00 6.6 | L33: 43988 | M33: yct | N33: 兼 | O33: 是
A34: 6.6 | B34: 美国纽约 | C34: 12 | D34: 张霞 | E34: 3 | F34: 林志刚 | G34: 11 | H34: 学生有一定的基础，上课非常认真，简单的生字都是认识的，但是学过的拼音有很多遗忘了，家长想让孩子打好基础，建议从拼音的aieiui开始学。 | I34: 家长希望老师能耐心点，孩子不喜欢太吵了。 | J34: 国内7点～9点 | K34: Z课堂 8:20 6.6 | L34: 43988 | M34: 中文 | N34: 白 | O34: 是
A35: 6.6 | B35: 美国纽约 | C35: 12 | D35: 展旺 | E35: 3 | F35: 郑丽颍 | G35: 10 | H35: 一上第四单元开始学起，双语。课文能读下来，每个词语都需要英语解释，双语 | I35: 老师好一点的，双语老师 | J35: 国内早上7：00后，9：00前 | K35: 双语课堂 8：20 6.6 | L35: 43988 | M35: 中文 | N35: 白 | O35: 是
A36: 6.5 | B36: 加拿大温哥华 | C36: -15 | D36: 张多多 | E36: 0 | F36: 李艾文 | G36: 7 | H36: 孩子配合，建议从基础拼音aoe开始学习 | I36: 家长希望孩子能感兴趣学习中文 把他学好 孩子自己也在自学汉字 | J36: 时间自由 有合适的班级就可以上课 | K36: N课堂 7:40 6.6 | L36: 43988 | M36: 中文 | N36: 白 | O36: 否
A37: 6.5 | B37: 美国纽约 | C37: 12 | D37: 展旺 | E37: 3 | F37: 张恭旭 | G37: 7 | H37: 拼音零基础，认识简单的生字，建议学生从拼音开始学习。 | I37: 要好点的老师，细心耐心一点的，不然还要换课堂。 | J37: 国内早上7：00到8：30都可以 | K37: N课堂 7:40 6.6 | L37: 43988 | M37: 中文 | N37: 白 | O37: 是
B38: 澳大利亚 | C38: 2 | D38: 毛益丹 | E38: 3 | F38: 陈笑涵 | G38: 11岁 | H38: 建议一下第六七单元学起，配合上课，喜欢被夸奖。想当朗读家 | I38: 学过拼音，家长要求一定要一个好的老师，能够学到东西的 | J38: 国内下午5:10 | K38: J课堂 17:10 6.5 | L38: 43987 | M38: 中文 | N38: 白 | O38: 是
A39: 6.5 | B39: 美国 | C39: 15 | D39: 程蕾 | E39: 3 | F39: 小龙 | G39: 7 | H39: 拼音学过，直接试课，可以从一年级上册排 | J39: 10点到12点 | K39: A课堂 10:20 6.8 | L39: 43990 | M39: 中文 | N39: 白 | O39: 是
A40: 6.5 | B40: 美国旧金山 | C40: -15 | D40: 赵国花 | E40: 2 | F40: 吴钟凯 | G40: 10 | H40: 建议一上第四单元开始学起，不太爱说话要引导。 | I40: 希望老师耐心点教他 他表达力弱一些 句子太长了也就听不懂了 | J40: 上午10:30-11:30 | K40: N课堂 9:00 6.6 | L40: 43990 | M40: 中文 | N40: 白 | O40: 是
...

Sheet 美术课
A1: 日期 | B1: 国家 | C1: 时差 | D1: 业务员 | E1: 组别 | F1: 学生姓名 | G1: 年龄 | H1: 预排年级 | I1: 特殊要求 | J1: 上课时间（中国） | K1: 排课安排

Sheet 书法
A1: 日期 | B1: 国家 | C1: 时差 | D1: 业务员 | E1: 组别 | F1: 学生姓名 | G1: 年龄 | H1: 预排年级 | I1: 特殊要求 | J1: 上课时间（中国） | K1: 排课安排

Sheet 编程
A1: 日期 | B1: 国家 | C1: 时差 | D1: 业务员 | E1: 组别 | F1: 学生姓名 | G1: 年龄 | H1: 预排年级 | I1: 特殊要求 | J1: 上课时间（中国） | K1: 排课安排

Sheet 数学课
A1: 日期 | B1: 国家 | C1: 时差 | D1: 业务员 | E1: 组别 | F1: 学生姓名 | G1: 年龄 | H1: 预排年级 | I1: 特殊要求 | J1: 上课时间（中国） | K1: 排课安排

Sheet 英语
A1: 日期 | B1: 国家 | C1: 时差 | D1: 业务员 | E1: 组别 | F1: 学生姓名 | G1: 年龄 | H1: 预排年级 | I1: 特殊要求 | J1: 上课时间（中国） | K1: 排课安排

Sheet HSK、YCT
A1: 日期 | B1: 国家 | C1: 时差 | D1: 业务员 | E1: 组别 | F1: 学生姓名 | G1: 年龄 | H1: 预排年级 | I1: 特殊要求 | J1: 上课时间（中国） | K1: 排课安排
A18: 岁
