Workbook

Sheet 《2020年试读名单-启蒙课》
A1: 序号 | B1: 测试时间 | C1: 国家 | D1: 城市 | E1: 时差 | F1: 家长微信名 | G1: 家长微信 | H1: 电话号码 | I1: 学生姓名 | J1: 缴费 | K1: 年龄 | L1: 性别 | M1: 有没有学过拼音 | N1: 是否需要双语老师 | O1: 家长自述程度及学习需求 | P1: 学习课程 | Q1: 测试结果 | R1: 排课安排 | S1: 来源 | T1: 组别 | U1: 业务员 | V1: 试读日期 | W1: 试课安排 | X1: 排课校区 | Y1: 是否在读 | Z1: 是否缴费 | AA1: 失败原因 | AB1: 课程单价 | AC1: 折扣 | AD1: 实收 | AE1: 首次收费时间
B2: 44013 | C2: 澳大利亚 | E2: 2 | F2: joanneys | G2: joanneys | I2: 黄若毅 | J2: =IFERROR(VLOOKUP(I2,Sheet1!A:B,2,FALSE),"zhaobudao") -> 是 | K2: 5 | L2: 男 | M2: 否 | N2: 是 | O2: 可以听得懂 但是不愿意开口说中文 | P2: 启蒙中文 | R2: 张倩 18:30 7.1 | S2: 介绍 | T2: 3 | U2: 翁珊珊 美丽妈妈介绍 | Y2: 1 | Z2: 1 | AA2: 1 | AB2: 116/课 | AC2: 一对一46+2 | AD2: 755.31 | AE2: 7.2日缴费
B3: 44014 | C3: 美国 | D3: 东部 | E3: 12 | H3: 001-7188082035 | I3: 梁彧博 | J3: =IFERROR(VLOOKUP(I3,Sheet1!A:B,2,FALSE),"zhaobudao") -> zhaobudao | K3: 8 | L3: 男 | M3: 否 | N3: 否 | O3: 希望哥哥和妹妹一起学，因为都学过五四快读，识字量差不多 | P3: 启蒙中文 | R3: 林玲玲 6:00 7.2 | S3: 介绍 | T3: 3 | U3: 张文红 | Y3: 1 | Z3: 1 | AA3: 1 | AB3: 116/课 | AC3: 一对一65+3 | AD3: 7540 | AE3: 7.6日缴费
B4: 44014 | C4: 美国 | D4: 东部 | E4: 12 | H4: 001-7188082035 | I4: 梁书婧 | J4: =IFERROR(VLOOKUP(I4,Sheet1!A:B,2,FALSE),"zhaobudao") -> zhaobudao | K4: 5 | L4: 女 | M4: 否 | N4: 否 | O4: 希望哥哥和妹妹一起学，因为都学过五四快读，识字量差不多 | P4: 启蒙中文 | R4: 林玲玲 7:00 7.2 | S4: 介绍 | T4: 3 | U4: 张文红
B5: 44014 | C5: 美国 | D5: 东部 | E5: 12 | F5: felicia | G5: chippiopio | H5: +1 9176671031 | I5: 齊藤鎮彥 | J5: =IFERROR(VLOOKUP(I5,Sheet1!A:B,2,FALSE),"zhaobudao") -> zhaobudao | K5: 5.5 | N5: 是 | P5: 启蒙数学 | R5: 卢爽 21:00 7.2 | S5: 微信 | T5: 3 | U5: 王可
B6: 44015 | C6: 美中 | E6: 13 | G6: Lily | H6: xc420695634 | I6: lexi | J6: =IFERROR(VLOOKUP(I6,Sheet1!A:B,2,FALSE),"zhaobudao") -> zhaobudao | K6: 4.5 | L6: 男 | M6: 否 | N6: 否 | O6: 会中文交流，认识一两百字 | P6: 启蒙 | R6: 童美英 8:00 7.3 | S6: 微信 | T6: 3 | U6: 王可
B7: 44015 | C7: 澳洲 | H7: +61 433603061 | I7: 车伊然 | J7: =IFERROR(VLOOKUP(I7,Sheet1!A:B,2,FALSE),"zhaobudao") -> zhaobudao | K7: 3.5 | M7: 否 | N7: 否 | O7: 可以交流 | P7: 启蒙 | R7: 吴岚 15:00 7.3 | S7: 微信 | T7: 3 | U7: 王可
B8: 44015 | C8: 加拿大 | H8: 无账号 | I8: 陈熙 | J8: =IFERROR(VLOOKUP(I8,Sheet1!A:B,2,FALSE),"zhaobudao") -> zhaobudao | K8: 3 | L8: 男 | M8: 否 | N8: 否 | O8: 零基础，交流可以，孩子很不愿意主动讲话 | P8: 启蒙 | R8: 许杰8:30 7.3 | S8: 微信 | T8: 1 | U8: 何家昌1
B9: 44015 | C9: 美国 | H9: 16504070006 | I9: 吴舒瑶 | J9: =IFERROR(VLOOKUP(I9,Sheet1!A:B,2,FALSE),"zhaobudao") -> 是 | L9: 女 | M9: 否 | N9: 否 | O9: 可以交流 | P9: 启蒙 | R9: 蒋铄 7:20 7.3 | S9: 微信 | T9: 3 | U9: 王可
B10: 44015 | C10: 加拿大 | H10: 17782889773 | I10: Nina | J10: =IFERROR(VLOOKUP(I10,Sheet1!A:B,2,FALSE),"zhaobudao") -> zhaobudao | K10: 4岁 | L10: 女 | M10: 否 | N10: 否 | O10: 会中文交流 零基础 | P10: 启蒙 | R10: 张倩 8:00 7.3 | T10: 白 | U10: 俞酉兰
B11: 44015 | C11: 马来西亚 | H11: 60122236813 | I11: 颜豪庆 | J11: =IFERROR(VLOOKUP(I11,Sheet1!A:B,2,FALSE),"zhaobudao") -> zhaobudao | K11: 3.5 | L11: 男 | M11: 否 | N11: 否 | O11: 会交流，零基础 | P11: 启蒙 | R11: 林玲玲 19:00 7.3 | T11: 白
B12: 44015 | C12: 美西 | E12: 15 | F12: wechunku | G12: klaviergirl91 | I12: Dana Lin | J12: =IFERROR(VLOOKUP(I12,Sheet1!A:B,2,FALSE),"zhaobudao") -> zhaobudao | K12: 6 | L12: 女 | O12: 三位数加法，基本九九乘法 | P12: 启蒙数学 | R12: 解一聪 8:40 7.3 | S12: 微信 | T12: 3 | U12: 程蕾
B13: 44015 | C13: 美国 | F13: Serena | G13: serena138 | H13: 1 5086157686 | I13: 乐乐 | J13: =IFERROR(VLOOKUP(I13,Sheet1!A:B,2,FALSE),"zhaobudao") -> zhaobudao | K13: 5岁 | L13: 女 | M13: 没有 | N13: 否 | O13: 中文一般，认识20个汉字 | P13: 启蒙中文 | R13: 许杰 7:30 7.3 | S13: 微信 | T13: 3 | U13: 毛益丹
B14: 44015 | C14: 美国 | F14: Serena | G14: serena138 | H14: 1 3303895044 | I14: 点点 | J14: =IFERROR(VLOOKUP(I14,Sheet1!A:B,2,FALSE),"zhaobudao") -> zhaobudao | K14: 快5岁 | L14: 女 | M14: 没有 | N14: 否 | O14: 有自己教她认字，进度是四五快读完成了第一册和第二册，平常在家里都说中文，希望后续学拼音 | P14: 启蒙中文 | R14: 许杰 7:30 7.3 | S14: 微信 | T14: 3 | U14: 毛益丹
B15: 44016 | C15: 澳大利亚悉尼 | H15: 416640906 | I15: camille | J15: =IFERROR(VLOOKUP(I15,Sheet1!A:B,2,FALSE),"zhaobudao") -> zhaobudao | K15: 2.5岁 3岁 | L15: 女 | M15: 没有 | N15: 需要 | O15: 小的两岁出头，大宝因为语言发育迟缓，跟小的差不多，中文会基本的沟通，也不是很懂。家长说试试看孩子能不能坐的住 | R15: 国内下午17:30-18:00蒋铄 | U15: 张仁波0
B16: 44016 | C16: 澳大利亚悉尼 | H16: 416640906 | I16: damier | J16: =IFERROR(VLOOKUP(I16,Sheet1!A:B,2,FALSE),"zhaobudao") -> zhaobudao | K16: 2.5岁 3岁 | L16: 女 | M16: 没有 | N16: 需要 | O16: 小的两岁出头，大宝因为语言发育迟缓，跟小的差不多，中文会基本的沟通，也不是很懂。家长说试试看孩子能不能坐的住 | R16: 国内下午17:30-18:00蒋铄 | U16: 张仁波0
B17: 44016 | C17: 加拿大多伦多 | H17: 5147466789 | I17: 王泰博 | J17: =IFERROR(VLOOKUP(I17,Sheet1!A:B,2,FALSE),"zhaobudao") -> zhaobudao | K17: 6岁 | L17: 男 | M17: 没有 | N17: 否 | O17: 认识几个字 喜欢攀岩 听说OK 家里尽力提供中文环境 | R17: 21：00-21:30许杰 | U17: 赵国花2
B18: 44016 | C18: 加拿大温哥华 | H18: 7789286579 | I18: 晨晨 | J18: =IFERROR(VLOOKUP(I18,Sheet1!A:B,2,FALSE),"zhaobudao") -> zhaobudao | K18: 5.5岁 | L18: 男 | M18: 没有 | N18: 否 数学 | O18: 学习数学哦，孩子零基础，没有学习过数学哦。喜欢卡通 | R18: 11：00-11:30解一聪 | U18: 高翱翔2
B19: 44016 | C19: 加拿大温哥华 | H19: 7789286579 | I19: 晨晨 | J19: =IFERROR(VLOOKUP(I19,Sheet1!A:B,2,FALSE),"zhaobudao") -> zhaobudao | K19: 5.5岁 | L19: 男 | M19: 没有 | N19: 否 | O19: 学习中文，孩子平时在家中文交流没有问题，没有学习过拼音什么的喜欢卡通 | R19: 9：00-9:30蒋铄 | U19: 高翱翔2
A20: 二次试读 | B20: 44017 | C20: 美国西海岸 | H20: 1 9192822200 | I20: 米明西 | J20: =IFERROR(VLOOKUP(I20,Sheet1!A:B,2,FALSE),"zhaobudao") -> zhaobudao | K20: 6岁 | L20: 男 | M20: 学过 | N20: 否 | O20: 没有系统学习，不过在看其他学中文的app。拼音基本都会，但是还是有一些不熟练， 而且拼的比较慢，某些字也会拼错， 像“无”字， 他会直接打u，不是wu；建议一年级上册五六单元，孩子话很多，会打断老师聊天，拼音发音二声容易读成四声。因为孩子觉得小学语文枯燥转过来的，孩子喜欢有趣的课程，老师尽量提升宝贝的兴趣 | R20: 国内早上7:00张倩 | U20: 毛益丹3
B21: 44016 | C21: 美国西海岸 | H21: 323 283 7396 | I21: 武雨桐 | J21: =IFERROR(VLOOKUP(I21,Sheet1!A:B,2,FALSE),"zhaobudao") -> zhaobudao | K21: 四岁 | L21: 女 | M21: 否 | N21: 是 | O21: 零基础，一般的对话可以，害羞喜欢画画粉色 大裙子 | R21: 国内早上八点半张倩 | U21: 刘巧芹2 | Y21: 1 | Z21: 1 | AA21: 1 | AB21: 96/课 | AC21: 一对一收一对二44 | AD21: 4224 | AE21: 7.6日缴费
B22: 44016 | C22: 美国西部 | H22: 1 6692566661 | I22: 小宝 | J22: =IFERROR(VLOOKUP(I22,Sheet1!A:B,2,FALSE),"zhaobudao") -> zhaobudao | K22: 快5岁 | M22: 没有 | N22: 否 | O22: 不会写字，会认100个字左右，交流的话中文很好，会很多成语，暂时不学拼音 | R22: 国内早上7:00吴岚 | U22: 毛益丹3
B23: 44016 | C23: 加拿大 | D23: 温哥华 | E23: 15 | F23: Liberty | G23: Liberty_feng | H23: +1 6043387728 | I23: 徐志镐 | J23: =IFERROR(VLOOKUP(I23,Sheet1!A:B,2,FALSE),"zhaobudao") -> zhaobudao | K23: 月底满3岁 | L23: 男 | M23: 否 | N23: 是 | O23: 会说粤语，和一点中文 不会说英文 | P23: 启蒙 | R23: 国内9点张媛媛 | S23: 扫一扫 | T23: 白 | U23: 俞酉兰
A24: 二次试读 | B24: 44017 | F24: 早上7:30张倩 | G24: 美东 | H24: 9176052667 | I24: Darren Ma | J24: =IFERROR(VLOOKUP(I24,Sheet1!A:B,2,FALSE),"zhaobudao") -> zhaobudao | K24: 6 | L24: 男 | M24: 否 | N24: 是 | O24: 孩子零基础，会说一点中文 | P24: 翁珊珊3
B25: 44017 | F25: 国内早上7点钟许杰 | G25: 加拿大 | H25: 17788296089 | I25: Nicole | J25: =IFERROR(VLOOKUP(I25,Sheet1!A:B,2,FALSE),"zhaobudao") -> zhaobudao | K25: 6.5 | L25: 女 | M25: 否 | N25: 是 | O25: 会说中文 不会写 有的时候听不懂 | P25: 启蒙 | T25: 白 | U25: 俞酉兰
B26: 44017 | C26: 美中 | E26: 13 | F26: rina | G26: rina4557715 | I26: Elina | J26: =IFERROR(VLOOKUP(I26,Sheet1!A:B,2,FALSE),"zhaobudao") -> zhaobudao | K26: 6 | L26: 女 | M26: 没有 | N26: 是 | O26: 有时会用中文交流 | P26: 中文 | S26: 微信 | T26: 3 | U26: 翁珊珊
B27: 44018 | C27: 美国 | D27: 西部 | E27: 15 | G27: 13807489455 | I27: 秦可伊 | J27: =IFERROR(VLOOKUP(I27,Sheet1!A:B,2,FALSE),"zhaobudao") -> zhaobudao | K27: 4岁半 | L27: 女 | M27: 否 | N27: 否 | O27: 妈妈在家教了一些字 | P27: 启蒙 | R27: 卢爽8:00 7.6 | T27: 3 | U27: 张霞
B28: 44019 | C28: 美国 | D28: 加利福尼亚 | E28: 15 | H28: 17788583038 | I28: Felicia | J28: =IFERROR(VLOOKUP(I28,Sheet1!A:B,2,FALSE),"zhaobudao") -> zhaobudao | K28: 5.5 | L28: 女 | M28: 否 | N28: 是 | O28: 没学过 一家的 一块上 | P28: 启蒙中文 | R28: 卢爽 7:00 7.7 | T28: 白 | U28: 俞酉兰
B29: 44019 | C29: 美国 | D29: 加利福尼亚 | E29: 15 | H29: 17788583038 | I29: Natasha | J29: =IFERROR(VLOOKUP(I29,Sheet1!A:B,2,FALSE),"zhaobudao") -> zhaobudao | K29: 4 | L29: 女 | M29: 否 | N29: 是 | O29: 没学过 一家的 一块上 | P29: 启蒙中文 | R29: 卢爽 7:00 7.7 | T29: 白 | U29: 俞酉兰
B30: 44019 | C30: 加拿大 | D30: 温哥华 | E30: 15 | H30: 7786808698 | I30: 陆子涵 | J30: =IFERROR(VLOOKUP(I30,Sheet1!A:B,2,FALSE),"zhaobudao") -> 是 | K30: 6 | L30: 女 | M30: 学过 | N30: 否 | O30: 从启蒙开始，20以内的加减法，扳着手指头算 | P30: 启蒙数学 | R30: 卢爽8:15 7.7 | U30: 任宏印
B31: 44019 | C31: 美国 | D31: 西部 | E31: 15 | H31: 13811239849 | I31: 卡卡 | J31: =IFERROR(VLOOKUP(I31,Sheet1!A:B,2,FALSE),"zhaobudao") -> zhaobudao | K31: 5 | L31: 男 | M31: 否 | N31: 否 | O31: 有在网络中文课，还没学拼音，有意向学拼音课 | P31: 启蒙中文 | R31: 卢爽 7:00 7.7 | S31: 微信 | T31: 3 | U31: 毛益丹

Sheet 2020.7
A1: 序号 | B1: 测试时间 | C1: 国家 | D1: 城市 | E1: 时差 | F1: 家长微信名 | G1: 家长微信 | H1: 电话号码 | I1: 学生姓名 | K1: 缴费 | L1: 年龄 | M1: 性别 | N1: 有没有学过拼音 | O1: 是否需要双语老师 | P1: 家长自述程度及学习需求 | Q1: 学习课程 | R1: 测试结果 | S1: 排课安排 | T1: 来源 | U1: 组别 | V1: 业务员 | W1: 试读日期 | X1: 试课安排 | Y1: 排课校区 | Z1: 是否在读 | AA1: 是否缴费 | AB1: 失败原因 | AC1: 课程单价 | AD1: 折扣 | AE1: 实收 | AF1: 首次收费时间
B2: 44013 | C2: 美国 | D2: 美东 | E2: 12 | F2: Yijie Liu | G2: cytotech | I2: 黄善泽 | J2: =TRIM(I2) -> 黄善泽 | K2: =IFERROR(VLOOKUP(J2,Sheet1!A:B,2,FALSE),"zhaobudao") -> zhaobudao | L2: 7 | M2: 男 | N2: 是 | O2: 否 | P2: 孩子之前学习过中文，家长说有二年级的程度，拼音会一点 | Q2: 中文 | R2: 一年级下册，发音不够标准，老师要强调 | S2: 刘钰兰；8:20；7.1 | T2: 微信 | U2: 2 | V2: 高翱翔 | Z2: 0 | AA2: 0
B3: 44013 | C3: 美国 | D3: 西部 | E3: 15 | F3: Jane | G3: zhuangdou2013 | I3: 邵子鑫 | J3: =TRIM(I3) -> 邵子鑫 | K3: =IFERROR(VLOOKUP(J3,Sheet1!A:B,2,FALSE),"zhaobudao") -> zhaobudao | L3: 13岁 | N3: 学过 | O3: 否 | P3: 在美国的中文学校学中文，开学马上升八年级，会拼音 | Q3: 中文 | R3: 三年级上册，一单元，发音标准，难一点的字不认识 | S3: 刘钰兰；9:00；7.1 | T3: 家长介绍 | U3: 3 | V3: 毛益丹
B4: 44013 | C4: 美国 | D4: 西部 | E4: 15 | F4: Jane | G4: zhuangdou2013 | I4: 邵子晗 | J4: =TRIM(I4) -> 邵子晗 | K4: =IFERROR(VLOOKUP(J4,Sheet1!A:B,2,FALSE),"zhaobudao") -> zhaobudao | L4: 11岁 | N4: 学过 | O4: 否 | P4: 在美国的中文学校学中文，开学马上升六年级，会拼音 | Q4: 中文 | R4: 建议从二下一单元开始，发音标准，表达理解可以。 | S4: 张璐；9:40；7.1 | T4: 家长介绍 | U4: 3 | V4: 毛益丹
B5: 44013 | C5: 美西 | E5: 15 | F5: 顽皮鼠 | G5: Wanpishu | I5: 李嘉宝 | J5: =TRIM(I5) -> 李嘉宝 | K5: =IFERROR(VLOOKUP(J5,Sheet1!A:B,2,FALSE),"zhaobudao") -> zhaobudao | L5: 7岁 | M5: 男 | N5: 学过一点 | O5: 否 | P5: 基本的听说没有问题，学过一点拼音 | Q5: 中文 | R5: 一年级上册，四单元秋天开始，拼音全认识，发音标准 | S5: 刘钰兰；9:40；7.1 | T5: 微信 | U5: 3 | V5: 毛益丹
B6: 44013 | C6: 加拿大 | D6: 多伦多 | E6: -12 | F6: 建华 | G6: yoo_hoo76 | I6: 金子鉴 | J6: =TRIM(I6) -> 金子鉴 | K6: =IFERROR(VLOOKUP(J6,Sheet1!A:B,2,FALSE),"zhaobudao") -> zhaobudao | L6: 7岁 | M6: 男 | N6: 有 | O6: 否 | P6: 拼音都学习过读的不标准 大概认识100多个汉字 | Q6: 中文 | R6: 学生发音不是很好，有带国外的口音，词汇量少，不太会组词，建议从一上四单元开始上课 | S6: 周虹 7:40 7-1 | T6: 微信 | U6: 2 | V6: 赵国花
B7: 44013 | C7: 加拿大 | E7: 12 | F7: Yulanda(莹) | G7: yy6479968110 | I7: 乐乐 | J7: =TRIM(I7) -> 乐乐 | K7: =IFERROR(VLOOKUP(J7,Sheet1!A:B,2,FALSE),"zhaobudao") -> zhaobudao | L7: 7 | M7: 女 | N7: 是 | O7: 否 | P7: 在当地有在学习 | Q7: 中文 | R7: 比较害羞，慢热，涉及到复韵母的读音会有点问题，建议从一上五六单元开始上课 | S7: 周虹 8:207-1 | T7: 微信 | U7: 1 | V7: 何家昌
B8: 44013 | C8: 美国 | D8: 中部 | E8: 13 | F8: Chaoying | G8: chaoyingz66 | I8: 陈凯琳 | J8: =TRIM(I8) -> 陈凯琳 | K8: =IFERROR(VLOOKUP(J8,Sheet1!A:B,2,FALSE),"zhaobudao") -> zhaobudao | L8: 10岁 | M8: 女 | N8: 学过 | O8: 否 | P8: 一二年级的水平 | Q8: 中文 | R8: 学生发音标准，朗读流畅，识字量大，建议从二下开始学习 | S8: 周虹 9:00 7-1 | T8: 家长介绍 | U8: 3 | V8: 毛益丹
B9: 44013 | C9: 澳大利亚 | E9: 2 | F9: DI | G9: diyu1065630866 | I9: 陈楚妍 | J9: =TRIM(I9) -> 陈楚妍 | K9: =IFERROR(VLOOKUP(J9,Sheet1!A:B,2,FALSE),"zhaobudao") -> zhaobudao | L9: 11 | M9: 女 | N9: 学过一点 | O9: 否 | P9: 学过一点，中文交流没问题 | Q9: 中文 | R9: 学生发音标准，朗读较流畅，识字量不错，建议从二上三四单元开始学起 | S9: 周虹 9:40 7-1 | T9: 家长介绍 | U9: 3 | V9: 王可 陈彦熹妈妈推荐
B10: 44013 | C10: 美国 | E10: 12 | G10: yinxianglan0521 | I10: 林文慧 | J10: =TRIM(I10) -> 林文慧 | K10: =IFERROR(VLOOKUP(J10,Sheet1!A:B,2,FALSE),"zhaobudao") -> zhaobudao | L10: 6岁半 | M10: 女 | N10: 否 | O10: 是 | P10: 家长说孩子基础很差 | Q10: 中文 | R10: 建议和哥哥一起上拼音课，表达不如哥哥，建议双语老师。 | S10: 张璐 7:40 7.1 | T10: 微信 | U10: 1 | V10: 胡兰
B11: 44013 | C11: 美国 | E11: 12 | G11: yinxianglan0521 | I11: 林文景 | J11: =TRIM(I11) -> 林文景 | K11: =IFERROR(VLOOKUP(J11,Sheet1!A:B,2,FALSE),"zhaobudao") -> zhaobudao | L11: 8岁半 | M11: 男 | N11: 否 | O11: 是 | P11: 中文基础比较差 | Q11: 中文 | R11: 建议从拼音课开始，非常活泼，中文理解表达一般。 | S11: 张璐 7:00 7.1 | T11: 微信 | U11: 1 | V11: 胡东东
B12: 44013 | C12: 美国 | D12: 西部 | E12: 15 | F12: 吴琳 | G12: k2d23p | I12: 小恩 | J12: =TRIM(I12) -> 小恩 | K12: =IFERROR(VLOOKUP(J12,Sheet1!A:B,2,FALSE),"zhaobudao") -> 是 | L12: 7岁 | N12: 没有 | O12: 否 | P12: 学过一册双双教材，认识一些字，不太擅长说句子，家里说中文，孩子听得懂。笔画也学了，想学拼音 | Q12: 中文 | R12: 从拼音课开始，理解表达一般。 | S12: 张璐；9:00；7.1 | T12: 介绍 | U12: 3 | V12: 毛益丹
B13: 44013 | C13: 美国 | D13: 纽约 | E13: 12 | F13: Rebecca | G13: aliceli520 | I13: 林以昊 | J13: =TRIM(I13) -> 林以昊 | K13: =IFERROR(VLOOKUP(J13,Sheet1!A:B,2,FALSE),"zhaobudao") -> zhaobudao | L13: 6 | M13: 男 | N13: 否 | O13: 否 | P13: 零基础，拼音aoe开始学 | Q13: 中文 | T13: 家长介绍 | U13: 2 | V13: 刘巧芹 乐芯妈妈介绍
B14: 44013 | C14: 美国 | D14: 纽约 | E14: 12 | F14: Liang | G14: chenxiaoxi_yu | I14: 陈睿萱 | J14: =TRIM(I14) -> 陈睿萱 | K14: =IFERROR(VLOOKUP(J14,Sheet1!A:B,2,FALSE),"zhaobudao") -> 是 | L14: 6 | M14: 女 | N14: 否 | O14: 是 | P14: 零基础，拼音aoe开始学 | Q14: 中文 | T14: 家长介绍 | U14: 2 | V14: 刘巧芹 乐芯妈妈介绍
B15: 44013 | C15: 美国 | D15: 纽约 | E15: 12 | F15: 晓霞 | G15: li2241984 | I15: 朱紫晴 | J15: =TRIM(I15) -> 朱紫晴 | K15: =IFERROR(VLOOKUP(J15,Sheet1!A:B,2,FALSE),"zhaobudao") -> 是 | L15: 快七岁 | M15: 女 | N15: 否 | O15: 否 | P15: 零基础，拼音aoe开始学 | Q15: 中文 | T15: 家长介绍 | U15: 2 | V15: 刘巧芹 乐芯妈妈介绍
B16: 44013 | C16: 美国 | D16: 纽约 | E16: 12 | F16: MaY。海外购 | G16: candy60701332 | I16: 林卡卡 | J16: =TRIM(I16) -> 林卡卡 | K16: =IFERROR(VLOOKUP(J16,Sheet1!A:B,2,FALSE),"zhaobudao") -> 是 | L16: 8 | M16: 男 | N16: 否 | O16: 否 | P16: 零基础，二月测试过，现在过来上一下正式课，在家中文交流 | Q16: 中文 | T16: 陈珊珊妈妈介绍 | U16: 2 | V16: 高翱翔
B17: 44013 | C17: 美国 | E17: 12 | G17: 冰雨 | I17: 子原 | J17: =TRIM(I17) -> 子原 | K17: =IFERROR(VLOOKUP(J17,Sheet1!A:B,2,FALSE),"zhaobudao") -> zhaobudao | L17: 8岁 | M17: 男 | N17: 学会 | O17: 否 | P17: 孩子学会拼音但是需要巩固。现在二年级 | Q17: 中文 | T17: 微信 | U17: 3 | V17: 张霞
B18: 44014 | C18: 美东 | E18: 12 | F18: Michelle🏘64 | G18: lz1314520 | I18: jia xin | J18: =TRIM(I18) -> jia xin | K18: =IFERROR(VLOOKUP(J18,Sheet1!A:B,2,FALSE),"zhaobudao") -> zhaobudao | L18: 13 | N18: 学过一点 | O18: 否 | P18: 中文交流没问题，以前学过中文 | Q18: 中文 | R18: 朗读不流畅，学过拼音，但是有遗忘，建议从gkh后面复韵母前面开始学 | S18: 周虹 7:40 7-2 | T18: 微信 | U18: 3 | V18: 翁珊珊
B19: 44014 | C19: 美东 | E19: 12 | F19: Michelle🏘65 | G19: lz1314521 | I19: jia ye | J19: =TRIM(I19) -> jia ye | K19: =IFERROR(VLOOKUP(J19,Sheet1!A:B,2,FALSE),"zhaobudao") -> zhaobudao | L19: 11 | N19: 否 | O19: 否 | P19: 中文交流没问题 | Q19: 中文 | R19: 朗读不流畅，学过拼音，但是有遗忘，弟弟的基础比哥哥差，aoe有混淆，四个声调不会读，建议从aoe开始学。 | S19: 周虹 8：20 7-2 | T19: 微信 | U19: 3 | V19: 翁珊珊
B20: 44014 | C20: 美东 | E20: 12 | F20: Michelle🏘66 | G20: lz1314522 | I20: jia yu | J20: =TRIM(I20) -> jia yu | K20: =IFERROR(VLOOKUP(J20,Sheet1!A:B,2,FALSE),"zhaobudao") -> zhaobudao | L20: 10 | N20: 否 | O20: 否 | P20: 中文交流没问题 | Q20: 中文 | R20: 建议从zcs开始，中文理解表达可以，很活泼开朗。 | S20: 张璐 8：20 7.2 | T20: 微信 | U20: 3 | V20: 翁珊珊
B21: 44014 | C21: 澳洲 | E21: 2 | F21: 谢 | G21: angelz2015 | I21: 谢家佑 | J21: =TRIM(I21) -> 谢家佑 | K21: =IFERROR(VLOOKUP(J21,Sheet1!A:B,2,FALSE),"zhaobudao") -> zhaobudao | L21: 8 | M21: 男 | N21: 否 | O21: 否 | P21: 可以交流 | Q21: 中文 | T21: 介绍 | U21: 3 | V21: 张文红
B22: 44014 | C22: 美国 | D22: 西部 | E22: 15 | F22: 兰 | G22: lan9176604297 | I22: 林水 | J22: =TRIM(I22) -> 林水 | K22: =IFERROR(VLOOKUP(J22,Sheet1!A:B,2,FALSE),"zhaobudao") -> 是 | L22: 13岁 | M22: 男 | O22: 否 | P22: 这是12岁的男孩,平常在家说中文,平常可以用中文交流,可是不懂看和写,或者看得不多 | Q22: 中文 | R22: 零基础，完全不会，aoe开始学习，三声发音不准确 | S22: 刘钰兰；7:40；7.2 | T22: 家长介绍 | V22: 任宏印
B23: 44014 | C23: 澳洲 | E23: 2 | F23: Chloe Mi | G23: chloe4671 | I23: 米嘟 | J23: =TRIM(I23) -> 米嘟 | K23: =IFERROR(VLOOKUP(J23,Sheet1!A:B,2,FALSE),"zhaobudao") -> zhaobudao | L23: 8 | M23: 男 | N23: 是 | O23: 否 | P23: 哥哥学过拼音，中文交流 | Q23: 中文 | R23: 建议从iu ui开始，有学过但是忘了一部分，后面的拼音有的会有的不会。或者从一上秋天开始学。理解表达可以，读课文时发音不标准。有点害羞 | S23: 张璐 13:30 7.2 | T23: 微信 | U23: 3 | V23: 杨斌
B24: 44014 | C24: 澳洲 | E24: 2 | F24: Chloe Mi | G24: chloe4671 | I24: 米哒 | J24: =TRIM(I24) -> 米哒 | K24: =IFERROR(VLOOKUP(J24,Sheet1!A:B,2,FALSE),"zhaobudao") -> zhaobudao | L24: 6 | M24: 女 | N24: 否 | O24: 否 | P24: 零基础，中文交流 | Q24: 中文 | R24: 建议从拼音开始学起，识字量大，理解表达表达能力好。比较活泼。 | S24: 张璐 14:10 7.2 | T24: 微信 | U24: 3 | V24: 杨斌
B25: 44014 | C25: 美国 | D25: 加州 | E25: -15 | F25: cathrny | G25: cathrnygao | I25: 赵宏康 | J25: =TRIM(I25) -> 赵宏康 | K25: =IFERROR(VLOOKUP(J25,Sheet1!A:B,2,FALSE),"zhaobudao") -> zhaobudao | L25: 10 | M25: 男 | N25: 否 | O25: 是 | P25: 零基础，最好有双语老师，喜欢数学 | Q25: 中文 | R25: 建议从拼音开始，从aoe或者ie ei开始，理解表达都可以，有一点点害羞。 | S25: 张璐 9:40 7.2 | T25: 家长介绍 | U25: 0 | V25: 王晨 逸凌妈咪介绍
B26: 44014 | C26: 美西 | E26: 15 | F26: 胡俊洛杉矶 | G26: hujun107904875 | I26: Shawn | J26: =TRIM(I26) -> Shawn | K26: =IFERROR(VLOOKUP(J26,Sheet1!A:B,2,FALSE),"zhaobudao") -> zhaobudao | L26: 8 | M26: 男 | N26: 学过 | O26: 否 | P26: 一直在学中文，估计相当于国内一年级的水平 | Q26: 中文 | R26: 建议从一下3 4单元开始学，表达理解都可以，家长想要app可以让学生自己去看作业和课程回顾。 | S26: 张璐 11:00 7.2 | T26: 微信 | U26: 3 | V26: 程蕾
B27: 44014 | C27: 美国 | D27: 东部 | E27: 12 | F27: cuizh | G27: jiangcuizh | I27: 陈净灵 | J27: =TRIM(I27) -> 陈净灵 | K27: =IFERROR(VLOOKUP(J27,Sheet1!A:B,2,FALSE),"zhaobudao") -> 是 | L27: 8 | M27: 女 | N27: 否 | O27: 最好 | P27: 只会一点点，拼音不会，喜欢跳舞 | Q27: 中文 | R27: 孩子每周一节课学过2年中午，有中文基础，会写会认简单的汉字。基础汉语交流都能听懂，可以说简单的词。第一次上课，有一点害羞，后面可以跟上节奏，积极回答老师问题。建议从一年级上册拼音开始学起。 | S27: 刘依琳 21:30 7.2 | T27: 家长介绍 | U27: 2 | V27: 平金军 林宇妈妈介绍 | Z27: 1 | AA27: 1 | AB27: 1 | AC27: 56/课 | AD27: 一对四65 | AE27: 515 | AF27: 7.6日缴费
B28: 44014 | C28: 西班牙 | E28: 6 | F28: 张晶晶Serena | G28: Z139017555 | I28: 潘昊泉 | J28: =TRIM(I28) -> 潘昊泉 | K28: =IFERROR(VLOOKUP(J28,Sheet1!A:B,2,FALSE),"zhaobudao") -> 是 | L28: 8 | M28: 男 | N28: 否 | O28: 否 | P28: 中文字认识300多个 | Q28: 中文 | T28: 微信 | U28: 1 | V28: 何家昌
B29: 44014 | C29: 加拿大 | E29: 15 | F29: 杨柳Willow | G29: Davidestelle | I29: 奕赫 | J29: =TRIM(I29) -> 奕赫 | K29: =IFERROR(VLOOKUP(J29,Sheet1!A:B,2,FALSE),"zhaobudao") -> zhaobudao | L29: 7 | M29: 男 | N29: 有 | O29: 否 | P29: 一年级的课自学完了 | Q29: 中文 | R29: 二上第一单元，发音标准，思路清晰 | S29: 刘钰兰；9:40；7.3 | T29: 家长介绍 | V29: LAWERNCE1妈妈介绍
B30: 44015 | C30: 加拿大 | E30: 15 | F30: Nancy 佳 | G30: nancy-kejia | I30: Nina | J30: =TRIM(I30) -> Nina | K30: =IFERROR(VLOOKUP(J30,Sheet1!A:B,2,FALSE),"zhaobudao") -> zhaobudao | L30: 4 | M30: 女 | N30: 否 | O30: 否 | P30: 零基础 | Q30: 启蒙 | T30: 扫码 | U30: 白 | V30: 俞酉兰
B31: 44015 | C31: 加拿大 | E31: 15 | F31: tingting | G31: wxid_9207ly4bzg2s22 | I31: Lillian | J31: =TRIM(I31) -> Lillian | K31: =IFERROR(VLOOKUP(J31,Sheet1!A:B,2,FALSE),"zhaobudao") -> zhaobudao | L31: 4.7 | M31: 女 | N31: 否 | O31: 是 | P31: 会说广东话和英文，不会说中文 | Q31: 启蒙 | T31: 扫码 | U31: 白 | V31: 俞酉兰
B32: 44015 | C32: 美东 | E32: 12 | F32: Mickey | G32: HUA812985471 | I32: 铭烁 | J32: =TRIM(I32) -> 铭烁 | K32: =IFERROR(VLOOKUP(J32,Sheet1!A:B,2,FALSE),"zhaobudao") -> zhaobudao | L32: 7 | M32: 男 | N32: 否 | O32: 否 | P32: 在国内上幼儿园中班，在家说中文 | Q32: 中文 | R32: 中文沟通流畅，零基础，建议从拼音开始学。 | S32: 周虹 7:40 7.3 | T32: 微信 | U32: 3 | V32: 杨斌
B33: 44015 | C33: 美国 | D33: 纽约 | E33: -12 | F33: 幸福来临 | G33: xiu123m | I33: 陈煾则 | J33: =TRIM(I33) -> 陈煾则 | K33: =IFERROR(VLOOKUP(J33,Sheet1!A:B,2,FALSE),"zhaobudao") -> zhaobudao | L33: 9 | M33: 男 | N33: 一点 | O33: 否 | P33: 会一点拼音 | Q33: 中文 | R33: 中文沟通流畅，零基础，建议从拼音开始学。 | S33: 周虹 8:10 7.3 | T33: 微信 | U33: 0 | V33: 王晨
B34: 44015 | C34: 美东 | E34: 12 | F34: Venus@Compass 917.88 | G34: lemontree859 | I34: 黄梓瑄 | J34: =TRIM(I34) -> 黄梓瑄 | K34: =IFERROR(VLOOKUP(J34,Sheet1!A:B,2,FALSE),"zhaobudao") -> zhaobudao | L34: 12 | N34: 否 | O34: 否 | P34: 中文交流 | Q34: 中文 | R34: 两姐妹程度一般，会拼音，中文能听懂一些，词汇量识字量很少 ，建议从一上四单元开始上课 | S34: 周虹 8:20 7.3 | T34: 微信 | U34: 3 | V34: 翁珊珊 | Z34: 1 | AA34: 1 | AB34: 1 | AC34: 96/课 | AD34: 一对二18 | AE34: 492.8 | AF34: 7.8日缴费
B35: 44015 | C35: 美东 | E35: 12 | F35: Venus@Compass 917.88 | G35: lemontree859 | I35: 黄奕瑄 | J35: =TRIM(I35) -> 黄奕瑄 | K35: =IFERROR(VLOOKUP(J35,Sheet1!A:B,2,FALSE),"zhaobudao") -> zhaobudao | L35: 10 | N35: 否 | O35: 否 | P35: 中文交流 | Q35: 中文 | R35: 两姐妹程度一般，会拼音，中文能听懂一些，词汇量识字量很少 ，建议从一上四单元开始上课 | S35: 周虹 8:20 7.3 | T35: 微信 | U35: 3 | V35: 翁珊珊 | Z35: 1 | AA35: 1 | AB35: 1 | AC35: 96/课 | AD35: 一对二18 | AE35: 492.8 | AF35: 7.8日缴费
B36: 44015 | C36: 美国 | E36: 15 | F36: Helen | G36: wanglin880120 | I36: 王桠楠 | J36: =TRIM(I36) -> 王桠楠 | K36: =IFERROR(VLOOKUP(J36,Sheet1!A:B,2,FALSE),"zhaobudao") -> zhaobudao | L36: 6 | M36: 女 | N36: 无 | O36: 否 | P36: 在家说中文，零基础，没有学过中文，家里给她念过故事书，有点不太理解。 | Q36: 中文 | R36: 比较害羞，不怎么说话，家里都是说中文，能用中文沟通，但是不是很能理解，零基础，建议从拼音开始学起。 | S36: 包海燕 9:20 7.3 | T36: 微信 | U36: 2 | V36: 丁阮琪
B37: 44015 | C37: 美国 | E37: 15 | G37: rich858598 | I37: 蔡昊泽 | J37: =TRIM(I37) -> 蔡昊泽 | K37: =IFERROR(VLOOKUP(J37,Sheet1!A:B,2,FALSE),"zhaobudao") -> zhaobudao | L37: 8 | M37: 男 | N37: 是 | O37: 否 | P37: 上过中文课，有点基础，但是对中文课兴趣不大 | Q37: 中文 | R37: 零基础，十分不配合，上课要妈妈在旁边，不喜欢说，全程不在状态 | S37: 刘钰兰；9:00；7.3 | T37: 家长介绍 | U37: 1 | V37: 邢国栋 锦鹏妈妈介绍
B38: 44015 | C38: 美中 | E38: 13 | F38: bin | G38: binr2005 | I38: Daisy yu | J38: =TRIM(I38) -> Daisy yu | K38: =IFERROR(VLOOKUP(J38,Sheet1!A:B,2,FALSE),"zhaobudao") -> zhaobudao | L38: 6岁 | M38: 女 | N38: 有 | O38: 否 | P38: 一年级的水平，可以交流 | Q38: 中文 | R38: 建议从一上第四单元秋天开始，可以拼读有些慢，理解和表达一般。比较活泼。 | S38: 张璐 7:00 7.3 | T38: 微信 | U38: 3 | V38: 程蕾 | Z38: 1 | AA38: 1 | AB38: 1 | AC38: 53/课 | AD38: 一对四130 | AE38: 6890 | AF38: 7.7日开始每天1000，转一礼拜
B39: 44015 | C39: 美东 | E39: 12 | F39: 碧兰 | G39: wxidtbslgh9xr412 | I39: Jinyi jing | J39: =TRIM(I39) -> Jinyi jing | K39: =IFERROR(VLOOKUP(J39,Sheet1!A:B,2,FALSE),"zhaobudao") -> zhaobudao | L39: 9 | M39: 女 | N39: 学过 | O39: 否 | P39: 当地二年级的水平 | Q39: 中文 | R39: 大姐，二姐，三姐可以一起从一上第四单元开始，弟弟要从拼音开始学起。拼读有点慢，理解和表达一般，认字量一般，很活泼。 | S39: 张璐 8:20 7.3 | T39: 微信 | U39: 3 | V39: 程蕾
B40: 44015 | C40: 美国 | D40: 纽约 | E40: 12 | F40: 建武 | G40: a9176827476 | I40: 高鹏 | J40: =TRIM(I40) -> 高鹏 | K40: =IFERROR(VLOOKUP(J40,Sheet1!A:B,2,FALSE),"zhaobudao") -> zhaobudao | L40: 12 | M40: 男 | N40: 是 | O40: 否 | P40: 家长说孩子学习过拼音，不过知道现在还记不记得，平时在家用中文交流 | Q40: 中文 | R40: 建议从一上第七单元开始，小朋友非常爱学习，自己会从课文里找生字，理解表达一般。 | S40: 张璐 9:00 7.3 | T40: 家长介绍 | U40: 2 | V40: 高翱翔 陈城杰妈妈介绍
...

Sheet Sheet1
A1: 叶文浩1 | B1: 是
A2: 叶鋆睿 | B2: 是
A3: 何子恒 | B3: 是
A4: 吉娜 | B4: 是
A5: 宋崇铭 | B5: 是
A6: 吴楚惟 | B6: 是
A7: 吕泽歆 | B7: 是
A8: 小恩 | B8: 是
A9: 吴炳铨 | B9: 是
A10: 林泽锴1 | B10: 是
A11: 胡昊阳 | B11: 是
A12: 胡昊阳 | B12: 是
... A250: 张皓轩 | B250: 是

Sheet 2020.6
A1: 2020.6月 新生接待试读表 业务员：测+读 老师：试读两次
A2: 序号 | B2: 测试时间 | C2: 国家 | D2: 城市 | E2: 时差 | F2: 家长微信名 | G2: 家长微信 | H2: 电话号码 | I2: 学生姓名 | J2: 年龄 | K2: 性别 | L2: 有没有学过拼音 | M2: 是否需要双语老师 | N2: 家长自述程度及学习需求 | O2: 学习课程 | P2: 测试结果 | Q2: 排课安排 | R2: 来源 电话 微信 报第二门课 学生兄妹 家长介绍（哪个家长写到CC一栏 和你的名字一起） | S2: 组别 | T2: 业务员 | U2: 试读日期 | V2: 试课安排 | W2: 排课校区 | X2: 是否在读 | Y2: 是否缴费 | Z2: 失败原因 | AA2: 课程单价 | AB2: 折扣 | AC2: 实收 | AD2: 首次收费时间
A3: 1 | B3: 6.1 | C3: 美国 | D3: 东部 | E3: 12 | F3: Stella Hang | G3: hualeihang | I3: 蔡乐全 | J3: 13 | K3: 男 | L3: 学过 | M3: 否 | N3: 中文交流，马立平六年级 | O3: 中文 | P3: 学生有学过中文，识字量不错，但是有多遗忘的，建议从一下三四单元开始学习 | Q3: 周虹 7:40 6.1 | R3: 微信 | S3: 3 | T3: 杨斌 | Z3: 家长觉得价格贵，失联
A4: 2 | B4: 6.1 | C4: 美国 | D4: 亚特兰大 | E4: -12 | F4: 涂华 | G4: tuhua_us | I4: 轩辕瀚 | J4: 9 | K4: 女 | L4: 大致 | M4: 否 | N4: 二年级或三年级，500识字量 | O4: 中文 | Q4: 言智02 22:05 6.1 | R4: 家长介绍 | S4: 0 | T4: 王晨 诗瑶妈咪介绍 | V4: 兼 | Z4: 一起参加试课，指名试黄莺老师的课，但是家长希望上课内容是根据当地学习的中文知识帮助孩子加强辅导，在和老师沟通时不是很开心，黄老师也因为时间因素推脱，不愿意接课。
A5: 3 | B5: 6.1 | C5: 美国 | D5: 亚特兰大 | E5: -12 | F5: tracy | G5: tracyyiwenyan | I5: 杨乐乐 | J5: 8 | K5: 女 | L5: 大致 | M5: 否 | N5: 二年级或三年级，识字量100+没有统计计算过 | O5: 中文 | Q5: 言智02 22:05 6.1 | R5: 家长介绍 | S5: 0 | T5: 王晨 诗瑶妈咪介绍 | V5: 兼 | Z5: 一起参加试课，指名试黄莺老师的课，但是家长希望上课内容是根据当地学习的中文知识帮助孩子加强辅导，在和老师沟通时不是很开心，黄老师也因为时间因素推脱，不愿意接课。
A6: 4 | B6: 6.1 | C6: 美国 | D6: 西部 | E6: 15 | F6: Lingo | G6: LingoZheng | I6: 朱天胤 | J6: 7 | K6: 男 | L6: 学过 | M6: 否 | N6: 拼音已经会了初步学了一年级的中文字 | O6: 中文 | P6: 建议一上第四单元《小小的船》开始，测的秋天，生字部分不认识，很好学，跟老师互动很好，主动学习 | Q6: 黄礼云；8:20；6.1 | R6: 家长介绍 | S6: 3 | T6: 杨斌 张晗妈妈介绍 | Z6: 有个夏令营七月份结束到时再排课
A7: 5 | B7: 6.1 | C7: 美国 | D7: 西部 | E7: 15 | F7: G A 李子 | G7: Mara311 | I7: 吕艾黎 | J7: 7 | K7: 女 | L7: 学过 | M7: 否 | N7: 中文交流拼音没问题 | O7: 中文 | P7: 学生正在国外上一下第二单元第四课《四个太阳》，建议接着往下学，学生程度很好，偶尔会记混字，比如块和快，组词造句都很ok，接受能力强 | Q7: 黄礼云；7:40；6.1 | R7: 家长介绍 | S7: 3 | T7: 杨斌 朱天胤妈妈介绍 | Z7: 有个夏令营七月份结束到时再排课
A8: 6 | B8: 6.1 | C8: 新西兰 | D8: 奥克兰 | E8: 4 | F8: iudi | G8: ludizhangatnz | I8: 张之沐 | J8: 8 | K8: 男 | L8: 会 | M8: 否 | N8: 在学国内人教版语文二年级，有点不爱学习 | O8: 中文 | P8: 学生正在上二上第四单元，下一课学《黄山奇石》，建议接着往下上，学生程度还可以，写字笔画不错 | Q8: 黄礼云；13：00；6.1 | R8: 微信 | S8: 2 | T8: 泮攀
A9: 7 | B9: 6.1 | C9: 美国 | D9: 西部 | E9: 15 | F9: Amelia | G9: Amelia130920 | I9: Angela | J9: 5.5 | K9: 女 | L9: 否 | M9: 否 | N9: 中文交流，孩子想学 | O9: 启蒙中文 | Q9: 卢爽7：00 6.1 | R9: 微信 | S9: 3 | T9: 杨斌 | Z9: 家庭矛盾，孩子的学习不归妈妈管向她要爸爸联系方式也不愿意给
A10: 8 | B10: 6.1 | C10: 美国 | D10: 中部 | E10: 13 | F10: 辛运昕 | G10: x117653201 | H10: 6469799899 | I10: 王紫萱 | J10: 6 | K10: 女 | L10: 没有 | M10: 否 | N10: 会说，不怎么会写，会简单的六个韵母 | O10: 启蒙中文 | Q10: 卢爽8:20 6.1 | R10: 微信 | S10: 3 | T10: 程蕾 | Z10: 价格高
A11: 9 | B11: 6.1 | C11: 美国 | D11: 东部 | E11: 12 | F11: 玲 | G11: NJHLing | I11: 黄家睿 | J11: 5 | K11: 女 | L11: 否 | M11: 否 | N11: 在家用中文交流，不识字，家长希望能提高她的听说能力，增大理解，和词汇，之后才识字 | O11: 启蒙中文 | P11: 会说中文，刚开始比较腼腆，孩子活泼可爱，上的是测试ppt，家长说不想让孩子识字，先锻炼她的表达能力和听说能力，建议上启蒙课 | Q11: 卢爽6:00 6.1 | R11: 微信 | S11: 3 | T11: 翁珊珊
A12: 10 | B12: 6.1 | C12: 美西 | D12: 旧金山 | E12: 15 | F12: 夜猫不睡 | G12: lixinglisa | H12: +1 5203018387 | I12: 麦麦 | J12: 4岁半 | K12: 女 | L12: 否 | M12: 否 | N12: 中文口语流利，识字量250-300左右，能读短文。小孩子很不喜欢网课这种形式，完全没接触过拼音，偏旁部首知道一些 | O12: 启蒙中文 | Q12: 卢爽10:30 6.1 | R12: 微信 | S12: 3 | T12: 毛益丹 | Z12: 已经两次试课了，老师没调整好难度，所以教的小孩子都会，家长觉得没必要，和自己在家里教的差不多，并且家长不想学拼音的，所有没办法推小学语文
A13: 11 | B13: 6.1 | C13: 澳洲 | D13: 悉尼 | E13: 2 | F13: Evonne | G13: Evonne912266755 | H13: 610430808878 | I13: 何一依 | J13: 2.5岁 | K13: 女 | L13: 否 | M13: 否 | N13: 交流可以，吐字不清楚 | O13: 启蒙中文 | Q13: 孙恺悦18：30 6.1 | R13: 微信 | S13: 3 | T13: 张文红
A14: 12 | B14: 6.2 | C14: 美西 | D14: 圣何塞 | E14: 15 | F14: Lorraine Lu | G14: wwayway | I14: 陆时安 | J14: 快7岁 | K14: 男 | L14: 学过 | M14: 否 | N14: 学过拼音和一些中文字，和悟空识字一部分 | O14: 中文 | P14: 建议一下二、三单元开始，认字较多，词汇不理解。说话比较慢，会回应老师，不热情。 | Q14: 刘钰兰；7:00；6.2 Chineseonline O 7:00 6.4 | R14: 微信 | S14: 3 | T14: 毛益丹 | V14: 白 | W14: 白 | X14: 1 | Y14: 1 | Z14: 1 | AA14: 56/课 | AB14: 一对四65课时 | AC14: 3640 | AD14: 6.4日缴费
A15: 13 | B15: 6.2 | C15: 美西 | D15: 旧金山 | E15: 15 | F15: miaoyan | G15: yan102713 | I15: 苏智恒 | J15: 快7岁 | L15: 学过 | M15: 否 | N15: 之前在唐人街上了一个学期中文，学过拼音，但不是很会，不反感学拼音 | O15: 中文 | P15: 建议aoe开始，猫狗小动物这些用中文都会讲，在家说粤语，爱说话。 | Q15: 刘钰兰；8:20；6.2 | R15: 微信 | S15: 3 | T15: 毛益丹 | Z15: 去其他机构了，小孩子更喜欢那个机构的课程
A16: 14 | B16: 6.2 | C16: 美国 | D16: 东部 | E16: 12 | F16: annie | G16: g9810104 | I16: 林进轩 | J16: 11 | K16: 男 | L16: 学过差不多忘了 | M16: 否 | N16: 二年级水平，会阅读水浒传三国演义。拼音学过但是差不多都忘了 | O16: 中文 | P16: 建议先学拼音，然后跟着三年级学习，上下册都可以，识字量丰富，认学度高 | Q16: 刘钰兰；9:00；6.2 Chineseonline T10 7:30 6.3 | R16: 微信 | S16: 3 | T16: 展旺 | V16: 兼 | W16: 兼 | X16: 1 | Y16: 1 | Z16: 1 | AA16: 116/课 | AB16: 一对一65课时 | AC16: 7540 | AD16: 6.3日缴费
A17: 15 | B17: 6.2 | C17: 美国 | E17: 12 | G17: Yhmay23 | I17: 黄博腾 | J17: 11岁 | K17: 男 | L17: 会一点 | M17: 否 | N17: 口语会一点简单的能听懂 | O17: 中文 | P17: 基本零基础，很多日常词不太会说，从你我他开始，测试学了天地人，学过拼音，一半记得一半不记得 | Q17: 黄礼云；7:40；6.2 言智16王秋平 6.6 周一周四周六7：50～8：20 | R17: 电话 | S17: 5 | T17: 胡东东 | V17: 兼 | X17: 1 | Y17: 1 | Z17: 1 | AA17: 96/课 | AB17: 一对二65+5课时 | AC17: 6240 | AD17: 6.3日缴费
A18: 16 | B18: 6.2 | C18: 美国 | D18: 纽约 | E18: 2 | F18: Cherie💕美国代购&ABM | G18: jinyun-530 | I18: 吴星桦 | J18: 10 | K18: 男 | L18: 有，不过忘记了 | M18: 否 | N18: 孩子之前学习过拼音，不过应该早就忘记了，认识二百子左右。喜欢画画 | O18: 中文 | P18: 阅读能力很强，识字量大，拼音不是很熟练，要复习一下复韵母和前后鼻韵母，建议从一下二单元开始 | Q18: 黄礼云；8：20；6.2 | R18: 家长介绍 | S18: 2 | T18: 高翱翔 彭梓瑜妈妈介绍 | Z18: 搬家最近没时间，说到低还是嫌弃价格高
A19: 17 | B19: 6.2 | C19: 美国 | D19: 西部 | E19: 15 | F19: bing gao | G19: binggaorw | I19: 高泊宇 | J19: 11 | K19: 男 | L19: 学过 | M19: 否 | N19: 在家讲中文，听说可以，学过一些 | O19: 中文 | P19: 一下第三单元，学生学了五年，但测下来感觉没有五年的程度，声调会搞混 | Q19: 黄礼云；10:20；6.2 Chineseonline H 11:40 6.4 | R19: 微信 | S19: 3 | T19: 王可 | V19: 白 | W19: 白 | X19: 1 | Y19: 1 | Z19: 1 | AA19: 56/课 | AB19: 一对四65课时 | AC19: 3240 | AD19: 6.5日缴费 | AE19: 四人团优惠400
A20: 18 | B20: 6.2 | C20: 美国 | D20: 旧金山 | E20: 15 | G20: helenali999 | I20: 潘笑然 | J20: 12岁 | K20: 女 | L20: 没有 | M20: 否 | N20: 阅读可以看中文小说，写的程度不高。口语可以沟通 | O20: 中文 | P20: 学生喜欢阅读，没有系统学过拼音，声母会读，韵母不会，建议从一上第三单元ai ei ui开始，学完第三单元后，直接跳到四年级下册的班级里，她的认字和听说能力达到了四年级水平，写字可能没那么好，但也还可以 | Q20: 黄礼云；11:30；6.2 | R20: 微信介绍 | S20: 5 | T20: 邢国栋 | X20: 1 | Y20: 1 | Z20: 1 | AA20: 59/课 | AB20: 一对四22+1课时 | AC20: 1298 | AD20: 6.15日缴费
A21: 19 | B21: 6.2 | C21: 美国 | D21: 东部 | E21: 12 | F21: 陈意（纽约人寿） | G21: yvonnechen13 | I21: 陈敏怡 | J21: 9岁 | K21: 女 | L21: 有接触过 | M21: 否 | N21: 口语很好，会写一些字，拼音也有接触过 | O21: 中文 | P21: 拼音学起，比较认真，文静。认字量大。 | Q21: 杨静；7:40；6.2 | R21: 微信 | S21: 3 | T21: 翁珊珊
A22: 20 | B22: 6.2 | C22: 美国 | D22: 西部 | E22: 15 | F22: 然（谭老师 | G22: TR3515 | I22: 储衍 | J22: 9岁 | L22: 学过 | M22: 否 | N22: 学过拼音，但记不住 | O22: 中文 | P22: 建议拼音学起，学生有点大舌头，妈妈说舌头有点问题，老师慢慢讲解可以理解，学生话比较多，过于活泼坐不住。 | Q22: 杨静，9:00；6.2 | R22: 微信 | S22: 3 | T22: 毛益丹 | Y22: 家长和我自己都觉得老师上课效果不好
A23: 21 | B23: 6.2 | C23: 美国 | D23: 西部 | E23: 15 | F23: bing gao | G23: binggaorw | I23: 高泊翔 | J23: 9 | K23: 男 | L23: 学过 | M23: 否 | N23: 在家讲中文，听说可以，比哥哥稍弱一些 | O23: 中文 | P23: 建议一上第六七单元开始学起，学的能力比较好，课文一些词语不理解，不太会造句 | Q23: 杨静；10:20；6.2 Chineseonline H 11:40 6.4 | R23: 微信 | S23: 3 | T23: 王可 | V23: 白 | W23: 白 | X23: 1 | Y23: 1 | Z23: 1 | AA23: 56/课 | AB23: 一对四65课时 | AC23: 3240 | AD23: 6.5日缴费 | AE23: 四人团优惠400
A24: 22 | B24: 6.2 | C24: 美国 | D24: 西部 | E24: 15 | F24: SaSa | G24: SaSa77343 | I24: Abby | J24: 8 | K24: 女 | L24: 学过一点 | M24: 否 | N24: 学过一点拼音，在当地学到一二年级，可以普通话交流 | O24: 中文 | P24: 一下第二三单元开始学起，学生过度害羞不开摄像头，程度很好 | Q24: 杨静；9:40；6.2 | R24: 微信 | S24: 3 | T24: 王可
A25: 23 | B25: 6.2 | C25: 美国 | D25: 东部 | E25: 12 | F25: joy | G25: joyce927956 | I25: 江乃全 | J25: 7 | K25: 男 | L25: 否 | M25: 否 | N25: 识字量50，口语程度只有幼儿园，爱好唱歌 | O25: 中文 | P25: 建议拼音学起，比较认真，不会组词，认字量在50个内 | Q25: 杨静；7;00;6.2 言智38 7：00 6-17 | R25: 推荐 | S25: 2 | T25: 平金军 | U25: 6.17 | V25: 兼 | W25: 兼 | X25: 1 | Y25: 1 | Z25: 1 | AA25: 56/课 | AB25: 一对四65 | AC25: 454 | AD25: 6.11日缴费
A26: 24 | B26: 6.2 | C26: 澳洲 | E26: 2 | F26: 449977992 | G26: 三只小猪 | H26: david449977992 | I26: 潼潼 | J26: 9 | K26: 女 | L26: 普通的会一些 | M26: 否 | N26: 识字两到三百，拼音会一些，喜欢读英文小说，希望严格一点的老师 | O26: 中文 | Q26: 黄礼云；15:00；6.2 | R26: 微信 | S26: 2 | T26: 罗焱
A27: 25 | B27: 6.2 | C27: 加拿大 | D27: 温哥华 | E27: 15 | F27: 钟博 | G27: 17788853261 | H27: +1 7788853261 | I27: 钟宝乐 | J27: 14 | K27: 男 | L27: 是 | M27: 否 | N27: 基础很差，能简单的用中文交流 | O27: 启蒙中文 | Q27: 孙婷婷8:30 6.2 | R27: 微信 | S27: 5 | T27: 赵峰 | Z27: 家长还是有意向让孩子学习中文的，但是对于HSK不是太了解，一节课180元价格嫌贵
A28: 26 | B28: 6.3 | C28: 美国 | H28: +86 18913946146 | I28: 豆宝 | J28: 4.5 | L28: 否 | M28: 否 | N28: 正常沟通 | O28: 启蒙中文 | Q28: 庄雪22:00 6.2 | R28: 微信 | S28: 5 | T28: 李波 | Z28: 去美术宝了 小朋友喜欢那边
A29: 27 | B29: 6.3 | C29: 加拿大 | E29: 12 | G29: Gillian | H29: zhuqu003 | I29: 马榆果 | J29: 4 | K29: 女 | L29: 否 | M29: 否 | N29: 在家家长自己有教过，日常交流没问题 | O29: 启蒙 | Q29: 李晓杰23:00 6.2 | R29: 微信 | S29: 1 | T29: 何家昌 | V29: 兼 | W29: 兼 | X29: 1 | Y29: 1 | Z29: 1 | AA29: 118/课 | AB29: 一对一30课时 | AC29: 3540 | AD29: 6.3日缴费
A30: 28 | B30: 6.3 | C30: 英国 | E30: 7 | F30: 瞌睡 | G30: baobeicz | I30: 常艺霏 | J30: 8岁 | K30: 女 | L30: 是 | M30: 否 | N30: 学过学前班，会一些拼音，有些识字基础，可以日常对话 | O30: 中文 | Q30: 任宏印 ；16:00； 6.2 ChineseonlineA 16:00 6.3 | R30: 家长介绍 | S30: 1 | T30: 何家昌 安纹畅妈妈介绍 | V30: 白 | W30: 白 | X30: 1 | Y30: 1 | Z30: 1 | AA30: 56/课 | AB30: 一对四65课时 | AC30: 3640 | AD30: 6.3日缴费
A31: 29 | B31: 6.3 | C31: 美西 | E31: 15 | F31: SUSU素素 硅谷 VC | G31: SusuLiugo | I31: 冯浩齐 | J31: 7 | K31: 男 | L31: 学过一点 | M31: 是 | O31: 中文 | P31: 一上第八单元开始学起，读没问题，句子不理解，不会组词和造句，孩子比较顽皮坐不住。双语 | Q31: 杨静；7:00；6.3 | R31: 微信 | S31: 3 | T31: 王可 | X31: 1 | Y31: 1 | Z31: 1 | AA31: 56/课 | AB31: 一对四65课时 | AC31: 3640 | AD31: 6.30日缴费
A32: 30 | B32: 6.3 | C32: 美国 | D32: 纽约 | E32: 12 | G32: zhoulipi-9827 | I32: jayden | J32: 8岁 | K32: 男 | L32: 没有 | M32: 否 | N32: 沟通可以但是没有基础 | O32: 中文 | P32: 零基础，学生比较调皮，容易注意力不集中，妈妈说想要报一对一的班级，建议从拼音开始学起。 | Q32: 周虹 7:00 6.3 Chineseonline N 7:40 6.5 | R32: 家长介绍 | S32: 5 | T32: 刘箫 哒哒家长介绍 | W32: 白 | X32: 1 | Y32: 1 | Z32: 1 | AA32: 56/课 | AB32: 一对四65+5课时 | AC32: 3640 | AD32: 6.3日缴费
A33: 31 | B33: 6.3 | C33: 美东 | D33: 东部 | E33: 12 | F33: 三宝麻麻 | G33: 无 | I33: 李圳楠 | J33: 10 | K33: 男 | L33: 学过一点 | M33: 是 | N33: 学过一点，学w | O33: 中文 | P33: 程度非常不错，学生的理解力很好，识字量跟不上，建议从一下开始上课 | Q33: 周虹 8:20 6.3 | R33: 介绍 | S33: 3 | T33: 展旺 | X33: 2 | Y33: 没有 | Z33: 同事竞争
A34: 32 | B34: 6.3 | C34: 美西 | D34: 旧金山 | E34: 15 | F34: Jajane | G34: wxid_e1af73193e12 | I34: 谭煦彤 | J34: 12 | K34: 女 | L34: 学过 | M34: 否 | N34: 当地学了7年了，想着重写作方面 | O34: 中文 | P34: 程度不错，识字量比较少，词汇量较多，组词造句比较好，建议从二上三四单元开开始学习 | Q34: 周虹 9:20 6.3 | R34: 微信 | S34: 3 | T34: 王可 | AB34: 孩子不喜欢
A35: 33 | B35: 6.3 | C35: 美西 | D35: 旧金山 | E35: 15 | F35: 林小欧 | G35: L9175185008 | I35: 谭煦迪 | J35: 8 | K35: 男 | L35: 学过 | M35: 否 | N35: 学了3年了，拼音没问题 | O35: 中文 | P35: 弟弟跟姐姐相对较差，识字量和词汇量都比较少，朗读较为流畅，建议从一上八单元或者一下开始学。 | Q35: 周虹 10:00 6.3 | R35: 微信 | S35: 3 | T35: 王可 | AB35: 孩子不喜欢
A36: 34 | B36: 6.3 | C36: 美国 | D36: 西部 | E36: 15 | F36: 川富 | G36: tang272251187yy | I36: 唐源 | J36: 10 | K36: 女 | L36: 学过 | M36: 否 | N36: 国内学了三年级，刚到美国一年，希望从五年级开始 | O36: 中文 | P36: 建议五上开始，所有生字都认识，文章表层含义理解，深层道理不理解，不会总结 | Q36: 刘钰兰；7:00；6.3 Chineseonline L 9：00 6.4 | R36: 微信 | S36: 3 | T36: 杨斌 | V36: 白 | W36: 白 | X36: 1 | Y36: 1 | Z36: 1 | AA36: 56/课 | AB36: 一对四65课时 | AC36: 3640 | AD36: 6.5日缴费
A37: 35 | B37: 6.3 | C37: 美国 | D37: 中部 | E37: -14 | F37: yoyo高 | G37: gaoqiumei00 | I37: 林尚锴 | J37: 11 | K37: 男 | L37: 有 | M37: 否 | N37: 去年暑假学了2个月中文 ，会看拼音识字，识字量不多 | O37: 中文 | P37: 建议一上四单元开始，拼音会，识字量一般。孩子有些害羞 | Q37: 刘钰兰；8:20；6.3 | R37: 微信 | S37: 0 | T37: 王忆超
A38: 36 | B38: 6.3 | C38: 加拿大 | E38: 15 | F38: tina | G38: tina9972 | I38: 方宝 | J38: 12 | K38: 女 | L38: 有 | M38: 否 | N38: 之前在我们这边学过 后面有3个月没学了，想来从新上课 但是不知道学到哪了 三四年级的程度 | O38: 中文 | P38: 建议四上开始学习，语言表达能力很好，字词有一些不理解意思 | Q38: 刘钰兰；10:20；6.3 Chineseonline F 11:40 6.5 ChineseonlineT10 9:40 6.18 | R38: 微信 | S38: 白 | T38: 俞酉兰 | U38: 6.5 | V38: 白 | W38: 兼 | X38: 1 | Y38: 1 | AA38: 56/课 | AB38: 一对四65课时 | AC38: 3640 | AD38: 6.18缴费
A39: 37 | B39: 6.3 | C39: 美东 | D39: 东部 | E39: 12 | F39: 三宝麻麻 | G39: 无 | I39: 李圳洋 | J39: 9 | K39: 男 | L39: 学过会一点 | M39: 是 | N39: 学过一点，没有老大好 | O39: 中文 | P39: 一上第八单元开始学起，读的能力好，不会组词和造句。 | Q39: 杨静；7:40；6.3 | R39: 介绍 | S39: 3 | T39: 展旺 | Y39: 没有 | Z39: 同事竞争
A40: 38 | B40: 6.3 | C40: 美东 | D40: 纽约 | E40: 12 | F40: 林小欧 | G40: L9175185008 | I40: 王锦文 | J40: 6 | K40: 男 | L40: 没有 | M40: 否 | N40: 会说中文但是没有学过拼音 | O40: 中文 | P40: 建议拼音学起，配合度高很听话。说的能力好很爱表现，认字量50个内。 | Q40: 杨静；9:00；6.3 Chineseonline N 7:40 6.5 | R40: 微信 | S40: 3 | T40: 展旺 | V40: 白 | X40: 1 | Y40: 1 | Z40: 1 | AA40: 56/课 | AB40: 一对四65+2课时 | AC40: 3640 | AD40: 6.4日缴费
...

Sheet 2020.5
A1: 新生接待试读表 业务员：测+读 老师：试读两次
A2: 序号 | B2: 测试时间 | C2: 国家 | D2: 城市 | E2: 时差 | F2: 家长微信名 | G2: 家长微信 | H2: 学生姓名 | I2: 年龄 | J2: 性别 | K2: 有没有学过拼音 | L2: 是否需要双语老师 | M2: 家长自述程度及学习需求 | N2: 学习课程 | O2: 测试结果 | P2: 排课安排 | Q2: 来源 | R2: 组别 | S2: 业务员 | T2: 试读日期 | U2: 试课安排 | V2: 排课校区 | W2: 是否在读 | X2: 是否缴费 | Y2: 失败原因 | Z2: 课程单价 | AA2: 折扣 | AB2: 实收 | AC2: 首次收费时间
A3: 1 | B3: 5.1 | C3: 美国 | E3: 12 | G3: apple | H3: 郭宇镌 | I3: 17 | L3: 是 | M3: 会听说，认识少许字，口语基本都可以 | N3: 中文 | O3: 学生课堂反应能力很好，听力没问题，表达能力一般，明显的英式思维；三声调不准；建议从拼音学起，多练习日常口语 | P3: 刘紫佳7:00 5.1 | Q3: 电话 | R3: 1 | S3: 娄丽华 | Y3: 家长不信任我们学校，不愿意缴费
A4: 2 | B4: 5.1 | C4: 加拿大 | D4: 多伦多 | E4: 12 | F4: Fiona | G4: fionaleeparis | H4: 陆梓朗 | I4: 10 | J4: 男 | K4: 有 | L4: 否 | M4: 孩子零基础 ，之前学习过拼音，很久没有练习了。喜欢 钢琴 足球 basketball | N4: 中文 | O4: 日常交流不行，需要双语老师；拼音学过忘记了，汉字没学过，可以从拼读复习开始学 | P4: 刘依琳 7:40 5.1 | Q4: 家长介绍 | R4: 2 | S4: 高翱翔 陈彦豪妈妈介绍 | W4: 0 | X4: 0 | Y4: 还在谈
A5: 3 | B5: 5.1 | C5: 加拿大 | D5: 多伦多 | E5: 12 | F5: Fiona | G5: fionaleeparis | H5: 陆纪欣 | I5: 12 | J5: 女 | K5: 有 | L5: 否 | M5: 孩子零基础 ，之前学习过拼音，很久没有练习了。喜欢 钢琴 basketball | N5: 中文 | O5: 学生上课表现很好，需要双语老师，听说很困难；建议鼓励孩子张嘴说中文，从零基础开始学习 | P5: 任晓艳 8:20 5.1 | Q5: 家长介绍 | R5: 2 | S5: 高翱翔 陈彦豪妈妈介绍 | W5: 0 | X5: 0 | Y5: 还在谈
A6: 4 | B6: 5.1 | C6: 美国 | E6: 12 | G6: gao8888868 | H6: Leon Gao | I6: 9 | J6: 男 | L6: 否 | M6: 口语流利，会讲不会写 | N6: 中文 | O6: 学生积极性不高，需要上课比较活动调动性强的老师；建议从拼音开始学 | P6: 刘紫佳 9:00 5.1 言智14 单紫薇 22:10 5.17 | Q6: 电话 | R6: 1 | S6: 娄丽华 | T6: 5.2 | U6: 兼 | V6: 兼 | W6: 1 | X6: 1 | Y6: 1 | Z6: 56/课 | AA6: 65课时 | AB6: 3640 | AC6: 5.6日缴费
A7: 5 | B7: 5.2 | C7: 美国 | D7: 西部 | E7: 15 | F7: MaggieRH | G7: Hrmaggie | H7: 杨鼎彬 | I7: 12 | J7: 男 | K7: 学过 | L7: 否 | M7: 一年级 | N7: 中文 | O7: 一上后面部分 | P7: 张文红 5.1 ChineseonlineJ 11:40 5.5 ChineseonlineK1 8：20 5.9 | Q7: 电话 | R7: 3 | S7: 张文红 | U7: 兼 | V7: 白 | W7: 0 | X7: 0 | Y7: 本来就在lingoace在学，家长希望孩子一周五天，但孩子不喜欢
A8: 6 | B8: 5.2 | C8: 美国 | D8: 西部 | E8: 15 | F8: MaggieRH | G8: Hrmaggie | H8: 杨雨涵 | I8: 8 | J8: 女 | K8: 学过 | L8: 否 | M8: 三年级 | N8: 中文 | O8: 上课氛围不错，会回答老师问题，能主动学习，建议从三年级第一课开始学 | P8: 孙水仙 9:00 5.2 ChineseonlineF8:20 5.5 | Q8: 电话 | R8: 3 | S8: 张文红 杨鼎彬妹妹 | T8: 5.11 | U8: 白 | W8: 0 | X8: 0 | Y8: 本来就在lingoace在学，家长希望孩子一周五天，但孩子不喜欢
A9: 7 | B9: 5.2 | C9: 美国 | D9: 纽约 | E9: 12 | F9: irisliu | G9: irisliu32656 | H9: 郭柳钰 | I9: 16 | J9: 女 | K9: 有 | L9: 否 | M9: 3年级程度，会拼音 口语流利 | N9: 中文 | O9: 学生认字很好，写字差一点，测试《在牛肚子里旅行》，建议先学完这课，然后从三年级第一课开始学 | P9: 孙水仙 7:00 5.2 | Q9: 家长介绍 | R9: 2 | S9: 高翱翔 林若惜妈妈介绍 | W9: 0 | X9: 0 | Y9: 时间短，价格高
A10: 8 | B10: 5.2 | C10: 美国 | D10: 纽约 | E10: 12 | F10: irisliu | G10: irisliu32656 | H10: 郭子涵 | I10: 14 | J10: 男 | K10: 有 | L10: 否 | N10: 中文 | O10: 上课很认真，会积极主动提问，学过拼音但掌握程度一般，复韵母有些忘记了，认识简单的汉字，知道笔顺和笔画的概念；建议从复韵母部分开始学 | P10: 赵佳求7:40 5.2 | Q10: 家长介绍 | R10: 2 | S10: 高翱翔 林若惜妈妈介绍 | W10: 0 | X10: 0 | Y10: 时间短，价格高
A11: 9 | B11: 5.2 | C11: 美国 | D11: 纽约 | E11: 12 | F11: irisliu | G11: irisliu32656 | H11: 郭铭钰 | I11: 13 | J11: 女 | K11: 接触过一点 | L11: 否 | M11: 零基础 ，拼音需要重新学习了。 | N11: 中文 | O11: 上课很认真，课堂表现好，听说和理解力都没问题；学过拼音但不扎实，拼读比较困难，建议从声母部分重新学起 | P11: 任晓艳8:20 5.2 | Q11: 家长介绍 | R11: 2 | S11: 高翱翔 林若惜妈妈介绍 | W11: 0 | X11: 0 | Y11: 时间短，价格高
A12: 10 | B12: 5.2 | C12: 澳大利亚 | E12: 2 | F12: Cathy ོQ | G12: Q_Cathy | H12: 天天 | I12: 12 | J12: 男 | K12: 学过一点 | L12: 否 | M12: 简单的学过一点 | N12: 中文 | O12: 哥哥表现力比妹妹弱一些，会一点拼音但是没掌握，建议从一上拼音开始学 | P12: 程晓诺14:20 5.2 | Q12: 微信 | R12: 3 | S12: 杨斌 | W12: 0 | X12: 0 | Y12: 去别的机构试课，之后失联了，被拉黑
A13: 11 | B13: 5.2 | C13: 澳大利亚 | E13: 2 | F13: Cathy ོQ | G13: Q_Cathy | H13: 香香 | I13: 10 | J13: 女 | K13: 学过一点 | L13: 否 | M13: 简单的学过一点 | N13: 中文 | O13: 口语表达有限，会一些拼音但是不熟练，写字能力差，建议从一上拼音开始学 | P13: 程晓诺15:00 5.2 | Q13: 微信 | R13: 3 | S13: 杨斌 | W13: 0 | X13: 0 | Y13: 去别的机构试课，之后失联了，被拉黑
A14: 12 | B14: 5.4 | C14: 美国 | D14: 纽约 | E14: -12 | F14: XiaoZhanG | G14: figtzyx | H14: 马尔若兮 | I14: 7 | J14: 女 | K14: 有 | L14: 否 | M14: 家长说有国内一年级水平 会点拼音 不知道是否忘记 可以正常中文交流 爱好 手工 舞蹈 滑雪 家长要求测一年级下册 | N14: 中文 | O14: 建议一下第三单元开始学起，认字能力不错，词语的理解不懂 | P14: 杨静7:40；5.4 | Q14: 中文 | R14: 2 | S14: 高翱翔 | W14: 0 | X14: 0 | Y14: 老师无法深入孩子的心
A15: 上个月算过人数 | B15: 5.4 | C15: 澳大利亚 | D15: 悉尼 | E15: 2 | F15: Annie Z | G15: AnnieZ510 | H15: 江羿廷 | I15: 5 | J15: 男 | K15: 否 | L15: 否 | M15: 没学过，可以简单的听懂一些，家长希望学会拼读和写字 | N15: 启蒙 | O15: 建议天地人学起，后面拼音学起。中文交流没问题 启蒙课账号 +61 432305700 | P15: 杨静13:00 4.25 Chineseonline A 14:50 4.27 卢爽13:00 5.4 | Q15: 家长介绍 | R15: 3 | S15: 王可 王有衡妈妈推荐 | T15: 5.4 | U15: 兼 | V15: 兼 | W15: 1 | X15: 1 | Y15: 1 | Z15: 116/课 | AA15: 一对一65+3课时 | AB15: 7540 | AC15: 5.9日缴费
A16: 13 | B16: 5.4 | C16: 澳大利亚 | E16: 2 | F16: 小雅Jana | G16: Jana8888 | H16: 王安杰 | I16: 4 | J16: 男 | K16: 否 | L16: 否 | M16: 中文交流，会讲广东话 | N16: 启蒙 | O16: +61 432305700 | P16: 卢爽13:30 5.4 | Q16: 微信 | R16: 3 | S16: 杨斌 | T16: 5.4 | U16: 兼 | V16: 兼 | W16: 1 | X16: 1 | Y16: 1 | Z16: 140/课，一对二价格收费 | AA16: 一对一一小时，前半小时语文后半小数数学，10课时 | AB16: 和数学一起￥1400 | AC16: 5.15日缴费
A17: 14 | B17: 5.4 | C17: 加拿大 | D17: 温哥华 | E17: -15 | F17: 🏡Suki🇨🇦 | G17: suki176156 | H17: 莹莹 | I17: 3.5 | J17: 女 | K17: 否 | L17: 否 | M17: 没学过，识字量50-80 | N17: 启蒙 | P17: 卢爽8:00 5.4 卢爽10:00 5.7 | Q17: 微信 | R17: 白 | S17: 俞酉兰 | T17: 5.7 | U17: 兼 | V17: 兼 | W17: 1 | X17: 1 | Y17: 1 | Z17: 79/课 | AA17: 22课时 | AB17: 1738 | AC17: 5.8日缴费
A18: 15 | B18: 5.5 | C18: 加拿大 | D18: 温哥华 | E18: 15 | G18: ritaluo23 | H18: 张佳美 | I18: 3 | J18: 女 | K18: 否 | L18: 否 | M18: 简单交流在家 | N18: 启蒙 | P18: 卢爽10:30 5.5 | Q18: 微信 | R18: 1 | S18: 赵红艳 | T18: 5.5 | U18: 兼 | V18: 兼 | W18: 1 | X18: 1 | Y18: 1 | Z18: 96/课 | AA18: 一对二，65+5课时 | AB18: 6240 | AC18: 5.18日缴费
A19: 16 | B19: 5.5 | C19: 法国 | E19: 6 | F19: ENMA-D | G19: ENMA-D | H19: 刘咔诺 | I19: 8 | J19: 女 | K19: 是 | L19: 否 | M19: 国外中文学校学到二年级下册，学的一般，脱离拼音有些不认识 | N19: 中文 | O19: 孩子很愿意学，表达很流利，基础不是很扎实，可以从二年级下册开始学 | P19: 程晓茹19:30 5.4 周末班 第二十八课堂1:05 薛万意5.9 | Q19: 家长介绍 | R19: 白 | S19: 欧洲家长推荐 | U19: 夜 | W19: 0 | X19: 0 | Y19: 已经缴费周末班，但是上了一次又要退钱
A20: 17 | B20: 5.5 | C20: 加拿大 | D20: 温哥华 | E20: -15 | F20: Ye | G20: gingeraleye | H20: 童童2 | I20: 10 | J20: 女 | K20: 有 | L20: 否 | M20: 暨南大学第七册 | N20: 中文 | O20: 学过一些中文，但是有遗忘，建议从一下第四、五单元开始上课。 第二次测试，学生程度为一下六单元左右 | P20: 周虹 8:20 5.5 | Q20: 家长介绍 | R20: 白 | S20: 俞酉兰 Ella2妈妈介绍 | W20: 0 | X20: 0 | Y20: 就是想上张娟娟的课，没有课就不报名
A21: 18 | B21: 5.5 | C21: 加拿大 | D21: 温哥华 | E21: -15 | F21: Ye | G21: gingeraleye | H21: 涵涵1 | I21: 8 | J21: 女 | K21: 有 | L21: 否 | M21: 暨南大学第四册 | N21: 中文 | O21: 学过一些中文，从一上七，八单元开始上课 | P21: 周虹 9:00 5.5 Chineseonline C 1张娟娟7:40 5.6 | Q21: 家长介绍 | R21: 白 | S21: 俞酉兰 Ella2妈妈介绍 | T21: 5.5 | U21: 兼 | V21: 兼 | W21: 1 | X21: 1 | Y21: 1 | Z21: 59/课 | AA21: 22课时 | AB21: 1298 | AC21: 5.6缴费
A22: 19 | B22: 5.5 | C22: 美国 | D22: 旧金山 | E22: -15 | F22: Helen GuoGuo | G22: helenguoguoguo | H22: 豆豆 | I22: 3.8岁 | J22: 男 | K22: 否 | L22: 否 | M22: 会说中文，不认识字 | N22: 启蒙 | P22: 卢爽10：00 5.6 | Q22: 家长介绍 | R22: 兼 | S22: 俞酉兰 陈一一妈妈介绍 | T22: 5.6 | U22: 兼 | W22: 0 | X22: 0 | Y22: 孩子喜欢孙悟空，报了悟空中文
A23: 20 | B23: 5.5 | C23: 加拿大 | D23: 温哥华 | E23: -15 | F23: DAISY | G23: saloli | H23: 王子 | I23: 12 | J23: 男 | K23: 是 | L23: 否 | M23: 国内上完三年级 | N23: 中文 | O23: 在国内学完了三年级，从读的情况看，有些简单的生字有遗忘的，建议从四上一单元开始上课。 | P23: 周虹 9:40 5.5 | Q23: 家长介绍 | R23: 白 | S23: Lawrence1妈妈介绍 | W23: 0 | X23: 0 | Y23: 没时间
A24: 21 | B24: 5.5 | C24: 美国 | D24: 东部 | E24: 12 | F24: 与有荣焉 | G24: joy1joy2010 | H24: Quinny | I24: 6 | J24: 女 | K24: 没学过 | L24: 否 | M24: 没学过，可以听说 | N24: 中文 | O24: 年纪偏小坐不住，建议认字2开始学起，测试课已经学完了天地人 | P24: 杨静，7：40；5.5 ChineseonlineA7:40 5.8 | Q24: 微信 | R24: 3 | S24: 王可 | T24: 5.8 | U24: 白 | W24: 0 | X24: 0 | Y24: 喜欢测试老师，其它老师不满意
A25: 22 | B25: 5.5 | C25: 美国 | D25: 东部 | E25: 12 | F25: 与有荣焉 | G25: joy1joy2010 | H25: 妞妞 | I25: 8 | J25: 女 | K25: 没学过 | L25: 否 | M25: 没系统学过，可以交流 | N25: 中文 | O25: 建议拼音i;u学起，接受能力有点慢，建议老师讲课的时候耐心些。字的话认识最简单的，测试课已经学完了a;o;e | P25: 杨静；7：00；5.5 Chineseonline Z 7:00 5.6 | Q25: 微信 | R25: 3 | S25: 王可 | T25: 5.7 | U25: 白 | W25: 0 | X25: 0 | Y25: 喜欢测试老师，其它老师不满意
A26: 23 | B26: 5.5 | C26: 美国 | D26: 洛杉矶 | E26: 15 | F26: 美丰林灵 | G26: forest_bird2012 | H26: henry yang | I26: 10 | J26: 女 | K26: 学过一些 | L26: 要 | M26: 拼音学过一些，二年级水平 | N26: 中文 | O26: 建议拼音ai;ei;ui开始学起，老师讲解要慢一些耐心，学生有点排斥学习。 | P26: 杨静；9：40；5.5 | Q26: 微信 | R26: 2 | S26: 平金军 | W26: 0 | X26: 0 | Y26: 报了别人家，一对一，8月份再来
A27: 24 | B27: 5.5 | C27: 美国 | D27: 东部 | E27: 12 | F27: zeros | G27: jshi112 | H27: 王子文 | I27: 7 | J27: 男 | K27: 学过 | L27: 否 | M27: 拼音学完了，但是还需要巩固 | N27: 中文 | O27: 程度很好，简单的生字都是认识的，拼读不是很熟练，课文读的不够流畅，建议从一上五单元开始上课。 | P27: 周虹 7:00 5.5 Chineseonline W 9:00 5.8 | Q27: 微信 | R27: 3 | S27: 王可 | U27: 排课了没去试读 | W27: 0 | X27: 0 | Y27: 想要一对四的班级，一直没有
A28: 25 | B28: 5.5 | C28: 美国 | D28: 东部 | E28: 12 | F28: Syler | G28: meggy123_ | H28: 凯翌 | I28: 14 | J28: 女 | K28: 学过一点 | L28: 否 | M28: 拼音学过 | N28: 中文 | O28: 程度不错，拼音第四声要注意，建议从一上六单元开始学习。【课程顾问的信息不准确】 | P28: 周虹 7:40 5.5 Chineseonline O 8:20 5.8 | Q28: 介绍 | R28: 3 | S28: 张霞 | T28: 5.8 | U28: 白 | W28: 0 | X28: 0 | Y28: 报名了悟空中文
A29: 26 | B29: 5.5 | C29: 美国 | D29: 西部 | E29: 15 | F29: M | G29: meelion | H29: 焦黎明 | I29: 8 | J29: 男 | K29: 学过 | L29: 否 | M29: 学了三年了 | N29: 中文 | O29: 识字量到一下的程度，但是书写不理想，建议从一上八单元开始上课。 | P29: 周虹 10:20 5.5 Chineseonline H 8:20 5.8 | Q29: 微信 | R29: 3 | S29: 王可 | T29: 5.8 | U29: 白 | V29: 白 | W29: 1 | X29: 1 | Y29: 1 | Z29: 50/课 | AA29: 一对四130+10课时 | AB29: 焦黎明，焦子黎共13000 | AC29: 5.16日缴费
A30: 27 | B30: 5.5 | C30: 美国 | D30: 西部 | E30: 15 | F30: M | G30: meelion | H30: 焦子黎 | I30: 5 | J30: 女 | K30: 没学 | L30: 否 | M30: 还没学过，家长想让学习拼音，说孩子吸收能力不错 | N30: 中文 | O30: 建议拼音i;u;开始学起，接受能力很强，比较活泼，有一定的识字量。测试课简单的学习了a;o;e还需要复习 | P30: 杨静 11:00 5.5 chineseonline Z 7:00 5.9 | Q30: 微信 | R30: 3 | S30: 王可 | T30: 5.8 | U30: 白 | V30: 白 | W30: 1 | X30: 1 | Y30: 1 | Z30: 50/课 | AA30: 一对四130+10课时 | AB30: 焦黎明，焦子黎共13000 | AC30: 5.16日缴费
A31: 28 | B31: 5.5 | C31: 澳大利亚 | D31: 悉尼 | E31: 2 | F31: ［］IVY[] | G31: 无 | H31: 冠聪 | I31: 8 | J31: 男 | K31: 没学 | L31: 否 | M31: 没学过 | N31: 中文 | O31: 零基础，建议认字天地人开始学起，接受能力快，双语 | P31: 杨静；14：20；5.5 | Q31: 微信 | R31: 3 | S31: 展旺 | W31: 0 | X31: 0 | Y31: 蹭课，上课后直接说孩子不敢兴趣
A32: 29 | B32: 5.5 | C32: 美国 | D32: 东部 | E32: 12 | F32: Ella | G32: wangqian52572538 | H32: kelvin | I32: 4 | J32: 男 | K32: 没学过 | L32: 否 | M32: 日常中文交流，但没学过中文 | N32: 启蒙 | O32: 16262259586 | P32: 卢爽7:40 5.5 | Q32: 微信 | R32: 3 | S32: 严杨洁 | U32: 兼
A33: 30 | B33: 5.5 | C33: 加拿大 | D33: 温哥华 | E33: -15 | F33: lena | G33: jinlaxu | H33: 奥利维亚 | I33: 3.8 | J33: 女 | K33: 无 | L33: 否 | M33: 在家中一直坚持说中文 喜欢画画 坐得住 | N33: 启蒙 | O33: 18640554349 | P33: 卢爽9:00 5.5 | Q33: 家长介绍 | R33: 2 | S33: 赵国花 张加翼妈妈介绍 | T33: 5.6 | U33: 兼 | V33: 兼 | W33: 1 | X33: 1 | Y33: 1 | Z33: 76-6/课 | AA33: 35+6课时 | AB33: 和英语一起4550 | AC33: 5.7日缴费
A34: 31 | B34: 5.5 | C34: 美国 | D34: 洛杉矶 | E34: -15 | F34: Irene 加州洛杉矶地产经纪 | G34: Avril3691 | H34: 孙涵泽 | I34: 5 | J34: 男 | K34: 无 | L34: 是 | M34: 零基础，会说一点点中文，喜欢玩，画画。 | N34: 启蒙 | O34: 13904026582 | P34: 卢爽10:00 5.5 | Q34: 微信 | R34: 2 | S34: 丁阮琪 | T34: 5.6 | U34: 兼 | W34: 0 | X34: 0 | Y34: 马上要解禁了，想要去当地看一下 失败原因：孩子离电脑太近，怕孩子近视，且线下快可以报名了，想去看看线下的情况。_x000D_ CC原因：第一次试读时家长兴趣大，第二次试读明显兴趣下降，两次试读之间隔了一天，家长心态有点变化，下次家长要求第二次试读时，尽可能将时间排的紧密。_x000D_ 老师原因：老师其他地方都很好，可以吸引孩子注意力，让孩子集中听课，以后上课提醒孩子不要离电脑更近会更好。_x000D_
A35: 32 | B35: 5.6 | C35: 加拿大 | D35: 温哥华 | E35: -15 | F35: 喵 | G35: kkforever311 | H35: 戴辰熠 | I35: 4.5 | J35: 男 | K35: 否 | L35: 否 | M35: 会说中文，不认识字 | N35: 启蒙 | O35: +1 6043550310 | P35: 卢爽7:30 5.6 | Q35: 家长介绍 | R35: 兼 | S35: 俞酉兰 | T35: 5.6 | U35: 兼 | W35: 0 | X35: 0 | Y35: 0 | Z35: 微信没有回复
A36: 33 | B36: 5.6 | C36: 加拿大 | E36: 12 | G36: xiaoyu648727 | H36: Jayden | I36: 3 | J36: 男 | K36: 否 | L36: 否 | M36: 零基础，小朋友爱动坐不住，001 6479880186 | N36: 启蒙 | O36: 001 6479880186 | P36: 卢爽22:00 5.5 | Q36: 家长介绍 | R36: 1 | S36: 何家昌 aiden妈妈介绍 | T36: 5.5 | U36: 兼 | Y36: 家长觉得孩子不适合线上上课，不打算报名
A37: 34 | B37: 5.6 | C37: 法国 | E37: 6 | G37: paris-xuri | H37: 甘蔡铭 | I37: 7 | K37: 没有 | L37: 否 | M37: 平时中文交流，妈妈自己教的 | N37: 中文 | O37: 从拼音开始学，孩子很配合老师 | P37: 程晓茹 18:30 5.5 言智14 单紫薇 18:45 5.8 | Q37: 电话 | R37: 1 | S37: 赵红艳 | T37: 5.8 | U37: 兼 | Y37: 妈妈想给孩子报当地的，能让孩子交到更多朋友，而且当地可以申请免费都
A38: 35 | B38: 5.6 | C38: 加拿大 | D38: 温哥华 | E38: -15 | F38: light | G38: wxid-1559075596412 | H38: 马潇童 | I38: 6 | J38: 女 | K38: 否 | L38: 否 | M38: 会说会听没有学过 | N38: 中文 | O38: 拼音的复韵母开始（一上第三单元）（爸爸想让孩子上一对一） | P38: 黄礼云10:20 5.6 Chineseonline F 9:40 5.12 | Q38: 扫一扫 | R38: 白 | S38: 俞酉兰 | W38: 0 | X38: 0 | Y38: 想上一对一但是觉得价格贵
A39: 36 | B39: 5.6 | C39: 加拿大 | D39: 温哥华 | E39: -15 | F39: light | G39: wxid-1559075596412 | H39: 马诗蕊 | I39: 8 | J39: 女 | K39: 有 | L39: 否 | M39: 国内上完2年级了 | N39: 中文 | O39: 三上四年级开始（孩子在国内学到二年级，程度不错，爸爸觉得一对多可能效果好一点） | P39: 黄礼云9：40 5.6 | Q39: 扫一扫 | R39: 白 | S39: 俞酉兰 | W39: 0 | X39: 0 | Y39: 想上一对一但是觉得价格贵
A40: 37 | B40: 5.6 | C40: 加拿大 | E40: 加拿大 | F40: Nancy | G40: wxid_qnjid09ucqbf22 | H40: 李曜竹 | I40: 10 | J40: 女 | K40: 是 | L40: 否 | M40: 在中国学习到二年级上学期，忘了很多 | N40: 中文 | O40: 二上四单元开始（程度不错） | P40: 黄礼云9:00 5.6 | Q40: 家长介绍 | R40: 白 | S40: 周禹辰妈妈介绍 | W40: 0 | X40: 0 | Y40: 没课合适
...

Sheet 2020.4
A1: 新生接待试读表 业务员：测+读 老师：试读两次
A2: 序号 | B2: 测试时间 | C2: 国家 | D2: 城市 | E2: 时差 | F2: 家长微信名 | G2: 家长微信 | H2: 学生姓名 | I2: 年龄 | J2: 性别 | K2: 有没有学过拼音 | L2: 是否需要双语老师 | M2: 家长自述程度及学习需求 | N2: 学习课程 | O2: 测试结果 | P2: 排课安排 | Q2: 来源 | R2: 组别 | S2: 试读日期 | T2: 业务员 | U2: 排课分组 | V2: 是否在读 | W2: 是否缴费 | X2: 失败原因 | Y2: 课程单价 | Z2: 折扣 | AA2: 实收 | AB2: 首次收费时间 | AG2: =SUM(A2:AF2) -> 0
A3: 1 | B3: 4.1 | C3: 西班牙 | D3: 昆卡 | E3: 6 | F3: cristina | G3: Hhy820905 | H3: 陈芸汐 | I3: 13 | J3: 女 | N3: 数学 | Q3: 报第二门课 | R3: 夜 | T3: 夜 | U3: 兼 | V3: 0 | W3: 0 | X3: 中文课转成数学课，上完就停课
A4: 2 | B4: 4.1 | C4: 澳洲 | E4: 3 | G4: ytt7757942 | H4: 于茗舟 | J4: 男 | K4: 否 | L4: 否 | M4: 1 61403073278 | N4: 启蒙 | P4: 卢爽11:00 4.1 | Q4: 学生兄妹 | R4: 1 | T4: 张文红 | U4: 兼 | V4: 0 | W4: 0 | X4: 杨于葳弟弟，等大一点会来学
A5: 3 | B5: 4.1 | C5: 巴西 | E5: 11 | F5: Lidia Wang | G5: lidia_wang_liqin | H5: 叶雨泽 | I5: 8 | J5: 男 | L5: 否 | M5: 二年级数学 | N5: 数学 | P5: 十一课堂B 仇老师4.1 | Q5: 学生兄妹 | R5: 白 | T5: 叶瑜繁弟弟 | U5: 兼 | V5: 1 | W5: 1 | X5: 和叶瑜繁一起交
A6: 4 | B6: 4.1 | C6: 美国 | D6: 加州 | E6: 15 | F6: Kay 巴菲特地产BROKER | G6: Kaywolf0531 | H6: 乃欧咪Naomi Wolf | I6: 6 | J6: 女 | K6: 有 | L6: 否 | M6: 零基础 学编程 | N6: 编程 | O6: 试过半小时，喜欢 | P6: 编程课堂王老师 9:00 4.1 | Q6: 报第二门课 | R6: 白 | T6: 微信 | U6: 兼 | V6: 1 | W6: 1 | X6: 1 | Y6: 180/课 | Z6: 一周一次 | AA6: ＄100.08 | AB6: 4.1日缴费
A7: 5 | B7: 4.1 | C7: 加拿大 | D7: 多伦多 | E7: 12 | F7: kiki | G7: wxid_3qx4wrt8a5ya21 | H7: 陈婷婷 | I7: 10 | J7: 女 | K7: 无 | L7: 是 | M7: 零基础，不会普通话交流，只会粤语和英语 | N7: 中文 | O7: 需要双语，一上识字开始学 | P7: 徐晓晓8:00 4.1 范老师课堂8:00 4.4 | Q7: 微信 | R7: 2 | T7: 高翱翔 | U7: 兼 | V7: 0 | W7: 0 | X7: 价格贵
A8: 6 | B8: 4.1 | C8: 加拿大 | D8: 多伦多 | E8: 12 | F8: kiki | G8: wxid_3qx4wrt8a5ya21 | H8: 陈镇聪 | I8: 13 | J8: 男 | K8: F | L8: 是 | M8: 会简单交流，非常基础， | N8: 中文 | O8: 不需要，一上识字开始 | P8: 徐晓晓8:00 4.1 范老师课堂8:00 4.4 | Q8: 微信 | R8: 2 | T8: 高翱翔 | U8: 兼 | V8: 0 | W8: 0 | X8: 价格贵
A9: 7 | B9: 4.1 | C9: 加拿大 | D9: 温哥华 | E9: 15 | F9: Winnie 枫情新生活 | G9: audreywinniejohn1009 | H9: 周子欣 | I9: 12 | J9: 女 | K9: 有 | L9: 否 | M9: 拼音学过但是不熟，认识一些常用字，咬字清晰，词汇量一般，写字笔顺很乱不太会写 | N9: 中文 | O9: 不需要双语,建议二上中前期开始 | P9: 胡文君老师 4:00 4.1 | Q9: 电话 | R9: 3 | T9: 杨斌 | U9: 0 | V9: 0 | W9: 0 | X9: 一直没回复
A10: 8 | B10: 4.1 | C10: 澳大利亚 | D10: 布里斯班 | E10: 3 | F10: Daphne千捷 | G10: Daphne_Jie | H10: 岳穆霖 | I10: 4岁半 | J10: 男 | K10: 没学过 | L10: 否 | M10: 认识一百个字左右 想试试学拼音 | N10: 启蒙 | O10: 孩子没有规则意识需要好好引导，建议启蒙或者1对1拼音 | P10: 周虹 7:40 4.1 卢爽 启蒙4.2 | Q10: 微信 | R10: 3 | T10: 翁珊珊 | U10: 兼 | V10: 1 | W10: 1 | X10: 1 | Y10: 96/课 | Z10: 22课时 | AA10: 466澳元 | AB10: 4.10日缴费 | AC10: 岳穆霖，贺羲鸣，Ryan三人一起共￥6240，65+1课时三个人分
A11: 9 | B11: 4.1 | C11: 加拿大 | E11: 12 | G11: F7667C | H11: 陈颖欣 | I11: 10 | J11: 女 | K11: 学一点拼音 | L11: 否 | M11: 学一点拼音 | N11: 中文 | O11: 一上拼音iuv开始 | P11: 周虹 7:40 4.1 卢爽 启蒙4.2 | Q11: 家长介绍 | R11: 1 | T11: 张文红 陈温心妈妈介绍 | U11: 兼 | V11: 1 | W11: 1 | X11: 1 | Y11: 59/课 | Z11: 22课时 | AA11: 1298 | AB11: 4.2日缴费
A12: 10 | B12: 4.1 | C12: 加拿大 | E12: 12 | G12: F7667C | H12: 陈旻泽 | I12: 7 | J12: 男 | K12: 学一点拼音 | L12: 否 | M12: 学一点拼音 | N12: 中文 | O12: 一上拼音iuv开始 | P12: 周虹 7:30 4.1 赵老师课堂 7:00 4.2 | Q12: 家长介绍 | R12: 1 | T12: 张文红 | U12: 兼 | V12: 1 | W12: 1 | X12: 1 | Y12: 59/课 | Z12: 22课时 | AA12: 1298 | AB12: 4.2日缴费
A13: 11 | B13: 4.1 | C13: 加拿大 | E13: 12 | F13: cherry | G13: ch9929926 | H13: 林珍铖 | I13: 11 | J13: 男 | K13: 有 | L13: 否 | M13: 会听中文和基本拼音 书写不行 | N13: 中文 | O13: 一上拼音aoe | P13: 任宏印 8:30 4.1 | Q13: 微信 | R13: 1 | T13: 何家昌 | U13: 0 | V13: 0 | W13: 0 | X13: 孩子不想学
A14: 12 | B14: 4.1 | C14: 加拿大 | E14: 12 | F14: cherry | G14: ch9929926 | H14: 林珍熙 | I14: 6 | J14: 男 | K14: 否 | L14: 否 | M14: 听得差点 不会拼音 不会书写 | N14: 中文 | O14: 一上拼音aoe | P14: 任宏印 8:30 4.1 | Q14: 微信 | R14: 1 | T14: 何家昌 | U14: 0 | V14: 0 | W14: 0 | X14: 孩子不想学
A15: 13 | B15: 4.1 | C15: 澳大利亚 | E15: 3 | F15: Jessica 婕 Z | G15: jie311869 | H15: Annabell Yu（余佳懿） | I15: 7 | J15: 女 | K15: 没学过拼音 | L15: 否 | M15: 国外中文学校二年级 | N15: 中文 | O15: 妈妈问得非常详细，还问了和悟空的对比，孩子口语一般，从拼音或者识字都可以，具体还要顾问跟妈妈在沟通确定 | P15: 任宏印15:30 4.1 赵老师课堂 15:00 4.10 | Q15: 微信 | R15: 3 | T15: 翁珊珊 | U15: 兼 | V15: 0 | W15: 0 | X15: 待定
A16: 14 | B16: 4.1 | C16: 澳大利亚 | E16: 3 | F16: Jessica 婕 Z | G16: jie311869 | H16: Gracelyn Yu（余婧曦） | I16: 9 | J16: 女 | K16: 没学过 | L16: 否 | M16: 国外中文学校四年级，停了两年 | N16: 中文 | O16: 理解力快，学的很好 一上拼音aoe，可以上拼音速成班 | P16: 徐晓晓15:30 4.1 chineseonlineE10 10:50 4.10 | Q16: 微信 | R16: 3 | T16: 翁珊珊 | U16: 兼 | V16: 0 | W16: 0 | X16: 年纪太小坐不住
A17: 15 | B17: 4.1 | C17: 西班牙 | E17: 6 | F17: 婷婷 | G17: tingouyang5 | H17: 翁多豪 | I17: 7 | J17: 男 | K17: 学过一点拼音 | L17: 否 | M17: 1.26日生日 拼音学过一点点，字只学过一到百 | N17: 中文 | O17: 会一点拼音，认识几个简单的字，拼音要拼读重新学 | P17: 徐晓晓17:00 4.1 第十三课堂22:20 | Q17: 微信 | R17: 1 | T17: 俞酉兰 | U17: 夜 | V17: 1 | W17: 1 | X17: 1 | Y17: 660/月 | Z17: 22课时 | AA17: 660 | AB17: 4.8日缴费
A18: 16 | B18: 4.1 | C18: 西班牙 | E18: 6 | F18: 婷婷 | G18: tingouyang5 | H18: 翁佳慧 | I18: 5.5 | J18: 女 | K18: 否 | L18: 否 | M18: 6.4日生日 没学过 | N18: 中文 | O18: 完全零基础，一上识字开始 | P18: 徐晓晓17:00 4.1 | Q18: 微信 | R18: 1 | T18: 俞酉兰 | U18: 0 | V18: 0 | W18: 0 | X18: 不回复了
A19: 17 | B19: 4.1 | C19: 澳大利亚 | D19: 悉尼 | E19: 3 | F19: Annie han | G19: annie9970466 | H19: 黎若诗 | I19: 8 | J19: 女 | K19: 否 | L19: 否 | M19: 当地学过一年，没有学过拼音，认识一些字 | N19: 中文 | O19: 学过一点但是几乎零基础，从一上识字开始 | P19: 徐晓晓17:30 4.1 二十课堂A19:00 4.7 | Q19: 电话 | R19: 3 | T19: 展旺 | U19: 兼 | V19: 0 | W19: 0 | X19: 排课时间隔太久，家长不回复了
A20: 18 | B20: 4.2 | C20: 美国 | D20: 东部 | E20: 12 | F20: 莫颜 | G20: moyanruoxi | H20: 李宇晨 | I20: 6 | J20: 男 | K20: 否 | L20: 是 | M20: 零基础 | N20: 中文 | O20: +1 917 822 7868双语，一上识字开始 | P20: 徐晓晓7:40 4.2 启蒙22:00 4.7 | Q20: 家长介绍 | R20: 3 | T20: 展旺 郑孝颖妈妈介绍 | U20: 兼 | V20: 0 | W20: 0 | X20: 还没完全拒绝，但缴费希望很小
A21: 19 | B21: 4.2 | C21: 加拿大 | D21: 温哥华 | E21: -15 | F21: josie | G21: q247995920 | H21: 李嘉文 | I21: 7 | J21: 女 | K21: 无 | L21: 否 | M21: 个别字会认，会说，有的词不懂意思 | N21: 中文 | O21: 15000787892 孩子程度很好，爱上课很积极，拼音aoe学了a的四个声调 | P21: 任宏印8:00 4.2 三十六课堂张老师 4.7 陆老师课堂陆春美 5：30 5.2 | Q21: 电话 | R21: 2 | T21: 石富贵 | U21: 兼 | V21: 1 | W21: 1 | X21: 1 | Y21: 90/课 | Z21: 22 | AA21: 3960和由由一起 | AB21: 4.2日缴费
A22: 20 | B22: 4.2 | C22: 加拿大 | D22: 温哥华 | E22: 15 | F22: 林丹 | G22: lindan1987217 | H22: Angela2 | I22: 5 | J22: 女 | K22: 是 | L22: 否 | M22: 有学过，但是拼音很差，到现在字母都认不全；想要耐心幽默，赏罚分明的老师 | N22: 中文 | O22: 有拼音基础，先快速复习一下单韵母，再学习复韵母 | P22: 周虹 7:30 4.2 黄莺6:00 4.11 | Q22: 代理 | R22: 白 | T22: 陈静 | U22: 兼 | V22: 1 | W22: 1 | X22: 99团购 | Y22: 99 | Z22: 4.14缴费 | AA22: 后面缴费一对三¥1738 22节课 | AC22: 4.24日缴费，4.30计费
A23: 21 | B23: 4.2 | C23: 加拿大 | D23: 温哥华 | E23: 15 | F23: 林丹 | G23: lindan1987217 | H23: Leo | I23: 7 | J23: 男 | K23: 是 | L23: 否 | M23: 有学过，但是拼音很差，到现在字母都认不全；想要耐心幽默，赏罚分明的老师 | N23: 中文 | O23: 有拼音基础，先快速复习一下单韵母，再学习复韵母 | P23: 周虹 7:30 4.2 第十二课堂5:50钱程 4.7 | Q23: 代理 | R23: 白 | T23: 陈静 | U23: 夜 | V23: 1 | W23: 1 | X23: 99团购 | Y23: 99 | Z23: 4.10缴费 | AA23: 后面缴费一对三¥1738 22节课 | AC23: 4.24缴费
A24: 上个月算过人数 | B24: 4.2 | C24: 美国 | D24: 尔湾 | E24: 15 | F24: 阿康 | G24: akamg789506 | H24: 徐菏阳 | I24: 8 | J24: 女 | K24: 学过 | L24: 否 | M24: 写读比较差 | N24: 中文 | O24: 程度较好，识字量比较大，建议从一上八单元开始学习 | P24: 周虹 8:30 3.26 ChineseOnline E 9：40 | Q24: 家长介绍 | R24: 2 | T24: 平金军 付吉夏家长介绍 | U24: 白 | V24: 1 | W24: 1 | X24: 1 | Y24: 53/课 | Z24: 130 | AA24: 1849 | AB24: 4.13日缴费
A25: 上个月算过人数 | B25: 4.3 | C25: 美国 | D25: 尔湾 | E25: 15 | F25: 阿康 | G25: akamg789506 | H25: 徐沐阳 | I25: 8 | J25: 女 | K25: 学过 | L25: 否 | M25: 写读比较差 | N25: 中文 | O25: 和姐姐一起测的 | P25: 周虹 8:30 3.26 ChineseOnline E 9：40 | Q25: 家长介绍 | R25: 2 | T25: 平金军 | U25: 白 | V25: 1 | W25: 1 | X25: 1 | Y25: 53/课 | Z25: 130 | AB25: 4.13日缴费
A26: 22 | B26: 4.2 | C26: 加拿大 | D26: 温哥华 | E26: 15 | F26: 惠怡 | G26: huiyiq | H26: Emma4 | I26: 4.5 | J26: 女 | K26: 否 | L26: 否 | M26: 在家讲中文，认识一点中文字，不会拼音 | N26: 中文 | O26: 没有基础，一上拼音开始 | P26: 周虹 8:00 4.2 | Q26: 代理 | R26: 白 | T26: 陈静 | U26: 0 | V26: 0 | W26: 0 | X26: 觉得课程一般 推荐一下启蒙课
A27: 23 | B27: 4.2 | C27: 美国 | D27: 加州 | E27: 15 | F27: Natalie | G27: Natalielook | H27: 陈曦琳 | I27: 7.5 | J27: 女 | K27: 无 | L27: 否 | M27: 学了中华字经认字，不会写字，不会拼音，家里讲广东话，课后班讲普通话 | N27: 中文 | O27: 一上拼音开始学【测试课上了aoe】 | P27: 周虹 9:30 4.2 陆老师课堂7:00 4.4 | Q27: 家长介绍 | R27: 2 | T27: 赵国花 刘奕晓麻麻推荐 | U27: 兼 | V27: 0 | W27: 0 | X27: 孩子没有融入，不是很有吸引力
A28: 24 | B28: 4.2 | C28: 加拿大 | D28: 温哥华 | E28: 15 | F28: 元宝儿 | G28: leozhou1343 | H28: 周茹墨加 | I28: 7 | J28: 女 | K28: 无 | L28: 否 | M28: 少量认字，能说能听（希望老师能够带动气氛些） | N28: 中文 | O28: 中文 一上拼音开始学【测试课上了aoe】 | P28: 周虹 10:00 4.2 | Q28: 电话 | R28: 2 | T28: 石富贵 | U28: 0 | X28: 试课老师只露了一点脸，家长觉得很不好
A29: 25 | B29: 4.2 | C29: 美国 | D29: 加州 | E29: 15 | F29: 苏芳Susan | G29: sufang205462 | H29: 曾心怡 | I29: 9 | J29: 女 | K29: 有 | L29: 否 | M29: 2年级/1年级 | N29: 中文 | O29: 一上的五、六单元开始学习。 | P29: 周虹 10.：30 4.2 Chineseonline F 10:20 4.3 | Q29: 微信 | R29: 2 | T29: 王晨 | U29: 白 | V29: 0 | W29: 0 | X29: 价格贵
A30: 26 | B30: 4.2 | C30: 加拿大 | D30: 温哥华 | E30: 15 | F30: josie | G30: q247995920 | H30: 由由 | I30: 5 | J30: 男 | K30: 无 | L30: 否 | M30: 零基础，会说，有的词不懂意思 | N30: 启蒙 | P30: 卢爽8:30 4.2 | Q30: 电话 | R30: 2 | T30: 石富贵 | U30: 兼 | V30: 1 | W30: 1 | X30: 1 | Y30: 90/课 | Z30: 22 | AA30: 和李嘉文一起交 | AB30: 4.2日缴费
A31: 27 | B31: 4.2 | C31: 加拿大 | D31: 温哥华 | E31: 15 | F31: michelle | G31: 13622367933 | H31: 龙龙 | I31: 5.5 | J31: 男 | K31: 无 | L31: 否 | M31: 会听会说，口语流利 | N31: 启蒙 | P31: 卢爽8:00 4.2 | Q31: 电话 | R31: 2 | T31: 石富贵 | U31: 兼 | V31: 1 | W31: 1 | X31: 1 | Y31: 90/课 | Z31: 22 | AA31: 1980 | AB31: 4.2日缴费
A32: 28 | B32: 4.2 | C32: 加拿大 | D32: 温哥华 | E32: 15 | F32: elaine | G32: 13602772434 | H32: 峻峻 | I32: 5 | J32: 男 | K32: 无 | L32: 否 | M32: 零基础，会说，有的词不懂意思 | N32: 启蒙 | P32: 卢爽8:30 4.2 | Q32: 电话 | R32: 2 | T32: 石富贵 | U32: 兼 | V32: 1 | W32: 1 | X32: 1 | Y32: 90/课 | Z32: 22 | AA32: 1980 | AB32: 4.2日缴费
A33: 29 | B33: 4.2 | C33: 新西兰 | E33: 5 | G33: Helenxiaoyi | H33: 蔡尚均 | I33: 6 | J33: 男 | K33: 否 | L33: 否 | M33: 中文交流没问题，词汇量不大，没有学过拼音，可以从aoe开始学 | N33: 中文 | O33: 上课情况良好，需要老师不停的提醒，测试学了aoe中得a以及4个声调 | P33: 任宏印14:30 4.2 赵老师课堂 1:00 4.3 | Q33: 家长介绍 | R33: 1 | T33: 刘巧芹 徐子睿妈妈推荐 | U33: 兼 | V33: 0 | W33: 0 | X33: 孩子太小了，好动
A34: 30 | B34: 4.2 | C34: 美国 | D34: 加州 | E34: 15 | F34: 一个表情 | G34: lunanana1 | H34: 程浩楠 | I34: 3.5 | K34: 无 | L34: 否 | M34: 没有学习过中文，中文交流能力一半一半 | N34: 启蒙 | O34: 不认字，没有学习过中文，中文程度一般 | P34: 卢爽11:20 4.2 | Q34: 微信 | R34: 2 | T34: 高翱翔 | U34: 兼 | V34: 0 | W34: 0 | X34: 妈妈也是老师，来蹭课的
A35: 31 | B35: 4.2 | C35: 加拿大 | D35: 温哥华 | E35: 15 | F35: 元宝儿 | G35: leozhou1343 | H35: 周茹馨羽 | I35: 5 | K35: 无 | L35: 否 | M35: 不识字，能说能听（希望老师能够带动气氛些） | N35: 启蒙 | P35: 卢爽10:30 4.2 | Q35: 电话 | R35: 2 | T35: 石富贵 | U35: 兼 | V35: 0 | W35: 0 | X35: 小的还喜欢的，但是大的不学小的也不学了
A36: 32 | B36: 4.2 | C36: 加拿大 | D36: 温哥华 | E36: 15 | F36: 闵江 | G36: mjmichelle | H36: 何如冰和妹妹 | I36: 5 | N36: 启蒙 | P36: 卢爽10:30 4.2 | Q36: 代理 | R36: 白 | T36: 陈静 | U36: 兼 | V36: 0 | W36: 0 | X36: 不回信息
A37: 33 | B37: 4.2 | C37: 加拿大 | D37: 温哥华 | E37: 15 | F37: Kelly | G37: kellymeng | H37: 张诗淇 | I37: 4 | N37: 启蒙 | P37: 卢爽10:30 4.2 | Q37: 代理 | R37: 白 | T37: 陈静 | U37: 兼 | V37: 0 | W37: 0 | X37: 不喜欢 | Y37: 99团购
A38: 34 | B38: 4.2 | C38: 西班牙 | D38: 巴塞罗那 | E38: 6 | F38: 愿 | G38: violet-isa | H38: 高兴 | I38: 6 | J38: 男 | M38: 老学生试读数学课 | N38: 数学 | P38: 数学课皋老师3.31 4.7 | Q38: 报第二门课 | R38: 3 | T38: 王可 | U38: 兼 | V38: 1 | W38: 1 | X38: 1 | Y38: 56/课 | Z38: 65+3+7 | AA38: 3584 | AB38: 4.1日缴费
A39: 35 | B39: 4.2 | C39: 加拿大 | D39: 温哥华 | E39: 15 | F39: studio.chloey | G39: guluyu | H39: 严顗安 | I39: 4 | N39: 启蒙 | P39: 卢爽10:30 4.2 | Q39: 代理 | R39: 白 | T39: 陈静 | U39: 兼 | V39: 0 | W39: 0 | X39: 试一下其他机构 | Y39: 99团购
A40: 36 | B40: 4.2 | C40: 西班牙 | E40: 6 | F40: 微 | G40: Weiwei28509 | H40: 吴宸宇 | I40: 5 | J40: 男 | K40: 否 | L40: 否 | M40: 没学过中文 | N40: 中文 | O40: 口齿稍微有点不清，但是表达没问题，中文交流可以;一上识字开始或启蒙开始 建议最好上启蒙课，但是不知道能不能接受价格 | P40: 徐晓晓18:30 4.2 二十课堂A19:00 4.7 | Q40: 微信 | R40: 1 | T40: 何家昌 | U40: 兼 | V40: 1 | W40: 1 | X40: 1 | Y40: 56/课 | Z40: 65 | AA40: 3640 | AB40: 4.4日缴费
...

Sheet 2020.3
A2: 序号 | B2: 测试时间 | C2: 国家 | D2: 城市 | E2: 时差 | F2: 家长微信名 | G2: 家长微信 | H2: 学生姓名 | I2: 年龄 | J2: 性别 | K2: 有没有学过拼音 | L2: 是否需要双语老师 | M2: 家长自述程度及学习需求 | N2: 学习课程 | O2: 测试结果 | P2: 排课安排 | Q2: 来源 | R2: 组别 | S2: 业务员 | T2: 排课分组 | U2: 是否在读 | V2: 是否缴费 | W2: 失败原因 | X2: 课程单价 | Y2: 折扣 | Z2: 实收 | AA2: 首次收费时间
A3: 1 | B3: 3.1 | C3: 美国 | D3: 特拉华州 | E3: 13 | F3: Tina免税玩购·美欧店 | G3: gracesong2012 | H3: Andy Wu | I3: 10 | J3: 男 | K3: 有 | L3: 否 | M3: 数学国内三下到四上之间水平 | N3: 数学 | O3: 数学课 | P3: 数学课04 9:00 3.1 | Q3: 微信 | R3: 3 | S3: 王可 | T3: 兼 | U3: 1 | V3: 1 | W3: 1 | X3: 53/课 130课 | Z3: 6890 | AA3: 2.29日缴费
A4: 2 | B4: 3.1 | C4: 美国 | D4: 东部 | E4: 13 | F4: Sophie | G4: huakaifugui2020 | H4: 孙一文 | I4: 13 | M4: 理解能力强，读字速度慢，一下到二上之间 | N4: 中文 | O4: 周末班 | P4: 滕柳星 9:00 3.1 | Q4: 微信 | R4: 3 | S4: 王可 | T4: 0 | U4: 0 | V4: 0 | W4: 时间定不好
A5: 3 | B5: 3.1 | C5: 加拿大 | D5: 多伦多 | E5: 13 | F5: 秦窗窗 | G5: qinchuanger | H5: 姜子欣 | I5: 11 | M5: 2008.7.15 中文普通话交流无障碍，读写困难 | N5: 中文 | O5: 会拼音，中文词汇表达会有点困难，词汇量两百左右，建议从一上中后段开始学 | P5: 徐晓晓8:00 3.2 ChineseonlineH8:00 3.5 ChineseonlineE8:00 3.10 chineseonlineH8:20 3.19 | Q5: 家长介绍 | R5: 2 | S5: 赵国花 王梓珂妈妈介绍 | T5: 白 | U5: 1 | V5: 1 | W5: 1 | X5: 59/课 | Z5: 1298 | AA5: 3.19日缴费
A6: 4 | B6: 3.3 | C6: 西班牙 | E6: 7 | F6: caili sun | G6: X690569006 | H6: 詹欣怡 | M6: 一上中间，拼音不错 | N6: 中文 | O6: 数学课 | P6: 第一课堂第五节课 | Q6: 报第二门课 | R6: 1 | S6: 何家昌 | T6: 夜3组 | U6: 1 | V6: 1 | W6: 1 | X6: 650/月 | Z6: €1018 | AA6: 3.3日缴费
A7: 5 | B7: 3.3 | C7: 西班牙 | E7: 7 | F7: caili sun | G7: X690569006 | H7: 詹可怡 | M7: 一上中间，拼音不错 | N7: 中文 | O7: 数学课 | P7: 第二十一课堂第三节课 | Q7: 报第二门课 | R7: 1 | S7: 何家昌 | T7: 夜3组 | U7: 1 | V7: 1 | W7: 1 | X7: 650/月 | AA7: 3.3日缴费
A8: 6 | B8: 3.3 | C8: 美国 | D8: 东部 | E8: 13 | F8: Serena | G8: serenajian | H8: 简斯若 | I8: 6 | M8: 中文流利，不会拼音 | N8: 中文 | P8: 滕柳星8:00 3.3 天娃课堂01 8:00 3.7 | Q8: 家长介绍 | R8: 2 | S8: 敖雪家长介绍王晨 | T8: 兼 | U8: 0 | V8: 0 | W8: 没时间，一周三节排不了
A9: 7 | B9: 3.3 | C9: 澳大利亚 | E9: 3 | F9: Amy是曦妈 | G9: z531002025 | H9: 郑乐曦 | I9: 4.5 | M9: 启蒙课 | N9: 启蒙 | P9: 卢老师启蒙课17:00 2.29 3.1 | Q9: 家长介绍 | R9: 1 | S9: 张文红 李乐轩妈妈介绍 | T9: 兼 | U9: 1 | V9: 1 | W9: 1 | X9: 79/课 | Z9: 1738 | AA9: 3.3日缴费 | AB9: 3.2-4.20日 一周三次
