Workbook

Sheet 中文新生排课表
A1: 登记日期 | B1: 国家 | C1: 时差 | D1: 业务员 | E1: 组别 | F1: 学生姓名 | G1: 年龄 | H1: 家长自述程度及学习需求 | I1: 课程类型 | J1: 测试结果/预排年级 | K1: 业务员备注 | L1: 上课时间（中国时间） | M1: 排课安排（老师填写）
A2: 43963.292 | B2: 美国 | C2: 12 | D2: 丁阮琪 | E2: 2 | F2: 妮妮 | G2: 9 | H2: 不需要双语老师，想上专门针对作文的中文课 | J2: 想学专门针对作文的中文课，拼音学了，识字量还可以，家长自称已有四年级水平 | L2: 国内早上7:00 | M2: 预排兼职 已发 没有人接
A3: 5.18 | B3: 美国 | C3: 15 | D3: 程蕾 | E3: 3 | F3: Eva | G3: 9 | H3: 家长想要重点学习写作和阅读 | J3: 写作阅读课堂 | L3: 国内周二周四早上7:30后 | M3: 预排兼职 已发 没有人接
A4: 5.22 | B4: 澳大利亚 | C4: 2 | D4: 程蕾 | E4: 3 | F4: Alex | G4: 10 | H4: 认识简单的字，拼音有学过，妈妈自己教的，可以中文交流， 二次试读，希望安排专业一点的老师，一对三 | J4: 拼音an en un ang eng ung 开始 | L4: 正式上课周六周日下午12:00后 | M4: 家长在找可以一起周末搭班的学生
A5: 5.3 | B5: 澳大利亚 | C5: 2 | D5: 张文红 | E5: 3 | F5: 邱宇新 | G5: 12 | H5: 拼音有学过，复韵母不太会，可以中文交流 | J5: 拼音复韵母开始 | L5: 国内下午16:00后 | M5: 目前没有合适的班级
A6: 6.1 | B6: 美国 | C6: 15 | D6: 王可 | E6: 3 | F6: 李梓墨 | G6: 11 | I6: 周末班 | J6: 二下一单元，学生爱笑，性格很好 | M6: 一个学生目前无法开班
A7: 6.9 | B7: 意大利 | C7: 6 | D7: 俞酉兰 | E7: 0 | F7: 邓洁雅 | G7: 8 | I7: 一对四 | J7: 二下 | L7: 国内下午4:00左右 | M7: 一个学生目前无法开班
A8: 6.11 | B8: 澳大利亚 | C8: 2 | D8: 王可 | E8: 3 | F8: 黎嘉晗 | G8: 7 | J8: 建议拼音学起，孩子比较很害羞，老师要多加引导。认字课的字都认得。 | L8: 下午2:00 | M8: 预排I课堂 14:10 7.8 课程顾问说家长未回复
A9: 6.17 | B9: 美东 | C9: 12 | D9: 翁珊珊 | E9: 3 | F9: 郑芷妍 | G9: 7 | H9: 下周放假再安排班级 | I9: 一对四 | J9: 听说没问题，零基础，会写一两个字，没学过拼音 | L9: 国内时候晚上10:30 | M9: 课程顾问说暂时不排，学生还没有时间
A10: 6.2 | B10: 澳大利亚 | C10: 2 | D10: 王可 | E10: 3 | F10: 游智煊 | G10: 6 | I10: 一对四 | J10: 学生程度一般，朗读不够流畅，家长想上一对四的课程，建议从拼音bpmf开始学习拼读。 | L10: 中国下午6点钟 | M10: 一个学生目前无法开班
A11: 6.25 | B11: 美西 | C11: 15 | D11: 王晨 | F11: 吕蔓舒 | G11: 8 | H11: 有秩序的班级 | I11: 一对四 | J11: 建议二年级上册3单元 | K11: 排好就缴费，急急急急急！ | L11: 国内早上11点 | M11: 这个时间点目前没有班级可以插班
A12: 6.27 | B12: 美国 | C12: 15 | D12: 张霞 | E12: 3 | F12: 陈凯文 | G12: 9 | I12: 一对四 | J12: 二年级一单元 | L12: 国内早上6-8点半 | M12: 课程顾问说家长未回复
A13: 6.16 | B13: 意大利 | C13: 6 | D13: 俞酉兰 | E13: 0 | F13: 董振钦 | G13: 6 | I13: 一对六 | J13: 天地人 开始 | L13: 国内晚上9:00 | M13: 目前没有可以插的班级，一个不能开班
A14: 7.1 | B14: 澳大利亚 | C14: 2 | D14: 王可 | F14: 陈楚妍 | G14: 11 | I14: 一对三 | J14: 学生发音标准，朗读较流畅，识字量不错，建议从二上三四单元开始学起 | L14: 国内下午2点之后 | M14: 一对三，两个人开班
A15: 7.3 | B15: 美国中部 | C15: 15 | D15: 毛益丹 | F15: 陈凯琳 | G15: 10岁 | H15: 妈妈说是一二年级的水平 | I15: 一对四 | J15: 建议从二下开始学习，学生发音标准，朗读流畅，识字量大 | L15: 家长还没确定好时间 | M15: /
A16: 7.2 | B16: 美东 | C16: 12 | D16: 王可 | F16: 王灿宇 | G16: 7 | I16: 一对一 | J16: 拼音开始 | L16: 早上7点 | M16: 兼职信息已发
A17: 7.7 | B17: 美西 | C17: 15 | D17: 翁珊珊 | F17: 王姝曼 | G17: 8 | H17: 学过拼音很基础 | I17: 一对三 | J17: 一上七八单元，中文沟通流利 | K17: 已缴费 | L17: 早上七点半 | M17: 一对三的课程，无法插班，一个人无法开班
A18: 7.7 | B18: 美西 | C18: 15 | D18: 翁珊珊 | F18: 王姝慈 | G18: 6 | H18: 学过拼音很基础 | I18: 一对三 | J18: 拼音aoe开始，不太喜欢说话，认识少量字，不会拼音 | K18: 已缴费 | L18: 早上七点半 | M18: 一对三课程已发兼职
A19: 7.9 | B19: 美西 | C19: 15 | D19: 胡东东 | F19: 王文源 | G19: 6 | H19: 从拼音开始再学习汉字一周三节 | I19: 一对四 | J19: 拼音开始，从启蒙转班 | K19: 已缴费 | L19: 早上7点到11点 | M19: 目前一个人，等第二个人开班
A20: 7.8 | B20: 美东 | C20: 12 | D20: 翁珊珊 | F20: 陈冠燊 | G20: 10 | H20: 拼音有时候会声调读不准，需要老师纠正 | I20: 一对四 | J20: 一上第五单元开始学 | K20: 排好就缴费 | L20: 早上7点到9点半
A21: 7.8 | B21: 美中 | C21: 13 | D21: 丁阮琪 | F21: 王诗涵 | G21: 7 | H21: 从拼音开始学起 | I21: 一对三 | J21: 建议从拼音开始学起，理解和表达可以，识字量不多。 | K21: 和王诗杰一个班级 | L21: 早上7点-9点之间 | M21: 一对三课程已发兼职
A22: 7.8 | B22: 美中 | C22: 13 | D22: 丁阮琪 | F22: 王诗杰 | G22: 5 | H22: 从拼音开始学起 | I22: 一对三 | J22: 零基础，aoe开始，三声读不标准，跟老师读完就忘记，年龄小，不够专注 | K22: 和王诗涵一个班级 | L22: 早上7点-9点之间 | M22: 一对三课程已发兼职

Sheet 试读跟进表2020.07
A1: 排课日期 | B1: 国家 | C1: 时差 | D1: 业务员 | E1: 组别 | F1: 学生姓名 | G1: 年龄 | H1: 预排年级 | I1: 课程类型 | J1: 上课时间（中国时间） | K1: 排课安排（老师填写） | L1: 试读日期 | M1: 课程 | O1: 学区 | P1: 是否到课（顾问填写） | Q1: 缴费
A2: 44012 | B2: 美西 | C2: 13 | D2: 程蕾 | F2: Tina | G2: 6 | H2: 拼音学过一点，识字量30 | I2: 一对四 | J2: bpmf，学习拼读 | K2: I课堂 8:20 7-1 | L2: 44013 | M2: 中文 | N2: =TRIM(F2) -> Tina | O2: 白 | P2: 是 | Q2: =IFERROR(VLOOKUP(N2,Sheet1!A:B,2,FALSE),"zhaobudao") -> zhaobudao
A3: 44012 | B3: 美西 | C3: 15 | D3: 王晨 | F3: 欧阳书泰 | G3: 10 | H3: 有秩序的班级 | I3: 一对三/一对四 | J3: 建议二年级下册一单元 | K3: H课堂 9:40 7-1 | L3: 44013 | M3: 中文 | N3: =TRIM(F3) -> 欧阳书泰 | O3: 白 | P3: 是 | Q3: =IFERROR(VLOOKUP(N3,Sheet1!A:B,2,FALSE),"zhaobudao") -> 是
A4: 44012 | B4: 美东 | C4: 12 | D4: 展旺 | F4: 曹天乐 | G4: 12 | H4: 国内早上七八点，九点之前结束就可以 | I4: 一对四 | J4: 可以放在程度比较好的班级里，建议一年级下册开始学 | K4: H课堂 8:20 7-1 | L4: 44013 | M4: 中文 | O4: 白
A5: 44012 | B5: 美东纽约 | C5: 12 | D5: 毛益丹3 | F5: Avera Lu | G5: 7岁 | H5: 需要老师讲英文，要找一个好的老师，和梁凯琪，甄子帅排在一起 | I5: 一对一，半小时 | J5: 零基础，从拼音aieiui开始，需要双语老师 | K5: 阮洪慧；言智19；8:20开始；7.1 | L5: 44013 | M5: 中文 | N5: =TRIM(F5) -> Avera Lu | O5: 兼 | P5: 是 | Q5: =IFERROR(VLOOKUP(N5,Sheet1!A:B,2,FALSE),"zhaobudao") -> zhaobudao
A6: 44013 | B6: 美东 | C6: 12 | D6: 高翱翔 | F6: 林卡卡 | G6: 8 | H6: 零基础开始，之前测试过，现在排正式课，在家中文交流 | I6: 一对四 | J6: 拼音开始学习 | K6: 宋老师课堂 7.2 8：10 | L6: 44014 | M6: 中文 | N6: =TRIM(F6) -> 林卡卡 | O6: 兼 | P6: 是 | Q6: =IFERROR(VLOOKUP(N6,Sheet1!A:B,2,FALSE),"zhaobudao") -> 是
A7: 44013 | B7: 美东 | C7: 12 | D7: 杨斌 | F7: 琪伟 | G7: 8 | I7: 一对四 | J7: 建议从拼音课开始学起，可以交流，识字量少，很活泼 | K7: 宋老师课堂 7.2 8：10 | L7: 44014 | M7: 中文 | O7: 兼
A8: 44013 | B8: 美国 | D8: 展旺 | F8: 陈宇翔 | I8: 一对四 | J8: aoe开始学 | K8: 宋老师课堂 7.2 8：10 | L8: 44014 | M8: 中文 | O8: 兼
A9: 44013 | B9: 美东 | C9: 12 | D9: 毛益丹 | F9: 蓝天 | G9: 6岁 | H9: 有学了一点中文，刚学拼音，会基本的中文交流，没上幼儿园前一直说中文，上了幼儿园后和同学们习惯说英文 | I9: 一对四 | J9: 孩子表现非常好，记忆力也很好，之前也学过中文，建议从拼音一年级上册第二单元《a o e》开始学，妈妈意向高，孩子也愿意学。 | K9: 言智38 9：00 7.2 言智 36 9:00 7.6 | L9: 44014 | M9: 中文 | N9: =TRIM(F9) -> 蓝天 | O9: 兼 | P9: 是 | Q9: =IFERROR(VLOOKUP(N9,Sheet1!A:B,2,FALSE),"zhaobudao") -> 是
A10: 44013 | B10: 美东 | C10: 12 | D10: 王可 | F10: 张明娜 | G10: 7 | H10: 零基础开始 | I10: 一对四 | K10: 言智38 9：00 7.2 | L10: 44014 | M10: 中文 | O10: 兼
A11: 44013 | B11: 美东 | C11: 12 | D11: 展旺 | F11: 苗牛牛 | G11: 10 | H11: 和蓝天， | I11: 一对四 | J11: 建议从拼音课开始，中文理解和表达很好，认字量一般，学生有时爱跑题需要老师去抓住学生的注意力。 | K11: 言智38 9：00 7.2 | L11: 44014 | M11: 中文 | O11: 兼
A12: 44013 | B12: 美东 | C12: 12 | D12: 翁珊珊 | F12: 陈冠燊 | G12: 10 | H12: 一上五单元《画》开始上 需要排在学生程度好的班级 | I12: 一对四 | J12: 一上五单元《画》 | K12: 三十九课堂 21:40 7-1 | L12: 44014 | M12: 中文 | N12: =TRIM(F12) -> 陈冠燊 | O12: 夜1 | P12: 是 | Q12: =IFERROR(VLOOKUP(N12,Sheet1!A:B,2,FALSE),"zhaobudao") -> zhaobudao
A13: 44013 | B13: 加拿大 | C13: 15 | D13: 俞酉兰 | F13: 潘昱淳 | G13: 10岁 | I13: 一对四 | J13: 一下二单元 | K13: A课堂 7:40 7-2 | L13: 44014 | M13: 中文 | O13: 白
A14: 44014 | B14: 美国东部 | C14: 12 | D14: 展望 | F14: Larry | G14: 7 | H14: 学过一年中文，中间断了半年，拼音没学过，听得懂中文，但是不太会说 | I14: 一对一 | J14: bpmf开始 | K14: 宋老师课堂 8:30 7-3 | L14: 44015 | M14: 中文 | O14: 兼
A15: 44014 | B15: 美国西部 | C15: 15 | D15: 任宏印 | F15: 谢恩耀 | G15: 7 | H15: 学生比较害羞，简单的生字认识，建议从拼音开始上课。 | I15: 一对四 | J15: 从拼音开始上课。 美国时间晚上7：30中国时间7月1号开始上课早上10:30 | K15: Z课堂 10:20 7-2 | L15: 44014 | M15: 中文 | N15: =TRIM(F15) -> 谢恩耀 | O15: 白 | P15: 是 | Q15: =IFERROR(VLOOKUP(N15,Sheet1!A:B,2,FALSE),"zhaobudao") -> zhaobudao
A16: 44014 | B16: 美国西部 | C16: 15 | D16: 任宏印 | F16: 泽宇 | G16: 7 | H16: 测试aoe ivu开始 建议拼音aoe开始学习，零基础，五岁去的美国，发音很标准，孩子特别好动 | I16: 一对四 | J16: 从拼音开始上课。 美国时间晚上7：30中国时间7月1号开始上课 早上10:30 | K16: Z课堂 10:20 7-2 | L16: 44014 | M16: 中文 | N16: =TRIM(F16) -> 泽宇 | O16: 白 | P16: 是 | Q16: =IFERROR(VLOOKUP(N16,Sheet1!A:B,2,FALSE),"zhaobudao") -> zhaobudao
A17: 44014 | B17: 美东 | C17: 12 | D17: 刘巧芹 | F17: 李乐芯 | G17: 5.5 | H17: 拼音aoe开始学 | I17: 一对四，国内周二到周六 | K17: J课堂 9:00 7-3 | L17: 44015 | M17: 中文 | N17: =TRIM(F17) -> 李乐芯 | O17: 白 | P17: 是 | Q17: =IFERROR(VLOOKUP(N17,Sheet1!A:B,2,FALSE),"zhaobudao") -> 是
A18: 44014 | B18: 美东 | C18: 12 | D18: 刘巧芹 | F18: 陈睿萱 | G18: 6 | H18: 拼音aoe开始学 | I18: 一对四，国内周二到周六 | K18: J课堂 9:00 7-3 | L18: 44015 | M18: 中文 | N18: =TRIM(F18) -> 陈睿萱 | O18: 白 | P18: 是 | Q18: =IFERROR(VLOOKUP(N18,Sheet1!A:B,2,FALSE),"zhaobudao") -> 是
A19: 44014 | B19: 美东 | C19: 12 | D19: 刘巧芹 | F19: 朱紫晴 | G19: 快七岁 | H19: 拼音aoe开始学 | I19: 一对四，国内周二到周六 | K19: J课堂 9:00 7-3 | L19: 44015 | M19: 中文 | N19: =TRIM(F19) -> 朱紫晴 | O19: 白 | P19: 是 | Q19: =IFERROR(VLOOKUP(N19,Sheet1!A:B,2,FALSE),"zhaobudao") -> 是
A20: 44014 | B20: 美国 | C20: 12 | D20: 张霞 | F20: 童童 | G20: 10 | H20: 零基础 | I20: 一对四 | J20: 直接从拼音开始 | K20: 言智38 7.2 22：00—22：30 | L20: 44014 | M20: 中文 | N20: =TRIM(F20) -> 童童 | O20: 兼 | P20: 是 | Q20: =IFERROR(VLOOKUP(N20,Sheet1!A:B,2,FALSE),"zhaobudao") -> 是
A21: 44014 | B21: 美国 | C21: 12 | D21: 张霞 | F21: 朴智美 | G21: 11 | H21: 零基础 | I21: 一对四 | J21: 直接从拼音开始 | K21: 言智38 7.2 22：00—22：30 | L21: 44014 | M21: 中文 | N21: =TRIM(F21) -> 朴智美 | O21: 兼 | P21: 是 | Q21: =IFERROR(VLOOKUP(N21,Sheet1!A:B,2,FALSE),"zhaobudao") -> 是
A22: 44014 | B22: 美国 | C22: 12 | D22: 张霞 | F22: 郑琳 | G22: 7 | H22: 希望老师带动力强，上课内容丰富一点 | I22: 一对四 | J22: 建议从拼音开始，能听懂一点点 | K22: 言智39 21:30~22:00 7.2 | L22: 44014 | M22: 中文 | N22: =TRIM(F22) -> 郑琳 | O22: 兼 | P22: 是 | Q22: =IFERROR(VLOOKUP(N22,Sheet1!A:B,2,FALSE),"zhaobudao") -> zhaobudao
A23: 44015 | B23: 美西 | C23: 15 | D23: 毛益丹3 | E23: 3 | F23: 曾博 | G23: 7岁 | H23: 一年级，和哥哥曾晰一起上过一年的周末中文学校，学的是二年级中文，没有基础，没学过拼音，不会笔画笔顺，想利用暑假从头开始学。会基本中文交流 | I23: 一对四，半小时；一周五天 | J23: 建议aoe开始学习，拼音认识几个，喜欢说话，配合老师，发音非常不标准 | K23: 言智41 7:00-7:30 7.4 | L23: 44016 | M23: 中文 | N23: =TRIM(F23) -> 曾博 | O23: 兼 | P23: 是 | Q23: =IFERROR(VLOOKUP(N23,Sheet1!A:B,2,FALSE),"zhaobudao") -> zhaobudao
A24: 44015 | B24: 美西 | C24: 15 | D24: 毛益丹3 | F24: 王子嘉 | G24: 6.5岁 | H24: 学过拼音，但是没学好，不介意孩子再学拼音，可以基本的中文交流 | J24: 学生其实拼音单独的可以完全读下来，但是拼读不太会。认字程度在一上七单元。妈妈想要拼音从头学起。 | K24: 言智41 7:00-7:30 7.4 | L24: 44016 | M24: 中文 | N24: =TRIM(F24) -> 王子嘉 | O24: 兼 | P24: 是 | Q24: =IFERROR(VLOOKUP(N24,Sheet1!A:B,2,FALSE),"zhaobudao") -> 是
A25: 44015 | B25: 美西 | C25: 15 | D25: 毛益丹3 | F25: 小恩 | G25: 7岁 | H25: 学过一册双双教材，认识一些字，不太擅长说句子，家里说中文，孩子听得懂。笔画也学了，想学拼音 | J25: 从拼音课开始，理解表达一般。 | K25: z课堂 10:20 7-3 | L25: 44015 | M25: 中文 | N25: =TRIM(F25) -> 小恩 | O25: 兼 | P25: 是 | Q25: =IFERROR(VLOOKUP(N25,Sheet1!A:B,2,FALSE),"zhaobudao") -> 是
A26: 44015 | B26: 美国 | C26: 15 | D26: 王可 | E26: 3 | F26: 冯浩齐 | G26: 7 | J26: 一上第八单元开始学起，读没问题，句子不理解，不会组词和造句，孩子比较顽皮坐不住。双语 | K26: 范老师课堂 6:20 7.3 | L26: 44015 | M26: 中文 | O26: 兼
A27: 44015 | B27: 美国 | D27: 展旺 | F27: irina chen | I27: 一对四 | J27: 建议从一上第四单元开始，可以理解中文但是不怎么会说，家长想要学生多说话。拼音中的ang ong eng发音不太好，有点害羞。 | K27: 范老师课堂 6:20 7.3 | L27: 44015 | M27: 中文 | O27: 兼
A28: 44015 | B28: 加拿大 | C28: 15 | D28: 李波 | E28: 1 | F28: 戴妮 | G28: 10 | H28: 数学 初中 | K28: 数学课堂 7月4日 8:00-8:30 | L28: 44016 | M28: 数学 | O28: 兼
A29: 44015 | B29: 美国 | C29: 12 | D29: 刘箫 | E29: 1 | F29: 洪安恬 | G29: 11 | H29: 数学 | I29: 1对1 | J29: 早上8点到9点 | K29: 黄老师上课课堂21:00 7-4 | L29: 44016 | M29: 数学 | O29: 兼
A30: 44015 | B30: 美中 | C30: 13 | D30: 杨斌 | F30: 陈嘉译 | G30: 9岁 | H30: 之前没学过听得懂简单的中文 | I30: 一对四 | J30: 建议从拼音开始学起，可以听懂但是中文表达一般。 | K30: 言智38，李斐斐老师； 8:20开始；7.3缴费 | L30: 44015 | M30: 中文 | O30: 兼
A31: 44015 | B31: 宋崇铭 | C31: 12 | D31: 杨斌 | F31: 宋崇铭 | G31: 8岁 | H31: 孩子注意力容易不集中希望老师引导 | J31: 建议从拼音开始学起，可以听懂但是中文表达一般。 | K31: 言智38，李斐斐老师； 8:20开始；7.3缴费 | L31: 44015 | M31: 中文 | O31: 兼
A32: 44015 | B32: 美国东部 | C32: 12 | D32: 毛益丹 | F32: 梁斯颖 | G32: 8岁半 | H32: 学了一年的中文，正在学拼音了，会一点点拼音，会基本的中文交流 | J32: 建议aoe开始，零基础，跟老师读发音标准，弟弟在旁边喜欢学 | K32: 言智38，李斐斐老师； 8:20开始；7.3缴费 | L32: 44015 | M32: 中文 | N32: =TRIM(F32) -> 梁斯颖 | O32: 兼 | P32: 是 | Q32: =IFERROR(VLOOKUP(N32,Sheet1!A:B,2,FALSE),"zhaobudao") -> zhaobudao
A33: 44015 | B33: 美国纽约 | C33: -12 | D33: 王晨 | F33: 陈煾则 | G33: 9 | I33: 小班课 | J33: 中文沟通流畅，零基础，建议从拼音开始学。 | K33: J课堂 9:00 7-4 | L33: 44016 | M33: 中文 | N33: =TRIM(F33) -> 陈煾则 | O33: 白 | P33: 是 | Q33: =IFERROR(VLOOKUP(N33,Sheet1!A:B,2,FALSE),"zhaobudao") -> zhaobudao
A34: 44015 | B34: 美东 | C34: 12 | D34: 翁珊珊 | F34: 黄梓瑄 | G34: 10 | I34: 一对二 | J34: 两姐妹程度一般，会拼音，中文能听懂一些，词汇量识字量很少 ，建议从一上四单元开始上课 | K34: 程老师课堂8:30 7.3 | L34: 44015 | M34: 中文 | N34: =TRIM(F34) -> 黄梓瑄 | O34: 兼 | P34: 是 | Q34: =IFERROR(VLOOKUP(N34,Sheet1!A:B,2,FALSE),"zhaobudao") -> zhaobudao
A35: 44015 | B35: 美东 | C35: 12 | D35: 翁珊珊 | F35: 黄奕瑄 | G35: 12 | I35: 一对二 | J35: 两姐妹程度一般，会拼音，中文能听懂一些，词汇量识字量很少 ，建议从一上四单元开始上课 | K35: 程老师课堂8:30 7.3 | L35: 44015 | M35: 中文 | O35: 兼
A36: 44015 | B36: 美西 | C36: 15 | D36: 程蕾 | F36: Selena | G36: 8 | H36: 小孩子爱问问题 | I36: 一对四 | J36: 二年级上册6单元开始 | K36: G课堂 10:20 7.4 | L36: 44016 | M36: 中文 | N36: =TRIM(F36) -> Selena | O36: 白 | P36: 是 | Q36: =IFERROR(VLOOKUP(N36,Sheet1!A:B,2,FALSE),"zhaobudao") -> zhaobudao
A37: 44015 | B37: 美国 | C37: 12 | D37: 李华 | E37: 1 | F37: 陈懿 | G37: 6 | H37: 数学，一上 | I37: 1对1 | J37: 早上10点 | K37: 数学十一C 22：00 7月3日 | L37: 44015 | M37: 数学 | O37: 兼
A38: 44015 | B38: 美东 | C38: 12 | D38: 高翱翔 | F38: 高鹏 | G38: 11 | H38: 会拼音，可以基础交流，希望可以老师带一点点英文讲解 | I38: 一对四 | J38: 一年上册七单元课文开始。{最好是项链这篇课文} | K38: Z 课堂 7:00 7-4 | L38: 44016 | M38: 中文 | N38: =TRIM(F38) -> 高鹏 | O38: 白 | P38: 是 | Q38: =IFERROR(VLOOKUP(N38,Sheet1!A:B,2,FALSE),"zhaobudao") -> zhaobudao
A39: 44015 | B39: 美国 | C39: 12 | D39: 李华 | E39: 1 | F39: 马瑾瑜 | G39: 7 | H39: 数学，一下 | I39: 1对1 | J39: 早上9.30后 晚上9.30前 | K39: 课堂言智43 20：007月4日 | L39: 44016 | M39: 数学 | O39: 兼
A40: 44015 | B40: 澳洲 | C40: 2 | D40: 杨斌 | F40: 米哒 | G40: 6 | H40: 妹妹没学过拼音 | I40: 一对三 | J40: 建议拼音开始识字量大理解表达能力不错 | K40: I 课堂 14:10 7-4 | L40: 44016 | M40: 中文 | O40: 白
...

Sheet Sheet1
A1: 叶文浩1 | B1: 是
A2: 叶鋆睿 | B2: 是
A3: 何子恒 | B3: 是
A4: 吉娜 | B4: 是
A5: 宋崇铭 | B5: 是
A6: 吴楚惟 | B6: 是
A7: 吕泽歆 | B7: 是
A8: 小恩 | B8: 是
A9: 吴炳铨 | B9: 是
A10: 林泽锴1 | B10: 是
A11: 胡昊阳 | B11: 是
A12: 胡昊阳 | B12: 是
... A250: 张皓轩 | B250: 是

Sheet 试读跟进表2020.06
A1: 日期 | B1: 国家 | C1: 时差 | D1: 业务员 | E1: 组别 | F1: 学生姓名 | G1: 年龄 | H1: 预排年级 | I1: 家长叙述/特殊要求 | J1: 上课时间（中国时间） | K1: 排课安排（老师填写） | L1: 试读日期 | M1: 课程 | N1: 学区 | O1: 是否到课（顾问填写）
A2: 6.1 | B2: 美国 | C2: 12 | D2: 王晨 | E2: 0 | F2: 轩辕瀚 | G2: 9 | H2: 2年级或3年级，识字量500 | I2: 想直接试黄莺老师的课 | J2: 国内134晚上22:05 | K2: 黄老师课堂 22:05 6.1 | L2: 43983 | M2: 中文 | N2: 兼 | O2: 是
A3: 6.1/22:05 | B3: 美国 | C3: 12 | D3: 王晨 | E3: 0 | F3: 杨乐乐 | G3: 8 | H3: 2年级或3年级，识字量100+没有准确统计过 | I3: 想直接试黄莺老师的课 | J3: 国内134晚上22:05 | K3: 黄老师课堂 22:05 6.1 | L3: 43983 | M3: 中文 | N3: 兼 | O3: 是
A4: 5.3 | B4: 西班牙 | C4: 6 | D4: 王可 | E4: 3 | F4: 王天缘 | G4: 14 | H4: 一上八单元 | I4: 表达能力较弱，识字量大，性格活泼爱笑，老师讲课要慢一些 | J4: 晚上11点半 | K4: 四十三课堂 23:40 6.1 | L4: 43983 | M4: 中文 | N4: 夜 | O4: 是
A5: 5.31 | B5: 美国 | C5: 15 | D5: 张文红 | E5: 3 | F5: Krystal | G5: 16 | H5: 建议拼音zh;ch;sh;r开始学起，很有耐心学习，认字量在10个左右，慢一点说可以听懂。 | J5: 国内早上八点 | K5: 言智16 7：00 6.2 | L5: 43984 | M5: 中文 | N5: 兼 | O5: 是
B6: 澳大利亚 | C6: 2 | D6: 张文红 | E6: 3 | F6: 陈远熙 | G6: 8 | H6: 建议天地人学起，零基础，学生比较好动，注意力不是太集中。双语 | I6: 需要双语，零基础 | J6: 国内时间18:30 | K6: 言智02 18:30 6.1 | L6: 43983 | M6: 中文 | N6: 兼 | O6: 是
B7: 美国 | C7: 15 | D7: 丁阮琪 | E7: 2 | F7: 李俊熙 | G7: 10 | H7: 已缴费，要魏霞老师教，一上六七单元开始上 | I7: 要魏霞老师教，一对一，已缴费 | J7: 国内早上11点 | K7: 魏老师课堂 11:00 6.2 | L7: 43984 | M7: 中文 | N7: 兼 | O7: 是
A8: 5.31 | B8: 美国 | C8: 15 | D8: 张文红 | E8: 3 | F8: Howard | G8: 8 | H8: 建议YCT的课学起，零基础，不太爱说话，有一点抵触发音比较慢。老师多引导 | J8: 国内早上八点 | K8: play east01 7:50 6.2 | L8: 43984 | M8: yct | N8: 兼 | O8: 是
A9: 6.1 | B9: 西班牙 | C9: 6 | D9: 欧阳江勇 | E9: 5 | F9: 张家盛 | G9: 10 | H9: 数学课，老师建议从四年级下册开始 | I9: 时间最好安排在国内凌晨四点左右 | J9: 国内凌晨04：00～05：00 | K9: 十一课堂 4：20 6.2 | L9: 43984 | M9: 中文 | N9: 夜
B10: 美国 | C10: -12 | D10: 翁珊珊 | E10: 3 | F10: 林雅熙 | G10: 10 | H10: 建议d;t;n;l开始学起，声调也不太会要复习。妈妈也希望拼音学起。认字量大一上第七单元的生字都认识，比较文静。 | I10: 家长想试一对二或者一对一的班级 | J10: 国内时间周5的早上七点到九点 | K10: 言智19 7：40 6.5 | L10: 43987 | M10: 中文 | N10: 兼 | O10: 是
A11: 5.31 | B11: 美西 | C11: 15 | D11: 王可 | E11: 3 | F11: 高一凡 | G11: 10 | H11: 三上第一单元 | J11: 中国上午11点 | K11: s课堂11:40 6.3 | L11: 43985 | M11: 中文 | N11: 白 | O11: 是
A12: 6.2 | B12: 美西圣何塞 | C12: 15 | D12: 毛益丹 | E12: 3 | F12: 陆时安 | G12: 快7岁 | H12: 建议一下二、三单元开始，认字较多，词汇不理解。说话比较慢，会回应老师，不热情。 | I12: 不需要老师 | J12: 中国早上7:00 | K12: O课堂 7：00 6.3 | L12: 43985 | M12: 中文 | N12: 白 | O12: 是
A13: 6.2 | B13: 美西旧金山 | C13: 15 | D13: 毛益丹 | E13: 3 | F13: 苑舒欣 | G13: 快7岁了 | H13: 建议拼音aoe开始学，沟通没问题，简单的字认识，拼音声调不认识 | I13: 学过一些中文，不太多 | J13: 国内早上7:00-9:00或10:00-11:00都可以 | K13: I课堂 11:00 6.2 | L13: 43984 | M13: 中文 | N13: 白 | O13: 是 | P13: 失败
A14: 6.2 | B14: 美东 | C14: 12 | D14: 展旺 | E14: 3 | F14: 林进轩 | G14: 11岁 | H14: 拼音忘记了，平翘舌不分，识字量丰富。建议三上中间，后面部分学习。 | I14: 一对一的，满意就缴费。我要求：1，安中国三年开始教，2，帮忙纠正拼音，有的忘了，可以穿插课堂教点，3，写字笔画也需要纠正。 | J14: 国内早上7:30到8：00 | K14: Chineseonline T10 7:30 6.3 | L14: 43985 | M14: 中文 | N14: 兼 | O14: 是
A15: 6.2 | B15: 英国 | C15: 7 | D15: 何家昌 | E15: 1 | F15: 常艺霏 | G15: 8 | H15: 孩子程度不错 ，拼音不是非常好，建议从一年级上册中后段开始 | I15: 已缴费，一对四。 | J15: 周一到周四16:00到16:30或者周一到周五19:30到20:00 | K15: A课堂 16：00 6.3 | L15: 43985 | M15: 中文 | N15: 白 | O15: 是
A16: 6.3 | B16: 加拿大 | C16: 15 | D16: 俞酉兰 | F16: 嘉轩 | G16: 8 | H16: 零基础 YCT 6月4号10点的课程 | I16: 6月4号上午10点 | J16: 6月4号上午10点 | K16: play east01 10:00 6.4 | L16: 43986 | M16: yct | N16: 兼 | O16: 是
A17: 6.2 | B17: 美西 | C17: 15 | D17: 王可 | E17: 3 | F17: 高泊宇 | G17: 11 | H17: 一下三单元 声调会搞混 | I17: 想要稍微难一点的，太简单担心孩子会觉得无聊 | J17: 国内上午11:40 | K17: H课堂 11:40 6.4 | L17: 43986 | M17: 中文 | N17: 白 | O17: 是
A18: 6.2 | B18: 美西 | C18: 15 | D18: 王可 | E18: 3 | F18: 高泊翔 | G18: 9 | H18: 一上六七单元 不太会造句 | J18: 国内上午11:40 | K18: J 课堂 11:40 6.4 | L18: 43986 | M18: 中文 | N18: 白 | O18: 是
A19: 6.3 | B19: 美西 | C19: 15 | D19: 杨斌 | E19: 3 | F19: 唐源 | G19: 10 | H19: 建议五上开始，所有生字都认识，文章表层含义理解，深层道理不理解，不会总结 | J19: 国内早上七点以后 | K19: L 课堂 9：00 6.4 | L19: 43986 | M19: 中文 | N19: 白 | O19: 是
A20: 6.2 | B20: 美国 | C20: 15 | D20: 王可 | E20: 3 | F20: Abby | G20: 8 | H20: 一下二三单元，学生程度很好，过度害羞，不开摄像头 | J20: 中国早上8-10点 | K20: E课堂 9：40 6.4 | L20: 43986 | M20: 中文 | N20: 白 | O20: 否
A21: 6.5 | B21: 美国 | C21: 12 | D21: 胡东东 | E21: 5 | F21: 柳宇翔 | G21: 10 | H21: 一上末尾开始 | I21: 老师上课生动一点，能让孩子学习到知识 妈妈想上一对1或1对2 | J21: 国内周五早上9点 | K21: Chineseonline T10 9:00 6.5 | L21: 43987 | M21: 中文 | N21: 兼 | O21: 是
B22: 美国 | C22: 15 | D22: 程蕾 | E22: 3 | F22: 小龙 | G22: 7 | H22: 一年级上册 | I22: 拼音学完了，能中文交流 | J22: 国内早上9：00-12;00 | K22: O课堂 7:40 6.4 | L22: 43986 | M22: 中文 | N22: 白 | O22: 否
A23: 6.4 | B23: 美国 | C23: 12 | D23: 高翱翔 | E23: 2 | F23: 孙浩轩 | G23: 9 | H23: 零基础，可以从拼音开始学起，家长不测试，直接安排小班试课 | I23: 小班测课满意就缴费， | J23: 国内7点到8点之间 | K23: N 课堂 7:40 6.5 | L23: 43987 | M23: 中文 | N23: 白 | O23: 是
A24: 6.3 | B24: 美国 | C24: 12 | D24: 刘箫 | E24: 5 | F24: jayden | G24: 8 | H24: 0基础，家长要求从拼音开始学起【已缴费】 | I24: 上课时间在7点到8点之间 | J24: 国内7点到8点之间 | K24: N 课堂 7:40 6.5 | L24: 43987 | M24: 中文 | N24: 白 | O24: 是
A25: 6.3 | B25: 美国 | C25: 12 | D25: 展望 | E25: 3 | F25: 王锦文 | G25: 6 | H25: 建议拼音学起，配合度高很听话。说的能力好很爱表现，认字量50个内。 | I25: 国内上午7：30——9：00.已缴费 | J25: 国内时间7：30——9：00 | K25: N 课堂 7:40 6.5 | L25: 43987 | M25: 中文 | N25: 白 | O25: 是
A26: 6.4 | B26: 美东 | C26: 12 | D26: 翁珊珊 | E26: 3 | F26: Evangela | G26: 7 | H26: 建议从一上四五单元开始学 | J26: 国内时间9：00 | K26: O课堂 7:40 | L26: 43988 | M26: 中文 | N26: 白 | O26: 否
A27: 5.31 | B27: 美西 | C27: 15 | D27: 王可 | E27: 3 | F27: Aine | G27: 5 | H27: 天地人开始 | I27: 需要双语老师 | J27: 中国早上七八点 | K27: 言智31 8:30 6.5 | L27: 43987 | M27: 中文 | N27: 兼 | O27: 是
D28: 王可 | E28: 3 | F28: Logan | G28: 8 | H28: 天地人开始 | I28: 需要双语老师 | J28: 中国早上七八点 | K28: 言智31 8:30 6.5 | L28: 43987 | M28: 中文 | N28: 兼 | O28: 是
A29: 6.3 | B29: 美国 | C29: 12 | D29: 平金军 | E29: 2 | F29: 林宇 | G29: 12 | H29: 建议拼音开始学起， | I29: 反映有点慢说中文的能力不太好，要双语老师， | J29: 国内早上7:30 | K29: 言智07 7:30 6.7 | L29: 43989 | M29: 中文 | N29: 兼 | O29: 是
A30: 6.4 | B30: 加拿大 | C30: 15 | D30: 俞酉兰 | F30: 彤彤 | G30: 7 | H30: 零基础 直接试课 | J30: 国内早上7点40 | K30: N课堂7:40 6.5 | L30: 43987 | M30: 中文 | N30: 白 | O30: 是
A31: 6.4 | B31: 美国 | C31: 12 | D31: 胡东东 | E31: 5 | F31: 黄博腾 | G31: 11 | H31: 你我他开始 | I31: 已缴费，一对二 。希望细心一点的老师，活泼一点的老师，一周三天一三五 | J31: 国内早上7点半 | K31: 言智16 7:50 6.6 | L31: 43988 | M31: 中文 | N31: 兼 | O31: 是
A32: 6.4 | B32: 加拿大 | C32: 15 | D32: 俞酉兰 | F32: 方宝 | G32: 14 | H32: 四上 | J32: 国内9多到10点 | K32: F课堂 11:40 6.5 | L32: 43987 | M32: 中文 | N32: 白 | O32: 否
A33: 6.5 | B33: 美国旧金山 | C33: -15 | D33: 赵国花 | E33: 2 | F33: 张心桥 | G33: 8.5 | H33: 零基础，建议YCT的课程，学生很认真乖巧。双语 | I33: 跟家长谈好一对一的课程了 明天付钱 要求明天就上课 请周老师一定拍好课 家长希望杨老师上课 而且不能中途换老师 | J33: 国内时间早上7:30-8:30 | K33: 已发yct play east02 8:00 6.6 | L33: 43988 | M33: yct | N33: 兼 | O33: 是
A34: 6.6 | B34: 美国纽约 | C34: 12 | D34: 张霞 | E34: 3 | F34: 林志刚 | G34: 11 | H34: 学生有一定的基础，上课非常认真，简单的生字都是认识的，但是学过的拼音有很多遗忘了，家长想让孩子打好基础，建议从拼音的aieiui开始学。 | I34: 家长希望老师能耐心点，孩子不喜欢太吵了。 | J34: 国内7点～9点 | K34: Z课堂 8:20 6.6 | L34: 43988 | M34: 中文 | N34: 白 | O34: 是
A35: 6.6 | B35: 美国纽约 | C35: 12 | D35: 展旺 | E35: 3 | F35: 郑丽颍 | G35: 10 | H35: 一上第四单元开始学起，双语。课文能读下来，每个词语都需要英语解释，双语 | I35: 老师好一点的，双语老师 | J35: 国内早上7：00后，9：00前 | K35: 双语课堂 8：20 6.6 | L35: 43988 | M35: 中文 | N35: 白 | O35: 是
A36: 6.5 | B36: 加拿大温哥华 | C36: -15 | D36: 张多多 | E36: 0 | F36: 李艾文 | G36: 7 | H36: 孩子配合，建议从基础拼音aoe开始学习 | I36: 家长希望孩子能感兴趣学习中文 把他学好 孩子自己也在自学汉字 | J36: 时间自由 有合适的班级就可以上课 | K36: N课堂 7:40 6.6 | L36: 43988 | M36: 中文 | N36: 白 | O36: 否
A37: 6.5 | B37: 美国纽约 | C37: 12 | D37: 展旺 | E37: 3 | F37: 张恭旭 | G37: 7 | H37: 拼音零基础，认识简单的生字，建议学生从拼音开始学习。 | I37: 要好点的老师，细心耐心一点的，不然还要换课堂。 | J37: 国内早上7：00到8：30都可以 | K37: N课堂 7:40 6.6 | L37: 43988 | M37: 中文 | N37: 白 | O37: 是
B38: 澳大利亚 | C38: 2 | D38: 毛益丹 | E38: 3 | F38: 陈笑涵 | G38: 11岁 | H38: 建议一下第六七单元学起，配合上课，喜欢被夸奖。想当朗读家 | I38: 学过拼音，家长要求一定要一个好的老师，能够学到东西的 | J38: 国内下午5:10 | K38: J课堂 17:10 6.5 | L38: 43987 | M38: 中文 | N38: 白 | O38: 是
A39: 6.5 | B39: 美国 | C39: 15 | D39: 程蕾 | E39: 3 | F39: 小龙 | G39: 7 | H39: 拼音学过，直接试课，可以从一年级上册排 | J39: 10点到12点 | K39: A课堂 10:20 6.8 | L39: 43990 | M39: 中文 | N39: 白 | O39: 是
A40: 6.5 | B40: 美国旧金山 | C40: -15 | D40: 赵国花 | E40: 2 | F40: 吴钟凯 | G40: 10 | H40: 建议一上第四单元开始学起，不太爱说话要引导。 | I40: 希望老师耐心点教他 他表达力弱一些 句子太长了也就听不懂了 | J40: 上午10:30-11:30 | K40: N课堂 9:00 6.6 | L40: 43990 | M40: 中文 | N40: 白 | O40: 是
...

Sheet 美术课
A1: 日期 | B1: 国家 | C1: 时差 | D1: 业务员 | E1: 组别 | F1: 学生姓名 | G1: 年龄 | H1: 预排年级 | I1: 特殊要求 | J1: 上课时间（中国） | K1: 排课安排

Sheet 书法
A1: 日期 | B1: 国家 | C1: 时差 | D1: 业务员 | E1: 组别 | F1: 学生姓名 | G1: 年龄 | H1: 预排年级 | I1: 特殊要求 | J1: 上课时间（中国） | K1: 排课安排

Sheet 编程
A1: 日期 | B1: 国家 | C1: 时差 | D1: 业务员 | E1: 组别 | F1: 学生姓名 | G1: 年龄 | H1: 预排年级 | I1: 特殊要求 | J1: 上课时间（中国） | K1: 排课安排

Sheet 数学课
A1: 日期 | B1: 国家 | C1: 时差 | D1: 业务员 | E1: 组别 | F1: 学生姓名 | G1: 年龄 | H1: 预排年级 | I1: 特殊要求 | J1: 上课时间（中国） | K1: 排课安排 | M1: 号码
A2: 44020 | B2: 葡萄牙 | C2: 7 | D2: 徐琪琪 | F2: 郭子涵 | G2: 9 | H2: 二年级下册

Sheet 英语
A1: 日期 | B1: 国家 | C1: 时差 | D1: 业务员 | E1: 组别 | F1: 学生姓名 | G1: 年龄 | H1: 预排年级 | I1: 特殊要求 | J1: 上课时间（中国） | K1: 排课安排

Sheet HSK、YCT
A1: 日期 | B1: 国家 | C1: 时差 | D1: 业务员 | E1: 组别 | F1: 学生姓名 | G1: 年龄 | H1: 预排年级 | I1: 特殊要求 | J1: 上课时间（中国） | K1: 排课安排
A18: 岁
